Workbook

Sheet 26-1-08
A1: model | B1: PyCaret | C1: ARIMAX | D1: PCE | E1: LSTM | F1: GARCH | G1: VAR | H1: RW | I1: ETS | J1: DynaMix | L1: 26-Q1-08 | O1: Accuracy | P1: TNX | Q1: =SUM(P2:P10) -> 696.99259 | R1: DJI | S1: =SUM(R2:R10) -> 795.37096 | T1: SPX | U1: =SUM(T2:T10) -> 793.01537 | V1: VIX | W1: =SUM(V2:V10) -> 637.03667 | X1: QQQ | Y1: =SUM(X2:X10) -> 787.1086 | Z1: AAPL | AA1: =SUM(Z2:Z10) -> 767.4878 | AC1: AVR-4 | AD1: AVR-6
A2: TNX | B2: 4.0602 | C2: 4.0356 | D2: 0 | E2: 4.0761 | F2: 4.0288 | G2: 0 | H2: 4.0269 | I2: 4.0268 | J2: 4.0464 | O2: =B1 -> PyCaret | P2: =100-ABS((($H10-B2)/($H10)))*100 -> 99.748148 | Q2: =P2/$Q$1 -> 0.14311221 | R2: =100-ABS((($H11-B3)/($H11)))*100 -> 98.109439 | S2: =R2/$S$1 -> 0.12335054 | T2: =100-ABS((($H12-B4)/($H12)))*100 -> 98.218684 | U2: =T2/$U$1 -> 0.1238547 | V2: =100-ABS((($H13-B5)/($H13)))*100 -> 70.647083 | W2: =V2/$W$1 -> 0.11089956 | X2: =100-ABS((($H14-B6)/($H14)))*100 -> 98.0318 | Y2: =X2/$Y$1 -> 0.12454673 | Z2: =100-ABS((($H15-B7)/($H15)))*100 -> 94.600985 | AA2: =Z2/$AA$1 -> 0.12326057 | AC2: =(R2+T2+V2+X2)/4 -> 91.251752 | AD2: =(P2+R2+T2+V2+X2+Z2)/6 -> 93.226023 | AE2: =IF($AC2=MAX(AC2:AC10),"TOP","")
A3: DJI | B3: 48564.172 | C3: 49474.57 | D3: 0 | E3: 49407.988 | F3: 49366.732 | G3: 49263.719 | H3: 49314.926 | I3: 49283.446 | J3: 49033.07 | L3: 2026/03/03 | O3: =C1 -> ARIMAX | P3: =100-ABS((($H10-C2)/($H10)))*100 -> 99.644444 | Q3: =P3/$Q$1 -> 0.14296342 | R3: =100-ABS((($H11-C3)/($H11)))*100 -> 99.948625 | S3: =R3/$S$1 -> 0.12566291 | T3: =100-ABS((($H12-C4)/($H12)))*100 -> 98.973037 | U3: =T3/$U$1 -> 0.12480595 | V3: =100-ABS((($H13-C5)/($H13)))*100 -> 82.330417 | W3: =V3/$W$1 -> 0.12923968 | X3: =100-ABS((($H14-C6)/($H14)))*100 -> 98.767083 | Y3: =X3/$Y$1 -> 0.12548088 | Z3: =100-ABS((($H15-C7)/($H15)))*100 -> 96.625682 | AA3: =Z3/$AA$1 -> 0.12589865 | AC3: =(R3+T3+V3+X3)/4 -> 95.004791 | AD3: =(P3+R3+T3+V3+X3+Z3)/6 -> 96.048215 | AE3: =IF($AC3=MAX(AC2:AC10),"TOP","") -> TOP
A4: SPX | B4: 6977.1092 | C4: 6925.3983 | D4: 0 | E4: 6888.2836 | F4: 6937.9702 | G4: 6890.7587 | H4: 6911.7912 | I4: 6909.2234 | J4: 6878.2617 | O4: =D1 -> PCE | P4: =100-ABS((($H10-D2)/($H10)))*100 -> 0 | Q4: =P4/$Q$1 -> 0 | R4: =100-ABS((($H11-D3)/($H11)))*100 -> 0 | S4: =R4/$S$1 -> 0 | T4: =100-ABS((($H12-D4)/($H12)))*100 -> 0 | U4: =T4/$U$1 -> 0 | V4: =100-ABS((($H13-D5)/($H13)))*100 -> 0 | W4: =V4/$W$1 -> 0 | X4: =100-ABS((($H14-D6)/($H14)))*100 -> 0 | Y4: =X4/$Y$1 -> 0 | Z4: =100-ABS((($H15-D7)/($H15)))*100 -> 0 | AA4: =Z4/$AA$1 -> 0 | AC4: =(R4+T4+V4+X4)/4 -> 0 | AD4: =(P4+R4+T4+V4+X4+Z4)/6 -> 0 | AE4: =IF($AC4=MAX(AC2:AC10),"TOP","")
A5: VIX | B5: 16.9553 | C5: 19.7593 | D5: 0 | E5: 18.1835 | F5: 19.7964 | G5: 19.6944 | H5: 19.4091 | I5: 19.6078 | J5: 19.483 | L5: ML | O5: =E1 -> LSTM | P5: =100-ABS((($H10-E2)/($H10)))*100 -> 99.355556 | Q5: =P5/$Q$1 -> 0.14254894 | R5: =100-ABS((($H11-E3)/($H11)))*100 -> 99.814117 | S5: =R5/$S$1 -> 0.12549379 | T5: =100-ABS((($H12-E4)/($H12)))*100 -> 99.514462 | U5: =T5/$U$1 -> 0.12548869 | V5: =100-ABS((($H13-E5)/($H13)))*100 -> 75.764583 | W5: =V5/$W$1 -> 0.11893285 | X5: =100-ABS((($H14-E6)/($H14)))*100 -> 98.152367 | Y5: =X5/$Y$1 -> 0.1246999 | Z5: =100-ABS((($H15-E7)/($H15)))*100 -> 95.053674 | AA5: =Z5/$AA$1 -> 0.1238504 | AC5: =(R5+T5+V5+X5)/4 -> 93.311382 | AD5: =(P5+R5+T5+V5+X5+Z5)/6 -> 94.609127 | AE5: =IF($AC5=MAX(AC2:AC10),"TOP","")
A6: QQQ | B6: 611.8092 | C6: 607.3975 | D6: 0 | E6: 611.0858 | F6: 612.3191 | G6: 607.5304 | H6: 610.098 | I6: 608.0805 | J6: 609.0279 | O6: =F1 -> GARCH | P6: =100-ABS((($H10-F2)/($H10)))*100 -> 99.476543 | Q6: =P6/$Q$1 -> 0.14272253 | R6: =100-ABS((($H11-F3)/($H11)))*100 -> 99.730773 | S6: =R6/$S$1 -> 0.125389 | T6: =100-ABS((($H12-F4)/($H12)))*100 -> 98.78964 | U6: =T6/$U$1 -> 0.12457468 | V6: =100-ABS((($H13-F5)/($H13)))*100 -> 82.485 | W6: =V6/$W$1 -> 0.12948234 | X6: =100-ABS((($H14-F6)/($H14)))*100 -> 97.946817 | Y6: =X6/$Y$1 -> 0.12443876 | Z6: =100-ABS((($H15-F7)/($H15)))*100 -> 95.440682 | AA6: =Z6/$AA$1 -> 0.12435466 | AC6: =(R6+T6+V6+X6)/4 -> 94.738057 | AD6: =(P6+R6+T6+V6+X6+Z6)/6 -> 95.644909 | AE6: =IF($AC6=MAX(AC2:AC10),"TOP","")
A7: AAPL | B7: 249.7466 | C7: 272.9082 | D7: 0 | E7: 277.0583 | F7: 276.0366 | G7: 273.9377 | H7: 273.009 | I7: 273.009 | J7: 273.62 | O7: =G1 -> VAR | P7: =100-ABS((($H10-G2)/($H10)))*100 -> 0 | Q7: =P7/$Q$1 -> 0 | R7: =100-ABS((($H11-G3)/($H11)))*100 -> 99.522665 | S7: =R7/$S$1 -> 0.12512736 | T7: =100-ABS((($H12-G4)/($H12)))*100 -> 99.478356 | U7: =T7/$U$1 -> 0.12544316 | V7: =100-ABS((($H13-G5)/($H13)))*100 -> 82.06 | W7: =V7/$W$1 -> 0.12881519 | X7: =100-ABS((($H14-G6)/($H14)))*100 -> 98.744933 | Y7: =X7/$Y$1 -> 0.12545274 | Z7: =100-ABS((($H15-G7)/($H15)))*100 -> 96.23572 | AA7: =Z7/$AA$1 -> 0.12539055 | AC7: =(R7+T7+V7+X7)/4 -> 94.951489 | AD7: =(P7+R7+T7+V7+X7+Z7)/6 -> 79.340279 | AE7: =IF($AC7=MAX(AC2:AC10),"TOP","")
O8: =H1 -> RW | P8: =100-ABS((($H10-H2)/($H10)))*100 -> 99.42963 | Q8: =P8/$Q$1 -> 0.14265522 | R8: =100-ABS((($H11-H3)/($H11)))*100 -> 99.626114 | S8: =R8/$S$1 -> 0.12525742 | T8: =100-ABS((($H12-H4)/($H12)))*100 -> 99.171536 | U8: =T8/$U$1 -> 0.12505626 | V8: =100-ABS((($H13-H5)/($H13)))*100 -> 80.87125 | W8: =V8/$W$1 -> 0.12694913 | X8: =100-ABS((($H14-H6)/($H14)))*100 -> 98.317 | Y8: =X8/$Y$1 -> 0.12490907 | Z8: =100-ABS((($H15-H7)/($H15)))*100 -> 96.5875 | AA8: =Z8/$AA$1 -> 0.12584891 | AC8: =(R8+T8+V8+X8)/4 -> 94.496475 | AD8: =(P8+R8+T8+V8+X8+Z8)/6 -> 95.667172 | AE8: =IF($AC8=MAX(AC2:AC10),"TOP","")
B9: Close YF | C9: Oraclum | D9: ML | F9: LLM | H9: +3-day | L9: =IF(L10<25,C30,IF(L10<45,C31,IF(L10<55,C32,IF(L10<75,C33,C34)))) -> Fear | O9: =I1 -> ETS | P9: =100-ABS((($H10-I2)/($H10)))*100 -> 99.42716 | Q9: =P9/$Q$1 -> 0.14265167 | R9: =100-ABS((($H11-I3)/($H11)))*100 -> 99.562517 | S9: =R9/$S$1 -> 0.12517746 | T9: =100-ABS((($H12-I4)/($H12)))*100 -> 99.208995 | U9: =T9/$U$1 -> 0.1251035 | V9: =100-ABS((($H13-I5)/($H13)))*100 -> 81.699167 | W9: =V9/$W$1 -> 0.12824877 | X9: =100-ABS((($H14-I6)/($H14)))*100 -> 98.65325 | Y9: =X9/$Y$1 -> 0.12533626 | Z9: =100-ABS((($H15-I7)/($H15)))*100 -> 96.5875 | AA9: =Z9/$AA$1 -> 0.12584891 | AC9: =(R9+T9+V9+X9)/4 -> 94.780982 | AD9: =(P9+R9+T9+V9+X9+Z9)/6 -> 95.856432 | AE9: =IF($AC9=MAX(AC2:AC10),"TOP","")
A10: TNX | B10: 4.033 | C10: 4.044 | D10: =(B2*Q26)+(C2*Q27)+(D2*Q28)+(E2*Q29)+(F2*Q30)+(G2*Q31)+(H2*Q32)+(I2*Q33)+(J2*Q34) -> 4.0421697 | E10: =D10/$H$10 -> 0.99806658 | F10: 4.0388972 | G10: =F10/$H$10 -> 0.99725858 | H10: 4.05 | L10: 43 | O10: =J1 -> DynaMix | P10: =100-ABS((($H10-J2)/($H10)))*100 -> 99.911111 | Q10: =P10/$Q$1 -> 0.14334602 | R10: =100-ABS((($H11-J3)/($H11)))*100 -> 99.056707 | S10: =R10/$S$1 -> 0.12454152 | T10: =100-ABS((($H12-J4)/($H12)))*100 -> 99.660661 | U10: =T10/$U$1 -> 0.12567305 | V10: =100-ABS((($H13-J5)/($H13)))*100 -> 81.179167 | W10: =V10/$W$1 -> 0.12743249 | X10: =100-ABS((($H14-J6)/($H14)))*100 -> 98.49535 | Y10: =X10/$Y$1 -> 0.12513565 | Z10: =100-ABS((($H15-J7)/($H15)))*100 -> 96.356061 | AA10: =Z10/$AA$1 -> 0.12554735 | AC10: =(R10+T10+V10+X10)/4 -> 94.597971 | AD10: =(P10+R10+T10+V10+X10+Z10)/6 -> 95.776509 | AE10: =IF($AC10=MAX(AC2:AC10),"TOP","")
A11: DJI | B11: 49174.5 | C11: 48818.85 | D11: =(B3*S26)+(C3*S27)+(D3*S28)+(E3*S29)+(F3*S30)+(G3*S31)+(H3*S32)+(I3*S33)+(J3*S34) -> 49221.088 | E11: =D11/$H$11 -> 0.99436541 | F11: 49251.484 | G11: =F11/$H$11 -> 0.99497947 | H11: 49500 | O11: AVR : | P11: =SUM(P2:P10)/8 -> 87.124074 | R11: =AVERAGE(R2:R10) -> 88.374551 | T11: =AVERAGE(T2:T10) -> 88.112819 | V11: =AVERAGE(V2:V10) -> 70.781852 | X11: =AVERAGE(X2:X10) -> 87.456511 | Z11: =AVERAGE(Z2:Z10) -> 85.276423
A12: SPX | B12: 6890.07 | C12: 6837.74 | D12: =(B4*U26)+(C4*U27)+(D4*U28)+(E4*U29)+(F4*U30)+(G4*U31)+(H4*U32)+(I4*U33)+(J4*U34) -> 6912.7657 | E12: =D12/$H$12 -> 1.0084268 | F12: 6907.2033 | G12: =F12/$H$12 -> 1.0076154 | H12: 6855
A13: VIX | B13: 19.55 | C13: 19.55 | D13: =(B5*W26)+(C5*W27)+(D5*W28)+(E5*W29)+(F5*W30)+(G5*W31)+(H5*W32)+(I5*W33)+(J5*W34) -> 18.934458 | E13: =D13/$H$13 -> 0.78893576 | F13: 19.318179 | G13: =F13/$H$13 -> 0.80492413 | H13: 24 | O13: Update | P13: TNX | Q13: =SUM(P14:P22) -> 595 | R13: DJI | S13: =SUM(R14:R22) -> 690 | T13: SPX | U13: =SUM(T14:T22) -> 615 | V13: VIX | W13: =SUM(V14:V22) -> 6.2 | X13: QQQ | Y13: =SUM(X14:X22) -> 530 | Z13: AAPL | AA13: =SUM(Z14:Z22) -> 360 | AC13: Value | AD13: Assign
A14: QQQ | B14: 607.87 | C14: 607.87 | D14: =(B6*Y26)+(C6*Y27)+(D6*Y28)+(E6*Y29)+(F6*Y30)+(G6*Y31)+(H6*Y32)+(I6*Y33)+(J6*Y34) -> 609.60971 | E14: =D14/$H$14 -> 1.0160162 | F14: 609.91082 | G14: =F14/$H$14 -> 1.016518 | H14: 600 | O14: =O2 -> PyCaret | P14: =IF(P2=0,0, LOOKUP(P2-0.000000000001,$AC$14:$AC$30,$AD$14:$AD$30)) -> 90 | Q14: =P14/$Q$13 -> 0.1512605 | R14: =IF(R2=0,0, LOOKUP(R2-0.000000000001,$AC$14:$AC$30,$AD$14:$AD$30)) -> 65 | S14: =R14/$S$13 -> 0.094202899 | T14: =IF(T2=0,0, LOOKUP(T2-0.000000000001,$AC$14:$AC$30,$AD$14:$AD$30)) -> 65 | U14: =T14/$U$13 -> 0.10569106 | V14: =IF(V2=0,0, LOOKUP(V2-0.000000000001,$AC$14:$AC$30,$AD$14:$AD$30)) -> 0.1 | W14: =V14/$W$13 -> 0.016129032 | X14: =IF(X2=0,0, LOOKUP(X2-0.000000000001,$AC$14:$AC$30,$AD$14:$AD$30)) -> 65 | Y14: =X14/$Y$13 -> 0.12264151 | Z14: =IF(Z2=0,0, LOOKUP(Z2-0.000000000001,$AC$14:$AC$30,$AD$14:$AD$30)) -> 30 | AA14: =Z14/$AA$13 -> 0.083333333 | AC14: 1 | AD14: 0.1
A15: AAPL | B15: 272.14 | C15: 272.19 | D15: =(B7*AA25)+(C7*AA26)+(D7*AA27)+(E7*AA28)+(F7*AA29)+(G7*AA30)+(H7*AA31)+(I7*AA32)+(J7*AA33) -> 271.24407 | E15: =D15/$H$15 -> 1.0274397 | F15: 274.37624 | G15: =F15/$H$15 -> 1.0393039 | H15: 264 | O15: =O3 -> ARIMAX | P15: =IF(P3=0,0, LOOKUP(P3-0.000000000001,$AC$14:$AC$30,$AD$14:$AD$30)) -> 90 | Q15: =P15/$Q$13 -> 0.1512605 | R15: =IF(R3=0,0, LOOKUP(R3-0.000000000001,$AC$14:$AC$30,$AD$14:$AD$30)) -> 95 | S15: =R15/$S$13 -> 0.13768116 | T15: =IF(T3=0,0, LOOKUP(T3-0.000000000001,$AC$14:$AC$30,$AD$14:$AD$30)) -> 70 | U15: =T15/$U$13 -> 0.11382114 | V15: =IF(V3=0,0, LOOKUP(V3-0.000000000001,$AC$14:$AC$30,$AD$14:$AD$30)) -> 1 | W15: =V15/$W$13 -> 0.16129032 | X15: =IF(X3=0,0, LOOKUP(X3-0.000000000001,$AC$14:$AC$30,$AD$14:$AD$30)) -> 70 | Y15: =X15/$Y$13 -> 0.13207547 | Z15: =IF(Z3=0,0, LOOKUP(Z3-0.000000000001,$AC$14:$AC$30,$AD$14:$AD$30)) -> 50 | AA15: =Z15/$AA$13 -> 0.13888889 | AC15: 80 | AD15: 1
O16: =O4 -> PCE | P16: =IF(P4=0,0, LOOKUP(P4-0.000000000001,$AC$14:$AC$30,$AD$14:$AD$30)) -> 0 | Q16: =P16/$Q$13 -> 0 | R16: =IF(R4=0,0, LOOKUP(R4-0.000000000001,$AC$14:$AC$30,$AD$14:$AD$30)) -> 0 | S16: =R16/$S$13 -> 0 | T16: =IF(T4=0,0, LOOKUP(T4-0.000000000001,$AC$14:$AC$30,$AD$14:$AD$30)) -> 0 | U16: =T16/$U$13 -> 0 | V16: =IF(V4=0,0, LOOKUP(V4-0.000000000001,$AC$14:$AC$30,$AD$14:$AD$30)) -> 0 | W16: =V16/$W$13 -> 0 | X16: =IF(X4=0,0, LOOKUP(X4-0.000000000001,$AC$14:$AC$30,$AD$14:$AD$30)) -> 0 | Y16: =X16/$Y$13 -> 0 | Z16: =IF(Z4=0,0, LOOKUP(Z4-0.000000000001,$AC$14:$AC$30,$AD$14:$AD$30)) -> 0 | AA16: =Z16/$AA$13 -> 0 | AC16: 82.5 | AD16: 2
A17: =F9 -> LLM | B17: RD | D17: 85220 | F17: MICH | H17: max-Q | O17: =O5 -> LSTM | P17: =IF(P5=0,0, LOOKUP(P5-0.000000000001,$AC$14:$AC$30,$AD$14:$AD$30)) -> 80 | Q17: =P17/$Q$13 -> 0.13445378 | R17: =IF(R5=0,0, LOOKUP(R5-0.000000000001,$AC$14:$AC$30,$AD$14:$AD$30)) -> 95 | S17: =R17/$S$13 -> 0.13768116 | T17: =IF(T5=0,0, LOOKUP(T5-0.000000000001,$AC$14:$AC$30,$AD$14:$AD$30)) -> 90 | U17: =T17/$U$13 -> 0.14634146 | V17: =IF(V5=0,0, LOOKUP(V5-0.000000000001,$AC$14:$AC$30,$AD$14:$AD$30)) -> 0.1 | W17: =V17/$W$13 -> 0.016129032 | X17: =IF(X5=0,0, LOOKUP(X5-0.000000000001,$AC$14:$AC$30,$AD$14:$AD$30)) -> 65 | Y17: =X17/$Y$13 -> 0.12264151 | Z17: =IF(Z5=0,0, LOOKUP(Z5-0.000000000001,$AC$14:$AC$30,$AD$14:$AD$30)) -> 40 | AA17: =Z17/$AA$13 -> 0.11111111 | AC17: 85 | AD17: 5
A18: TNX | B18: 4.01 | C18: =1-ABS(1-B18/$H$10) -> 0.99012346 | D18: 4.05 | E18: =1-ABS(1-D18/$H$10) -> 1 | F18: 4.15 | G18: =1-ABS(1-F18/$H$10) -> 0.97530864 | H18: TNX | I18: =MAX(P2:P10) -> 99.911111 | J18: G | O18: =O6 -> GARCH | P18: =IF(P6=0,0, LOOKUP(P6-0.000000000001,$AC$14:$AC$30,$AD$14:$AD$30)) -> 80 | Q18: =P18/$Q$13 -> 0.13445378 | R18: =IF(R6=0,0, LOOKUP(R6-0.000000000001,$AC$14:$AC$30,$AD$14:$AD$30)) -> 90 | S18: =R18/$S$13 -> 0.13043478 | T18: =IF(T6=0,0, LOOKUP(T6-0.000000000001,$AC$14:$AC$30,$AD$14:$AD$30)) -> 70 | U18: =T18/$U$13 -> 0.11382114 | V18: =IF(V6=0,0, LOOKUP(V6-0.000000000001,$AC$14:$AC$30,$AD$14:$AD$30)) -> 1 | W18: =V18/$W$13 -> 0.16129032 | X18: =IF(X6=0,0, LOOKUP(X6-0.000000000001,$AC$14:$AC$30,$AD$14:$AD$30)) -> 60 | Y18: =X18/$Y$13 -> 0.11320755 | Z18: =IF(Z6=0,0, LOOKUP(Z6-0.000000000001,$AC$14:$AC$30,$AD$14:$AD$30)) -> 40 | AA18: =Z18/$AA$13 -> 0.11111111 | AC18: 87.5 | AD18: 10
A19: DJI | B19: 49615 | C19: =1-ABS(1-B19/$H$11) -> 0.99767677 | D19: 49583 | E19: =1-ABS(1-D19/$H$11) -> 0.99832323 | F19: 50321 | G19: =1-ABS(1-F19/$H$11) -> 0.98341414 | H19: DJI | I19: =MAX(R2:R10) -> 99.948625 | J19: R | O19: =O7 -> VAR | P19: =IF(P7=0,0, LOOKUP(P7-0.000000000001,$AC$14:$AC$30,$AD$14:$AD$30)) -> 0 | Q19: =P19/$Q$13 -> 0 | R19: =IF(R7=0,0, LOOKUP(R7-0.000000000001,$AC$14:$AC$30,$AD$14:$AD$30)) -> 90 | S19: =R19/$S$13 -> 0.13043478 | T19: =IF(T7=0,0, LOOKUP(T7-0.000000000001,$AC$14:$AC$30,$AD$14:$AD$30)) -> 80 | U19: =T19/$U$13 -> 0.1300813 | V19: =IF(V7=0,0, LOOKUP(V7-0.000000000001,$AC$14:$AC$30,$AD$14:$AD$30)) -> 1 | W19: =V19/$W$13 -> 0.16129032 | X19: =IF(X7=0,0, LOOKUP(X7-0.000000000001,$AC$14:$AC$30,$AD$14:$AD$30)) -> 70 | Y19: =X19/$Y$13 -> 0.13207547 | Z19: =IF(Z7=0,0, LOOKUP(Z7-0.000000000001,$AC$14:$AC$30,$AD$14:$AD$30)) -> 50 | AA19: =Z19/$AA$13 -> 0.13888889 | AC19: 90 | AD19: 20
A20: SPX | B20: 6907 | C20: =1-ABS(1-B20/$H$12) -> 0.9924143 | D20: 6913 | E20: =1-ABS(1-D20/$H$12) -> 0.99153902 | F20: 6957 | G20: =1-ABS(1-F20/$H$12) -> 0.98512035 | H20: SPX | I20: =MAX(T2:T10) -> 99.660661 | J20: A | O20: =O8 -> RW | P20: =IF(P8=0,0, LOOKUP(P8-0.000000000001,$AC$14:$AC$30,$AD$14:$AD$30)) -> 80 | Q20: =P20/$Q$13 -> 0.13445378 | R20: =IF(R8=0,0, LOOKUP(R8-0.000000000001,$AC$14:$AC$30,$AD$14:$AD$30)) -> 90 | S20: =R20/$S$13 -> 0.13043478 | T20: =IF(T8=0,0, LOOKUP(T8-0.000000000001,$AC$14:$AC$30,$AD$14:$AD$30)) -> 75 | U20: =T20/$U$13 -> 0.12195122 | V20: =IF(V8=0,0, LOOKUP(V8-0.000000000001,$AC$14:$AC$30,$AD$14:$AD$30)) -> 1 | W20: =V20/$W$13 -> 0.16129032 | X20: =IF(X8=0,0, LOOKUP(X8-0.000000000001,$AC$14:$AC$30,$AD$14:$AD$30)) -> 65 | Y20: =X20/$Y$13 -> 0.12264151 | Z20: =IF(Z8=0,0, LOOKUP(Z8-0.000000000001,$AC$14:$AC$30,$AD$14:$AD$30)) -> 50 | AA20: =Z20/$AA$13 -> 0.13888889 | AC20: 92.5 | AD20: 30
A21: VIX | B21: 18.3 | C21: =1-ABS(1-B21/$H$13) -> 0.7625 | D21: 18.65 | E21: =1-ABS(1-D21/$H$13) -> 0.77708333 | F21: 18.02 | G21: =1-ABS(1-F21/$H$13) -> 0.75083333 | H21: VIX | I21: =MAX(V2:V10) -> 82.485 | J21: E | O21: =O9 -> ETS | P21: =IF(P9=0,0, LOOKUP(P9-0.000000000001,$AC$14:$AC$30,$AD$14:$AD$30)) -> 80 | Q21: =P21/$Q$13 -> 0.13445378 | R21: =IF(R9=0,0, LOOKUP(R9-0.000000000001,$AC$14:$AC$30,$AD$14:$AD$30)) -> 90 | S21: =R21/$S$13 -> 0.13043478 | T21: =IF(T9=0,0, LOOKUP(T9-0.000000000001,$AC$14:$AC$30,$AD$14:$AD$30)) -> 75 | U21: =T21/$U$13 -> 0.12195122 | V21: =IF(V9=0,0, LOOKUP(V9-0.000000000001,$AC$14:$AC$30,$AD$14:$AD$30)) -> 1 | W21: =V21/$W$13 -> 0.16129032 | X21: =IF(X9=0,0, LOOKUP(X9-0.000000000001,$AC$14:$AC$30,$AD$14:$AD$30)) -> 70 | Y21: =X21/$Y$13 -> 0.13207547 | Z21: =IF(Z9=0,0, LOOKUP(Z9-0.000000000001,$AC$14:$AC$30,$AD$14:$AD$30)) -> 50 | AA21: =Z21/$AA$13 -> 0.13888889 | AC21: 95 | AD21: 40
A22: QQQ | B22: 613.3 | C22: =1-ABS(1-B22/$H$14) -> 0.97783333 | D22: 615.4 | E22: =1-ABS(1-D22/$H$14) -> 0.97433333 | F22: 613.2 | G22: =1-ABS(1-F22/$H$14) -> 0.978 | H22: QQQ | I22: =MAX(X2:X10) -> 98.767083 | J22: A | O22: =O10 -> DynaMix | P22: =IF(P10=0,0, LOOKUP(P10-0.000000000001,$AC$14:$AC$30,$AD$14:$AD$30)) -> 95 | Q22: =P22/$Q$13 -> 0.15966387 | R22: =IF(R10=0,0, LOOKUP(R10-0.000000000001,$AC$14:$AC$30,$AD$14:$AD$30)) -> 75 | S22: =R22/$S$13 -> 0.10869565 | T22: =IF(T10=0,0, LOOKUP(T10-0.000000000001,$AC$14:$AC$30,$AD$14:$AD$30)) -> 90 | U22: =T22/$U$13 -> 0.14634146 | V22: =IF(V10=0,0, LOOKUP(V10-0.000000000001,$AC$14:$AC$30,$AD$14:$AD$30)) -> 1 | W22: =V22/$W$13 -> 0.16129032 | X22: =IF(X10=0,0, LOOKUP(X10-0.000000000001,$AC$14:$AC$30,$AD$14:$AD$30)) -> 65 | Y22: =X22/$Y$13 -> 0.12264151 | Z22: =IF(Z10=0,0, LOOKUP(Z10-0.000000000001,$AC$14:$AC$30,$AD$14:$AD$30)) -> 50 | AA22: =Z22/$AA$13 -> 0.13888889 | AC22: 96 | AD22: 50
A23: AAPL | B23: 273.2 | C23: =1-ABS(1-B23/$H$15) -> 0.96515152 | D23: 274.3 | E23: =1-ABS(1-D23/$H$15) -> 0.96098485 | F23: 274.4 | G23: =1-ABS(1-F23/$H$15) -> 0.96060606 | H23: AAPL | I23: =MAX(Z2:Z10) -> 96.625682 | J23: V | O23: AVR : | P23: =AVERAGE(P14:P22) -> 66.111111 | R23: =AVERAGE(R14:R22) -> 76.666667 | T23: =AVERAGE(T14:T22) -> 68.333333 | V23: =AVERAGE(V14:V22) -> 0.68888889 | X23: =AVERAGE(X14:X22) -> 58.888889 | Z23: =AVERAGE(Z14:Z22) -> 40 | AC23: 97 | AD23: 60
AA24: =SUM(Z26:Z34) -> 451.25 | AC24: 98 | AD24: 65
A25: =AC1 -> AVR-4 | B25: {=SUM(C19:C22/4)} -> 0.9326061 | D25: {=SUM(E19:E22/4)} -> 0.93531973 | F25: {=SUM(G19:G22/4)} -> 0.92434196 | H25: max-Q AVR-4 | J25: =AVERAGE(I19:I22) -> 95.215342 | O25: History | P25: TNX | Q25: =SUM(P26:P34) -> 486.25 | R25: DJI | S25: =SUM(R26:R34) -> 563.75 | T25: SPX | U25: =SUM(T26:T34) -> 622.5 | V25: VIX | W25: =SUM(V26:V34) -> 247.275 | X25: QQQ | Y25: =SUM(X26:X34) -> 547.5 | Z25: AAPL | AA25: =Z26/$AA$24 -> 0.11911357 | AC25: 98.5 | AD25: 70
A26: =AD1 -> AVR-6 | B26: {=SUM(C18:C23/6)} -> 0.94761656 | D26: {=SUM(E18:E23/6)} -> 0.9503773 | F26: {=SUM(G18:G23/6)} -> 0.93888042 | H26: max AVR-6 | J26: =AVERAGE(I18:I23) -> 96.233027 | O26: =O2 -> PyCaret | P26: 60 | Q26: =P26/$Q$25 -> 0.12339332 | R26: 62.5 | S26: =R26/$S$25 -> 0.11086475 | T26: 61.25 | U26: =T26/$U$25 -> 0.098393574 | V26: 50 | W26: =V26/$W$25 -> 0.20220402 | X26: 72.5 | Y26: =X26/$Y$25 -> 0.13242009 | Z26: 53.75 | AA26: =Z27/$AA$24 -> 0.12188366 | AC26: 99 | AD26: 75
O27: =O3 -> ARIMAX | P27: 65 | Q27: =P27/$Q$25 -> 0.13367609 | R27: 65 | S27: =R27/$S$25 -> 0.11529933 | T27: 77.5 | U27: =T27/$U$25 -> 0.12449799 | V27: 29.25 | W27: =V27/$W$25 -> 0.11828935 | X27: 75 | Y27: =X27/$Y$25 -> 0.1369863 | Z27: 55 | AA27: =Z28/$AA$24 -> 0 | AC27: 99.25 | AD27: 80
A28: https://feargreedmeter.com/fear-and-greed-index | O28: =O4 -> PCE | P28: 0 | Q28: =P28/$Q$25 -> 0 | R28: 0 | S28: =R28/$S$25 -> 0 | T28: 0 | U28: =T28/$U$25 -> 0 | V28: 0 | W28: =V28/$W$25 -> 0 | X28: 0 | Y28: =X28/$Y$25 -> 0 | Z28: 0 | AA28: =Z29/$AA$24 -> 0.10526316 | AC28: 99.5 | AD28: 90
O29: =O5 -> LSTM | P29: 66.25 | Q29: =P29/$Q$25 -> 0.13624679 | R29: 73.75 | S29: =R29/$S$25 -> 0.1308204 | T29: 77.5 | U29: =T29/$U$25 -> 0.12449799 | V29: 26.775 | W29: =V29/$W$25 -> 0.10828025 | X29: 60 | Y29: =X29/$Y$25 -> 0.10958904 | Z29: 47.5 | AA29: =Z30/$AA$24 -> 0.13296399 | AC29: 99.75 | AD29: 95
A30: Scale | B30: 0 | C30: Extreme Fear | O30: =O6 -> GARCH | P30: 77.5 | Q30: =P30/$Q$25 -> 0.15938303 | R30: 70 | S30: =R30/$S$25 -> 0.12416851 | T30: 77.5 | U30: =T30/$U$25 -> 0.12449799 | V30: 33.75 | W30: =V30/$W$25 -> 0.13648772 | X30: 65 | Y30: =X30/$Y$25 -> 0.11872146 | Z30: 60 | AA30: =Z31/$AA$24 -> 0.12742382 | AC30: 99.99 | AD30: 100
B31: 25 | C31: Fear | O31: =O7 -> VAR | P31: 0 | Q31: =P31/$Q$25 -> 0 | R31: 73.75 | S31: =R31/$S$25 -> 0.1308204 | T31: 83.75 | U31: =T31/$U$25 -> 0.13453815 | V31: 30.5 | W31: =V31/$W$25 -> 0.12334445 | X31: 68.75 | Y31: =X31/$Y$25 -> 0.12557078 | Z31: 57.5 | AA31: =Z32/$AA$24 -> 0.13850416
B32: 45 | C32: Neutral | O32: =O8 -> RW | P32: 63.75 | Q32: =P32/$Q$25 -> 0.1311054 | R32: 72.5 | S32: =R32/$S$25 -> 0.1286031 | T32: 82.5 | U32: =T32/$U$25 -> 0.13253012 | V32: 33 | W32: =V32/$W$25 -> 0.13345466 | X32: 67.5 | Y32: =X32/$Y$25 -> 0.12328767 | Z32: 62.5 | AA32: =Z33/$AA$24 -> 0.13850416
B33: 55 | C33: Greed | O33: =O9 -> ETS | P33: 78.75 | Q33: =P33/$Q$25 -> 0.16195373 | R33: 72.5 | S33: =R33/$S$25 -> 0.1286031 | T33: 82.5 | U33: =T33/$U$25 -> 0.13253012 | V33: 23 | W33: =V33/$W$25 -> 0.093013851 | X33: 71.25 | Y33: =X33/$Y$25 -> 0.13013699 | Z33: 62.5 | AA33: =Z34/$AA$24 -> 0.11634349
B34: 75 | C34: Extreme Greed | O34: =O22 -> DynaMix | P34: 75 | Q34: =P34/$Q$25 -> 0.15424165 | R34: 73.75 | S34: =R34/$S$25 -> 0.1308204 | T34: 80 | U34: =T34/$U$25 -> 0.12851406 | V34: 21 | W34: =V34/$W$25 -> 0.08492569 | X34: 67.5 | Y34: =X34/$Y$25 -> 0.12328767 | Z34: 52.5
O35: AVR : | P35: =AVERAGE(P26:P34) -> 54.027778 | R35: =AVERAGE(R26:R34) -> 62.638889 | T35: =AVERAGE(T26:T34) -> 69.166667 | V35: =AVERAGE(V26:V34) -> 27.475 | X35: =AVERAGE(X26:X34) -> 60.833333 | Z35: =AVERAGE(Z26:Z34) -> 50.138889

Sheet 26-1-07
A1: model | B1: PyCaret | C1: ARIMAX | D1: PCE | E1: LSTM | F1: GARCH | G1: VAR | H1: RW | I1: ETS | J1: DynaMix | L1: 26-Q1-07 | O1: Accuracy | P1: TNX | Q1: =SUM(P2:P10) -> 696.99259 | R1: DJI | S1: =SUM(R2:R10) -> 795.37096 | T1: SPX | U1: =SUM(T2:T10) -> 793.01537 | V1: VIX | W1: =SUM(V2:V10) -> 765.20421 | X1: QQQ | Y1: =SUM(X2:X10) -> 787.1086 | Z1: AAPL | AA1: =SUM(Z2:Z10) -> 767.4878 | AC1: AVR-4 | AD1: AVR-6
A2: TNX | B2: 4.0602 | C2: 4.0356 | D2: 0 | E2: 4.0761 | F2: 4.0288 | G2: 0 | H2: 4.0269 | I2: 4.0268 | J2: 4.0464 | O2: =B1 -> PyCaret | P2: =100-ABS((($H10-B2)/($H10)))*100 -> 99.748148 | Q2: =P2/$Q$1 -> 0.14311221 | R2: =100-ABS((($H11-B3)/($H11)))*100 -> 98.109439 | S2: =R2/$S$1 -> 0.12335054 | T2: =100-ABS((($H12-B4)/($H12)))*100 -> 98.218684 | U2: =T2/$U$1 -> 0.1238547 | V2: =100-ABS((($H13-B5)/($H13)))*100 -> 89.238421 | W2: =V2/$W$1 -> 0.1166204 | X2: =100-ABS((($H14-B6)/($H14)))*100 -> 98.0318 | Y2: =X2/$Y$1 -> 0.12454673 | Z2: =100-ABS((($H15-B7)/($H15)))*100 -> 94.600985 | AA2: =Z2/$AA$1 -> 0.12326057 | AC2: =(R2+T2+V2+X2)/4 -> 95.899586 | AD2: =(P2+R2+T2+V2+X2+Z2)/6 -> 96.324579 | AE2: =IF($AC2=MAX(AC2:AC10),"TOP","")
A3: DJI | B3: 48564.172 | C3: 49474.57 | D3: 0 | E3: 49407.988 | F3: 49366.732 | G3: 49263.719 | H3: 49314.926 | I3: 49283.446 | J3: 49033.07 | L3: 2026/02/24 | O3: =C1 -> ARIMAX | P3: =100-ABS((($H10-C2)/($H10)))*100 -> 99.644444 | Q3: =P3/$Q$1 -> 0.14296342 | R3: =100-ABS((($H11-C3)/($H11)))*100 -> 99.948625 | S3: =R3/$S$1 -> 0.12566291 | T3: =100-ABS((($H12-C4)/($H12)))*100 -> 98.973037 | U3: =T3/$U$1 -> 0.12480595 | V3: =100-ABS((($H13-C5)/($H13)))*100 -> 96.003684 | W3: =V3/$W$1 -> 0.12546152 | X3: =100-ABS((($H14-C6)/($H14)))*100 -> 98.767083 | Y3: =X3/$Y$1 -> 0.12548088 | Z3: =100-ABS((($H15-C7)/($H15)))*100 -> 96.625682 | AA3: =Z3/$AA$1 -> 0.12589865 | AC3: =(R3+T3+V3+X3)/4 -> 98.423108 | AD3: =(P3+R3+T3+V3+X3+Z3)/6 -> 98.327093 | AE3: =IF($AC3=MAX(AC2:AC10),"TOP","")
A4: SPX | B4: 6977.1092 | C4: 6925.3983 | D4: 0 | E4: 6888.2836 | F4: 6937.9702 | G4: 6890.7587 | H4: 6911.7912 | I4: 6909.2234 | J4: 6878.2617 | O4: =D1 -> PCE | P4: =100-ABS((($H10-D2)/($H10)))*100 -> 0 | Q4: =P4/$Q$1 -> 0 | R4: =100-ABS((($H11-D3)/($H11)))*100 -> 0 | S4: =R4/$S$1 -> 0 | T4: =100-ABS((($H12-D4)/($H12)))*100 -> 0 | U4: =T4/$U$1 -> 0 | V4: =100-ABS((($H13-D5)/($H13)))*100 -> 0 | W4: =V4/$W$1 -> 0 | X4: =100-ABS((($H14-D6)/($H14)))*100 -> 0 | Y4: =X4/$Y$1 -> 0 | Z4: =100-ABS((($H15-D7)/($H15)))*100 -> 0 | AA4: =Z4/$AA$1 -> 0 | AC4: =(R4+T4+V4+X4)/4 -> 0 | AD4: =(P4+R4+T4+V4+X4+Z4)/6 -> 0 | AE4: =IF($AC4=MAX(AC2:AC10),"TOP","")
A5: VIX | B5: 16.9553 | C5: 19.7593 | D5: 0 | E5: 18.1835 | F5: 19.7964 | G5: 19.6944 | H5: 19.4091 | I5: 19.6078 | J5: 19.483 | L5: ML | O5: =E1 -> LSTM | P5: =100-ABS((($H10-E2)/($H10)))*100 -> 99.355556 | Q5: =P5/$Q$1 -> 0.14254894 | R5: =100-ABS((($H11-E3)/($H11)))*100 -> 99.814117 | S5: =R5/$S$1 -> 0.12549379 | T5: =100-ABS((($H12-E4)/($H12)))*100 -> 99.514462 | U5: =T5/$U$1 -> 0.12548869 | V5: =100-ABS((($H13-E5)/($H13)))*100 -> 95.702632 | W5: =V5/$W$1 -> 0.12506809 | X5: =100-ABS((($H14-E6)/($H14)))*100 -> 98.152367 | Y5: =X5/$Y$1 -> 0.1246999 | Z5: =100-ABS((($H15-E7)/($H15)))*100 -> 95.053674 | AA5: =Z5/$AA$1 -> 0.1238504 | AC5: =(R5+T5+V5+X5)/4 -> 98.295894 | AD5: =(P5+R5+T5+V5+X5+Z5)/6 -> 97.932135 | AE5: =IF($AC5=MAX(AC2:AC10),"TOP","")
A6: QQQ | B6: 611.8092 | C6: 607.3975 | D6: 0 | E6: 611.0858 | F6: 612.3191 | G6: 607.5304 | H6: 610.098 | I6: 608.0805 | J6: 609.0279 | O6: =F1 -> GARCH | P6: =100-ABS((($H10-F2)/($H10)))*100 -> 99.476543 | Q6: =P6/$Q$1 -> 0.14272253 | R6: =100-ABS((($H11-F3)/($H11)))*100 -> 99.730773 | S6: =R6/$S$1 -> 0.125389 | T6: =100-ABS((($H12-F4)/($H12)))*100 -> 98.78964 | U6: =T6/$U$1 -> 0.12457468 | V6: =100-ABS((($H13-F5)/($H13)))*100 -> 95.808421 | W6: =V6/$W$1 -> 0.12520634 | X6: =100-ABS((($H14-F6)/($H14)))*100 -> 97.946817 | Y6: =X6/$Y$1 -> 0.12443876 | Z6: =100-ABS((($H15-F7)/($H15)))*100 -> 95.440682 | AA6: =Z6/$AA$1 -> 0.12435466 | AC6: =(R6+T6+V6+X6)/4 -> 98.068913 | AD6: =(P6+R6+T6+V6+X6+Z6)/6 -> 97.865479 | AE6: =IF($AC6=MAX(AC2:AC10),"TOP","")
A7: AAPL | B7: 249.7466 | C7: 272.9082 | D7: 0 | E7: 277.0583 | F7: 276.0366 | G7: 273.9377 | H7: 273.009 | I7: 273.009 | J7: 273.62 | O7: =G1 -> VAR | P7: =100-ABS((($H10-G2)/($H10)))*100 -> 0 | Q7: =P7/$Q$1 -> 0 | R7: =100-ABS((($H11-G3)/($H11)))*100 -> 99.522665 | S7: =R7/$S$1 -> 0.12512736 | T7: =100-ABS((($H12-G4)/($H12)))*100 -> 99.478356 | U7: =T7/$U$1 -> 0.12544316 | V7: =100-ABS((($H13-G5)/($H13)))*100 -> 96.345263 | W7: =V7/$W$1 -> 0.12590791 | X7: =100-ABS((($H14-G6)/($H14)))*100 -> 98.744933 | Y7: =X7/$Y$1 -> 0.12545274 | Z7: =100-ABS((($H15-G7)/($H15)))*100 -> 96.23572 | AA7: =Z7/$AA$1 -> 0.12539055 | AC7: =(R7+T7+V7+X7)/4 -> 98.522804 | AD7: =(P7+R7+T7+V7+X7+Z7)/6 -> 81.721156 | AE7: =IF($AC7=MAX(AC2:AC10),"TOP","")
O8: =H1 -> RW | P8: =100-ABS((($H10-H2)/($H10)))*100 -> 99.42963 | Q8: =P8/$Q$1 -> 0.14265522 | R8: =100-ABS((($H11-H3)/($H11)))*100 -> 99.626114 | S8: =R8/$S$1 -> 0.12525742 | T8: =100-ABS((($H12-H4)/($H12)))*100 -> 99.171536 | U8: =T8/$U$1 -> 0.12505626 | V8: =100-ABS((($H13-H5)/($H13)))*100 -> 97.846842 | W8: =V8/$W$1 -> 0.12787023 | X8: =100-ABS((($H14-H6)/($H14)))*100 -> 98.317 | Y8: =X8/$Y$1 -> 0.12490907 | Z8: =100-ABS((($H15-H7)/($H15)))*100 -> 96.5875 | AA8: =Z8/$AA$1 -> 0.12584891 | AC8: =(R8+T8+V8+X8)/4 -> 98.740373 | AD8: =(P8+R8+T8+V8+X8+Z8)/6 -> 98.496437 | AE8: =IF($AC8=MAX(AC2:AC10),"TOP","") -> TOP
B9: Close YF | C9: Oraclum | D9: ML | F9: LLM | H9: +3-day | L9: =IF(L10<25,C30,IF(L10<45,C31,IF(L10<55,C32,IF(L10<75,C33,C34)))) -> Fear | O9: =I1 -> ETS | P9: =100-ABS((($H10-I2)/($H10)))*100 -> 99.42716 | Q9: =P9/$Q$1 -> 0.14265167 | R9: =100-ABS((($H11-I3)/($H11)))*100 -> 99.562517 | S9: =R9/$S$1 -> 0.12517746 | T9: =100-ABS((($H12-I4)/($H12)))*100 -> 99.208995 | U9: =T9/$U$1 -> 0.1251035 | V9: =100-ABS((($H13-I5)/($H13)))*100 -> 96.801053 | W9: =V9/$W$1 -> 0.12650355 | X9: =100-ABS((($H14-I6)/($H14)))*100 -> 98.65325 | Y9: =X9/$Y$1 -> 0.12533626 | Z9: =100-ABS((($H15-I7)/($H15)))*100 -> 96.5875 | AA9: =Z9/$AA$1 -> 0.12584891 | AC9: =(R9+T9+V9+X9)/4 -> 98.556454 | AD9: =(P9+R9+T9+V9+X9+Z9)/6 -> 98.373413 | AE9: =IF($AC9=MAX(AC2:AC10),"TOP","")
A10: TNX | B10: 4.033 | C10: 4.044 | D10: =(B2*Q26)+(C2*Q27)+(D2*Q28)+(E2*Q29)+(F2*Q30)+(G2*Q31)+(H2*Q32)+(I2*Q33)+(J2*Q34) -> 4.0421697 | E10: =D10/$H$10 -> 0.99806658 | F10: 4.0388972 | G10: =F10/$H$10 -> 0.99725858 | H10: 4.05 | L10: 43 | O10: =J1 -> DynaMix | P10: =100-ABS((($H10-J2)/($H10)))*100 -> 99.911111 | Q10: =P10/$Q$1 -> 0.14334602 | R10: =100-ABS((($H11-J3)/($H11)))*100 -> 99.056707 | S10: =R10/$S$1 -> 0.12454152 | T10: =100-ABS((($H12-J4)/($H12)))*100 -> 99.660661 | U10: =T10/$U$1 -> 0.12567305 | V10: =100-ABS((($H13-J5)/($H13)))*100 -> 97.457895 | W10: =V10/$W$1 -> 0.12736194 | X10: =100-ABS((($H14-J6)/($H14)))*100 -> 98.49535 | Y10: =X10/$Y$1 -> 0.12513565 | Z10: =100-ABS((($H15-J7)/($H15)))*100 -> 96.356061 | AA10: =Z10/$AA$1 -> 0.12554735 | AC10: =(R10+T10+V10+X10)/4 -> 98.667653 | AD10: =(P10+R10+T10+V10+X10+Z10)/6 -> 98.489631 | AE10: =IF($AC10=MAX(AC2:AC10),"TOP","")
A11: DJI | B11: 49174.5 | C11: 48818.85 | D11: =(B3*S26)+(C3*S27)+(D3*S28)+(E3*S29)+(F3*S30)+(G3*S31)+(H3*S32)+(I3*S33)+(J3*S34) -> 49221.088 | E11: =D11/$H$11 -> 0.99436541 | F11: 49251.484 | G11: =F11/$H$11 -> 0.99497947 | H11: 49500 | O11: AVR : | P11: =SUM(P2:P10)/8 -> 87.124074 | R11: =AVERAGE(R2:R10) -> 88.374551 | T11: =AVERAGE(T2:T10) -> 88.112819 | V11: =AVERAGE(V2:V10) -> 85.02269 | X11: =AVERAGE(X2:X10) -> 87.456511 | Z11: =AVERAGE(Z2:Z10) -> 85.276423
A12: SPX | B12: 6890.07 | C12: 6837.74 | D12: =(B4*U26)+(C4*U27)+(D4*U28)+(E4*U29)+(F4*U30)+(G4*U31)+(H4*U32)+(I4*U33)+(J4*U34) -> 6912.7657 | E12: =D12/$H$12 -> 1.0084268 | F12: 6907.2033 | G12: =F12/$H$12 -> 1.0076154 | H12: 6855
A13: VIX | B13: 19.55 | C13: 19.55 | D13: =(B5*W26)+(C5*W27)+(D5*W28)+(E5*W29)+(F5*W30)+(G5*W31)+(H5*W32)+(I5*W33)+(J5*W34) -> 18.934458 | E13: =D13/$H$13 -> 0.99655043 | F13: 19.318179 | G13: =F13/$H$13 -> 1.0167463 | H13: 19 | O13: Update | P13: TNX | Q13: =SUM(P14:P22) -> 595 | R13: DJI | S13: =SUM(R14:R22) -> 690 | T13: SPX | U13: =SUM(T14:T22) -> 615 | V13: VIX | W13: =SUM(V14:V22) -> 360 | X13: QQQ | Y13: =SUM(X14:X22) -> 530 | Z13: AAPL | AA13: =SUM(Z14:Z22) -> 360 | AC13: Value | AD13: Assign
A14: QQQ | B14: 607.87 | C14: 607.87 | D14: =(B6*Y26)+(C6*Y27)+(D6*Y28)+(E6*Y29)+(F6*Y30)+(G6*Y31)+(H6*Y32)+(I6*Y33)+(J6*Y34) -> 609.60971 | E14: =D14/$H$14 -> 1.0160162 | F14: 609.91082 | G14: =F14/$H$14 -> 1.016518 | H14: 600 | O14: =O2 -> PyCaret | P14: =IF(P2=0,0, LOOKUP(P2-0.000000000001,$AC$14:$AC$30,$AD$14:$AD$30)) -> 90 | Q14: =P14/$Q$13 -> 0.1512605 | R14: =IF(R2=0,0, LOOKUP(R2-0.000000000001,$AC$14:$AC$30,$AD$14:$AD$30)) -> 65 | S14: =R14/$S$13 -> 0.094202899 | T14: =IF(T2=0,0, LOOKUP(T2-0.000000000001,$AC$14:$AC$30,$AD$14:$AD$30)) -> 65 | U14: =T14/$U$13 -> 0.10569106 | V14: =IF(V2=0,0, LOOKUP(V2-0.000000000001,$AC$14:$AC$30,$AD$14:$AD$30)) -> 10 | W14: =V14/$W$13 -> 0.027777778 | X14: =IF(X2=0,0, LOOKUP(X2-0.000000000001,$AC$14:$AC$30,$AD$14:$AD$30)) -> 65 | Y14: =X14/$Y$13 -> 0.12264151 | Z14: =IF(Z2=0,0, LOOKUP(Z2-0.000000000001,$AC$14:$AC$30,$AD$14:$AD$30)) -> 30 | AA14: =Z14/$AA$13 -> 0.083333333 | AC14: 1 | AD14: 0.1
A15: AAPL | B15: 272.14 | C15: 272.19 | D15: =(B7*AA25)+(C7*AA26)+(D7*AA27)+(E7*AA28)+(F7*AA29)+(G7*AA30)+(H7*AA31)+(I7*AA32)+(J7*AA33) -> 271.24407 | E15: =D15/$H$15 -> 1.0274397 | F15: 274.37624 | G15: =F15/$H$15 -> 1.0393039 | H15: 264 | O15: =O3 -> ARIMAX | P15: =IF(P3=0,0, LOOKUP(P3-0.000000000001,$AC$14:$AC$30,$AD$14:$AD$30)) -> 90 | Q15: =P15/$Q$13 -> 0.1512605 | R15: =IF(R3=0,0, LOOKUP(R3-0.000000000001,$AC$14:$AC$30,$AD$14:$AD$30)) -> 95 | S15: =R15/$S$13 -> 0.13768116 | T15: =IF(T3=0,0, LOOKUP(T3-0.000000000001,$AC$14:$AC$30,$AD$14:$AD$30)) -> 70 | U15: =T15/$U$13 -> 0.11382114 | V15: =IF(V3=0,0, LOOKUP(V3-0.000000000001,$AC$14:$AC$30,$AD$14:$AD$30)) -> 50 | W15: =V15/$W$13 -> 0.13888889 | X15: =IF(X3=0,0, LOOKUP(X3-0.000000000001,$AC$14:$AC$30,$AD$14:$AD$30)) -> 70 | Y15: =X15/$Y$13 -> 0.13207547 | Z15: =IF(Z3=0,0, LOOKUP(Z3-0.000000000001,$AC$14:$AC$30,$AD$14:$AD$30)) -> 50 | AA15: =Z15/$AA$13 -> 0.13888889 | AC15: 80 | AD15: 1
O16: =O4 -> PCE | P16: =IF(P4=0,0, LOOKUP(P4-0.000000000001,$AC$14:$AC$30,$AD$14:$AD$30)) -> 0 | Q16: =P16/$Q$13 -> 0 | R16: =IF(R4=0,0, LOOKUP(R4-0.000000000001,$AC$14:$AC$30,$AD$14:$AD$30)) -> 0 | S16: =R16/$S$13 -> 0 | T16: =IF(T4=0,0, LOOKUP(T4-0.000000000001,$AC$14:$AC$30,$AD$14:$AD$30)) -> 0 | U16: =T16/$U$13 -> 0 | V16: =IF(V4=0,0, LOOKUP(V4-0.000000000001,$AC$14:$AC$30,$AD$14:$AD$30)) -> 0 | W16: =V16/$W$13 -> 0 | X16: =IF(X4=0,0, LOOKUP(X4-0.000000000001,$AC$14:$AC$30,$AD$14:$AD$30)) -> 0 | Y16: =X16/$Y$13 -> 0 | Z16: =IF(Z4=0,0, LOOKUP(Z4-0.000000000001,$AC$14:$AC$30,$AD$14:$AD$30)) -> 0 | AA16: =Z16/$AA$13 -> 0 | AC16: 82.5 | AD16: 2
A17: =F9 -> LLM | B17: RD | D17: 85220 | F17: MICH | H17: max-Q | O17: =O5 -> LSTM | P17: =IF(P5=0,0, LOOKUP(P5-0.000000000001,$AC$14:$AC$30,$AD$14:$AD$30)) -> 80 | Q17: =P17/$Q$13 -> 0.13445378 | R17: =IF(R5=0,0, LOOKUP(R5-0.000000000001,$AC$14:$AC$30,$AD$14:$AD$30)) -> 95 | S17: =R17/$S$13 -> 0.13768116 | T17: =IF(T5=0,0, LOOKUP(T5-0.000000000001,$AC$14:$AC$30,$AD$14:$AD$30)) -> 90 | U17: =T17/$U$13 -> 0.14634146 | V17: =IF(V5=0,0, LOOKUP(V5-0.000000000001,$AC$14:$AC$30,$AD$14:$AD$30)) -> 40 | W17: =V17/$W$13 -> 0.11111111 | X17: =IF(X5=0,0, LOOKUP(X5-0.000000000001,$AC$14:$AC$30,$AD$14:$AD$30)) -> 65 | Y17: =X17/$Y$13 -> 0.12264151 | Z17: =IF(Z5=0,0, LOOKUP(Z5-0.000000000001,$AC$14:$AC$30,$AD$14:$AD$30)) -> 40 | AA17: =Z17/$AA$13 -> 0.11111111 | AC17: 85 | AD17: 5
A18: TNX | B18: 4.02 | C18: =1-ABS(1-B18/$H$10) -> 0.99259259 | D18: 4.05 | E18: =1-ABS(1-D18/$H$10) -> 1 | F18: 4.06 | G18: =1-ABS(1-F18/$H$10) -> 0.99753086 | H18: TNX | I18: =MAX(P2:P10) -> 99.911111 | J18: G | O18: =O6 -> GARCH | P18: =IF(P6=0,0, LOOKUP(P6-0.000000000001,$AC$14:$AC$30,$AD$14:$AD$30)) -> 80 | Q18: =P18/$Q$13 -> 0.13445378 | R18: =IF(R6=0,0, LOOKUP(R6-0.000000000001,$AC$14:$AC$30,$AD$14:$AD$30)) -> 90 | S18: =R18/$S$13 -> 0.13043478 | T18: =IF(T6=0,0, LOOKUP(T6-0.000000000001,$AC$14:$AC$30,$AD$14:$AD$30)) -> 70 | U18: =T18/$U$13 -> 0.11382114 | V18: =IF(V6=0,0, LOOKUP(V6-0.000000000001,$AC$14:$AC$30,$AD$14:$AD$30)) -> 40 | W18: =V18/$W$13 -> 0.11111111 | X18: =IF(X6=0,0, LOOKUP(X6-0.000000000001,$AC$14:$AC$30,$AD$14:$AD$30)) -> 60 | Y18: =X18/$Y$13 -> 0.11320755 | Z18: =IF(Z6=0,0, LOOKUP(Z6-0.000000000001,$AC$14:$AC$30,$AD$14:$AD$30)) -> 40 | AA18: =Z18/$AA$13 -> 0.11111111 | AC18: 87.5 | AD18: 10
A19: DJI | B19: 49515 | C19: =1-ABS(1-B19/$H$11) -> 0.99969697 | D19: 49583 | E19: =1-ABS(1-D19/$H$11) -> 0.99832323 | F19: 49310 | G19: =1-ABS(1-F19/$H$11) -> 0.99616162 | H19: DJI | I19: =MAX(R2:R10) -> 99.948625 | J19: R | O19: =O7 -> VAR | P19: =IF(P7=0,0, LOOKUP(P7-0.000000000001,$AC$14:$AC$30,$AD$14:$AD$30)) -> 0 | Q19: =P19/$Q$13 -> 0 | R19: =IF(R7=0,0, LOOKUP(R7-0.000000000001,$AC$14:$AC$30,$AD$14:$AD$30)) -> 90 | S19: =R19/$S$13 -> 0.13043478 | T19: =IF(T7=0,0, LOOKUP(T7-0.000000000001,$AC$14:$AC$30,$AD$14:$AD$30)) -> 80 | U19: =T19/$U$13 -> 0.1300813 | V19: =IF(V7=0,0, LOOKUP(V7-0.000000000001,$AC$14:$AC$30,$AD$14:$AD$30)) -> 50 | W19: =V19/$W$13 -> 0.13888889 | X19: =IF(X7=0,0, LOOKUP(X7-0.000000000001,$AC$14:$AC$30,$AD$14:$AD$30)) -> 70 | Y19: =X19/$Y$13 -> 0.13207547 | Z19: =IF(Z7=0,0, LOOKUP(Z7-0.000000000001,$AC$14:$AC$30,$AD$14:$AD$30)) -> 50 | AA19: =Z19/$AA$13 -> 0.13888889 | AC19: 90 | AD19: 20
A20: SPX | B20: 6907 | C20: =1-ABS(1-B20/$H$12) -> 0.9924143 | D20: 6913 | E20: =1-ABS(1-D20/$H$12) -> 0.99153902 | F20: 6919 | G20: =1-ABS(1-F20/$H$12) -> 0.99066375 | H20: SPX | I20: =MAX(T2:T10) -> 99.660661 | J20: A | O20: =O8 -> RW | P20: =IF(P8=0,0, LOOKUP(P8-0.000000000001,$AC$14:$AC$30,$AD$14:$AD$30)) -> 80 | Q20: =P20/$Q$13 -> 0.13445378 | R20: =IF(R8=0,0, LOOKUP(R8-0.000000000001,$AC$14:$AC$30,$AD$14:$AD$30)) -> 90 | S20: =R20/$S$13 -> 0.13043478 | T20: =IF(T8=0,0, LOOKUP(T8-0.000000000001,$AC$14:$AC$30,$AD$14:$AD$30)) -> 75 | U20: =T20/$U$13 -> 0.12195122 | V20: =IF(V8=0,0, LOOKUP(V8-0.000000000001,$AC$14:$AC$30,$AD$14:$AD$30)) -> 60 | W20: =V20/$W$13 -> 0.16666667 | X20: =IF(X8=0,0, LOOKUP(X8-0.000000000001,$AC$14:$AC$30,$AD$14:$AD$30)) -> 65 | Y20: =X20/$Y$13 -> 0.12264151 | Z20: =IF(Z8=0,0, LOOKUP(Z8-0.000000000001,$AC$14:$AC$30,$AD$14:$AD$30)) -> 50 | AA20: =Z20/$AA$13 -> 0.13888889 | AC20: 92.5 | AD20: 30
A21: VIX | B21: 18.4 | C21: =1-ABS(1-B21/$H$13) -> 0.96842105 | D21: 18.65 | E21: =1-ABS(1-D21/$H$13) -> 0.98157895 | F21: 19.21 | G21: =1-ABS(1-F21/$H$13) -> 0.98894737 | H21: VIX | I21: =MAX(V2:V10) -> 97.846842 | J21: E | O21: =O9 -> ETS | P21: =IF(P9=0,0, LOOKUP(P9-0.000000000001,$AC$14:$AC$30,$AD$14:$AD$30)) -> 80 | Q21: =P21/$Q$13 -> 0.13445378 | R21: =IF(R9=0,0, LOOKUP(R9-0.000000000001,$AC$14:$AC$30,$AD$14:$AD$30)) -> 90 | S21: =R21/$S$13 -> 0.13043478 | T21: =IF(T9=0,0, LOOKUP(T9-0.000000000001,$AC$14:$AC$30,$AD$14:$AD$30)) -> 75 | U21: =T21/$U$13 -> 0.12195122 | V21: =IF(V9=0,0, LOOKUP(V9-0.000000000001,$AC$14:$AC$30,$AD$14:$AD$30)) -> 50 | W21: =V21/$W$13 -> 0.13888889 | X21: =IF(X9=0,0, LOOKUP(X9-0.000000000001,$AC$14:$AC$30,$AD$14:$AD$30)) -> 70 | Y21: =X21/$Y$13 -> 0.13207547 | Z21: =IF(Z9=0,0, LOOKUP(Z9-0.000000000001,$AC$14:$AC$30,$AD$14:$AD$30)) -> 50 | AA21: =Z21/$AA$13 -> 0.13888889 | AC21: 95 | AD21: 40
A22: QQQ | B22: 613.3 | C22: =1-ABS(1-B22/$H$14) -> 0.97783333 | D22: 615.4 | E22: =1-ABS(1-D22/$H$14) -> 0.97433333 | F22: 609.9 | G22: =1-ABS(1-F22/$H$14) -> 0.9835 | H22: QQQ | I22: =MAX(X2:X10) -> 98.767083 | J22: A | O22: =O10 -> DynaMix | P22: =IF(P10=0,0, LOOKUP(P10-0.000000000001,$AC$14:$AC$30,$AD$14:$AD$30)) -> 95 | Q22: =P22/$Q$13 -> 0.15966387 | R22: =IF(R10=0,0, LOOKUP(R10-0.000000000001,$AC$14:$AC$30,$AD$14:$AD$30)) -> 75 | S22: =R22/$S$13 -> 0.10869565 | T22: =IF(T10=0,0, LOOKUP(T10-0.000000000001,$AC$14:$AC$30,$AD$14:$AD$30)) -> 90 | U22: =T22/$U$13 -> 0.14634146 | V22: =IF(V10=0,0, LOOKUP(V10-0.000000000001,$AC$14:$AC$30,$AD$14:$AD$30)) -> 60 | W22: =V22/$W$13 -> 0.16666667 | X22: =IF(X10=0,0, LOOKUP(X10-0.000000000001,$AC$14:$AC$30,$AD$14:$AD$30)) -> 65 | Y22: =X22/$Y$13 -> 0.12264151 | Z22: =IF(Z10=0,0, LOOKUP(Z10-0.000000000001,$AC$14:$AC$30,$AD$14:$AD$30)) -> 50 | AA22: =Z22/$AA$13 -> 0.13888889 | AC22: 96 | AD22: 50
A23: AAPL | B23: 273.2 | C23: =1-ABS(1-B23/$H$15) -> 0.96515152 | D23: 274.3 | E23: =1-ABS(1-D23/$H$15) -> 0.96098485 | F23: 272.9 | G23: =1-ABS(1-F23/$H$15) -> 0.96628788 | H23: AAPL | I23: =MAX(Z2:Z10) -> 96.625682 | J23: V | O23: AVR : | P23: =AVERAGE(P14:P22) -> 66.111111 | R23: =AVERAGE(R14:R22) -> 76.666667 | T23: =AVERAGE(T14:T22) -> 68.333333 | V23: =AVERAGE(V14:V22) -> 40 | X23: =AVERAGE(X14:X22) -> 58.888889 | Z23: =AVERAGE(Z14:Z22) -> 40 | AC23: 97 | AD23: 60
AA24: =SUM(Z26:Z34) -> 451.25 | AC24: 98 | AD24: 65
A25: =AC1 -> AVR-4 | B25: {=SUM(C19:C22/4)} -> 0.98459141 | D25: {=SUM(E19:E22/4)} -> 0.98644363 | F25: {=SUM(G19:G22/4)} -> 0.98981818 | H25: max-Q AVR-4 | J25: =AVERAGE(I19:I22) -> 99.055803 | O25: History | P25: TNX | Q25: =SUM(P26:P34) -> 486.25 | R25: DJI | S25: =SUM(R26:R34) -> 563.75 | T25: SPX | U25: =SUM(T26:T34) -> 622.5 | V25: VIX | W25: =SUM(V26:V34) -> 247.275 | X25: QQQ | Y25: =SUM(X26:X34) -> 547.5 | Z25: AAPL | AA25: =Z26/$AA$24 -> 0.11911357 | AC25: 98.5 | AD25: 70
A26: =AD1 -> AVR-6 | B26: {=SUM(C18:C23/6)} -> 0.98268496 | D26: {=SUM(E18:E23/6)} -> 0.9844599 | F26: {=SUM(G18:G23/6)} -> 0.98718191 | H26: max AVR-6 | J26: =AVERAGE(I18:I23) -> 98.793334 | O26: =O2 -> PyCaret | P26: 60 | Q26: =P26/$Q$25 -> 0.12339332 | R26: 62.5 | S26: =R26/$S$25 -> 0.11086475 | T26: 61.25 | U26: =T26/$U$25 -> 0.098393574 | V26: 50 | W26: =V26/$W$25 -> 0.20220402 | X26: 72.5 | Y26: =X26/$Y$25 -> 0.13242009 | Z26: 53.75 | AA26: =Z27/$AA$24 -> 0.12188366 | AC26: 99 | AD26: 75
O27: =O3 -> ARIMAX | P27: 65 | Q27: =P27/$Q$25 -> 0.13367609 | R27: 65 | S27: =R27/$S$25 -> 0.11529933 | T27: 77.5 | U27: =T27/$U$25 -> 0.12449799 | V27: 29.25 | W27: =V27/$W$25 -> 0.11828935 | X27: 75 | Y27: =X27/$Y$25 -> 0.1369863 | Z27: 55 | AA27: =Z28/$AA$24 -> 0 | AC27: 99.25 | AD27: 80
A28: https://feargreedmeter.com/fear-and-greed-index | O28: =O4 -> PCE | P28: 0 | Q28: =P28/$Q$25 -> 0 | R28: 0 | S28: =R28/$S$25 -> 0 | T28: 0 | U28: =T28/$U$25 -> 0 | V28: 0 | W28: =V28/$W$25 -> 0 | X28: 0 | Y28: =X28/$Y$25 -> 0 | Z28: 0 | AA28: =Z29/$AA$24 -> 0.10526316 | AC28: 99.5 | AD28: 90
O29: =O5 -> LSTM | P29: 66.25 | Q29: =P29/$Q$25 -> 0.13624679 | R29: 73.75 | S29: =R29/$S$25 -> 0.1308204 | T29: 77.5 | U29: =T29/$U$25 -> 0.12449799 | V29: 26.775 | W29: =V29/$W$25 -> 0.10828025 | X29: 60 | Y29: =X29/$Y$25 -> 0.10958904 | Z29: 47.5 | AA29: =Z30/$AA$24 -> 0.13296399 | AC29: 99.75 | AD29: 95
A30: Scale | B30: 0 | C30: Extreme Fear | O30: =O6 -> GARCH | P30: 77.5 | Q30: =P30/$Q$25 -> 0.15938303 | R30: 70 | S30: =R30/$S$25 -> 0.12416851 | T30: 77.5 | U30: =T30/$U$25 -> 0.12449799 | V30: 33.75 | W30: =V30/$W$25 -> 0.13648772 | X30: 65 | Y30: =X30/$Y$25 -> 0.11872146 | Z30: 60 | AA30: =Z31/$AA$24 -> 0.12742382 | AC30: 99.99 | AD30: 100
B31: 25 | C31: Fear | O31: =O7 -> VAR | P31: 0 | Q31: =P31/$Q$25 -> 0 | R31: 73.75 | S31: =R31/$S$25 -> 0.1308204 | T31: 83.75 | U31: =T31/$U$25 -> 0.13453815 | V31: 30.5 | W31: =V31/$W$25 -> 0.12334445 | X31: 68.75 | Y31: =X31/$Y$25 -> 0.12557078 | Z31: 57.5 | AA31: =Z32/$AA$24 -> 0.13850416
B32: 45 | C32: Neutral | O32: =O8 -> RW | P32: 63.75 | Q32: =P32/$Q$25 -> 0.1311054 | R32: 72.5 | S32: =R32/$S$25 -> 0.1286031 | T32: 82.5 | U32: =T32/$U$25 -> 0.13253012 | V32: 33 | W32: =V32/$W$25 -> 0.13345466 | X32: 67.5 | Y32: =X32/$Y$25 -> 0.12328767 | Z32: 62.5 | AA32: =Z33/$AA$24 -> 0.13850416
B33: 55 | C33: Greed | O33: =O9 -> ETS | P33: 78.75 | Q33: =P33/$Q$25 -> 0.16195373 | R33: 72.5 | S33: =R33/$S$25 -> 0.1286031 | T33: 82.5 | U33: =T33/$U$25 -> 0.13253012 | V33: 23 | W33: =V33/$W$25 -> 0.093013851 | X33: 71.25 | Y33: =X33/$Y$25 -> 0.13013699 | Z33: 62.5 | AA33: =Z34/$AA$24 -> 0.11634349
B34: 75 | C34: Extreme Greed | O34: =O22 -> DynaMix | P34: 75 | Q34: =P34/$Q$25 -> 0.15424165 | R34: 73.75 | S34: =R34/$S$25 -> 0.1308204 | T34: 80 | U34: =T34/$U$25 -> 0.12851406 | V34: 21 | W34: =V34/$W$25 -> 0.08492569 | X34: 67.5 | Y34: =X34/$Y$25 -> 0.12328767 | Z34: 52.5
O35: AVR : | P35: =AVERAGE(P26:P34) -> 54.027778 | R35: =AVERAGE(R26:R34) -> 62.638889 | T35: =AVERAGE(T26:T34) -> 69.166667 | V35: =AVERAGE(V26:V34) -> 27.475 | X35: =AVERAGE(X26:X34) -> 60.833333 | Z35: =AVERAGE(Z26:Z34) -> 50.138889

Sheet AVR
A18: 1-09 | B18: TNX | C18: 565 | D18: DJI | E18: 670 | F18: SPX | G18: 645 | H18: VIX | I18: 80.6 | J18: QQQ | K18: 600.1 | L18: AAPL | M18: 625 | O18: TNX | Q18: DJI | S18: SPX | U18: VIX | W18: QQQ | Y18: AAPL | AA18: TNX | AC18: DJI | AE18: SPX | AG18: VIX | AI18: QQQ | AK18: AAPL | AM18: =AM29 -> 4
A19: =A30 -> PyCaret | B19: 90 | C19: 0.15929204 | D19: 60 | E19: 0.089552239 | F19: 75 | G19: 0.11627907 | H19: 0.1 | I19: 0.0012406948 | J19: 90 | K19: 0.149975 | L19: 75 | M19: 0.12 | O19: =AA19/$AM$172 -> 80 | Q19: =AC19/$AM$172 -> 61.25 | S19: =AE19/$AM$172 -> 62.5 | U19: =AG19/$AM$172 -> 11.3 | W19: =AI19/$AM$172 -> 83.75 | Y19: =AK19/$AM$172 -> 60 | AA19: =(B63+B52+B41+B30) -> 320 | AC19: =(D63+D52+D41+D30) -> 245 | AE19: =(F63+F52+F41+F30) -> 250 | AG19: =(H63+H52+H41+H30) -> 45.2 | AI19: =(J63+J52+J41+J30) -> 335 | AK19: =(L63+L52+L41+L30) -> 240
A20: =A31 -> ARIMAX | B20: 70 | C20: 0.12389381 | D20: 80 | E20: 0.11940299 | F20: 70 | G20: 0.10852713 | H20: 0.1 | I20: 0.0012406948 | J20: 65 | K20: 0.10831528 | L20: 90 | M20: 0.144 | O20: =AA20/$AM$172 -> 63.75 | Q20: =AC20/$AM$172 -> 72.5 | S20: =AE20/$AM$172 -> 73.75 | U20: =AG20/$AM$172 -> 1.8 | W20: =AI20/$AM$172 -> 71.25 | Y20: =AK20/$AM$172 -> 67.5 | AA20: =(B64+B53+B42+B31) -> 255 | AC20: =(D64+D53+D42+D31) -> 290 | AE20: =(F64+F53+F42+F31) -> 295 | AG20: =(H64+H53+H42+H31) -> 7.2 | AI20: =(J64+J53+J42+J31) -> 285 | AK20: =(L64+L53+L42+L31) -> 270
A21: =A32 -> PCE | B21: 80 | C21: 0.14159292 | D21: 65 | E21: 0.097014925 | F21: 65 | G21: 0.10077519 | H21: 60 | I21: 0.74441687 | J21: 60 | K21: 0.099983336 | L21: 70 | M21: 0.112 | O21: =AA21/$AM$172 -> 40 | Q21: =AC21/$AM$172 -> 32.5 | S21: =AE21/$AM$172 -> 32.5 | U21: =AG21/$AM$172 -> 30 | W21: =AI21/$AM$172 -> 30 | Y21: =AK21/$AM$172 -> 35 | AA21: =(B65+B54+B43+B32) -> 160 | AC21: =(D65+D54+D43+D32) -> 130 | AE21: =(F65+F54+F43+F32) -> 130 | AG21: =(H65+H54+H43+H32) -> 120 | AI21: =(J65+J54+J43+J32) -> 120 | AK21: =(L65+L54+L43+L32) -> 140
A22: =A33 -> LSTM | B22: 70 | C22: 0.12389381 | D22: 95 | E22: 0.14179104 | F22: 75 | G22: 0.11627907 | H22: 10 | I22: 0.12406948 | J22: 95 | K22: 0.15830695 | L22: 30 | M22: 0.048 | O22: =AA22/$AM$172 -> 65 | Q22: =AC22/$AM$172 -> 82.5 | S22: =AE22/$AM$172 -> 70 | U22: =AG22/$AM$172 -> 5.525 | W22: =AI22/$AM$172 -> 77.5 | Y22: =AK22/$AM$172 -> 32.5 | AA22: =(B66+B55+B44+B33) -> 260 | AC22: =(D66+D55+D44+D33) -> 330 | AE22: =(F66+F55+F44+F33) -> 280 | AG22: =(H66+H55+H44+H33) -> 22.1 | AI22: =(J66+J55+J44+J33) -> 310 | AK22: =(L66+L55+L44+L33) -> 130
A23: =A34 -> GARCH | B23: 65 | C23: 0.11504425 | D23: 75 | E23: 0.1119403 | F23: 75 | G23: 0.11627907 | H23: 10 | I23: 0.12406948 | J23: 95 | K23: 0.15830695 | L23: 30 | M23: 0.048 | O23: =AA23/$AM$172 -> 71.25 | Q23: =AC23/$AM$172 -> 70 | S23: =AE23/$AM$172 -> 72.5 | U23: =AG23/$AM$172 -> 7.5 | W23: =AI23/$AM$172 -> 80 | Y23: =AK23/$AM$172 -> 36.25 | AA23: =(B67+B56+B45+B34) -> 285 | AC23: =(D67+D56+D45+D34) -> 280 | AE23: =(F67+F56+F45+F34) -> 290 | AG23: =(H67+H56+H45+H34) -> 30 | AI23: =(J67+J56+J45+J34) -> 320 | AK23: =(L67+L56+L45+L34) -> 145
A24: =A35 -> VAR | B24: 0 | C24: 0 | D24: 75 | E24: 0.1119403 | F24: 65 | G24: 0.10077519 | H24: 0.1 | I24: 0.0012406948 | J24: 65 | K24: 0.10831528 | L24: 70 | M24: 0.112 | O24: =AA24/$AM$172 -> 15 | Q24: =AC24/$AM$172 -> 73.75 | S24: =AE24/$AM$172 -> 73.75 | U24: =AG24/$AM$172 -> 1.8 | W24: =AI24/$AM$172 -> 68.75 | Y24: =AK24/$AM$172 -> 57.5 | AA24: =(B68+B57+B46+B35) -> 60 | AC24: =(D68+D57+D46+D35) -> 295 | AE24: =(F68+F57+F46+F35) -> 295 | AG24: =(H68+H57+H46+H35) -> 7.2 | AI24: =(J68+J57+J46+J35) -> 275 | AK24: =(L68+L57+L46+L35) -> 230
A25: =A36 -> RW | B25: 70 | C25: 0.12389381 | D25: 75 | E25: 0.1119403 | F25: 70 | G25: 0.10852713 | H25: 0.1 | I25: 0.0012406948 | J25: 65 | K25: 0.10831528 | L25: 95 | M25: 0.152 | O25: =AA25/$AM$172 -> 58.75 | Q25: =AC25/$AM$172 -> 72.5 | S25: =AE25/$AM$172 -> 75 | U25: =AG25/$AM$172 -> 1.8 | W25: =AI25/$AM$172 -> 67.5 | Y25: =AK25/$AM$172 -> 78.75 | AA25: =(B69+B58+B47+B36) -> 235 | AC25: =(D69+D58+D47+D36) -> 290 | AE25: =(F69+F58+F47+F36) -> 300 | AG25: =(H69+H58+H47+H36) -> 7.2 | AI25: =(J69+J58+J47+J36) -> 270 | AK25: =(L69+L58+L47+L36) -> 315
A26: =A37 -> ETS | B26: 70 | C26: 0.12389381 | D26: 80 | E26: 0.11940299 | F26: 70 | G26: 0.10852713 | H26: 0.1 | I26: 0.0012406948 | J26: 0.1 | K26: 0.00016663889 | L26: 95 | M26: 0.152 | O26: =AA26/$AM$172 -> 73.75 | Q26: =AC26/$AM$172 -> 75 | S26: =AE26/$AM$172 -> 75 | U26: =AG26/$AM$172 -> 1.8 | W26: =AI26/$AM$172 -> 38.8 | Y26: =AK26/$AM$172 -> 78.75 | AA26: =(B70+B59+B48+B37) -> 295 | AC26: =(D70+D59+D48+D37) -> 300 | AE26: =(F70+F59+F48+F37) -> 300 | AG26: =(H70+H59+H48+H37) -> 7.2 | AI26: =(J70+J59+J48+J37) -> 155.2 | AK26: =(L70+L59+L48+L37) -> 315
A27: =A38 -> DynaMix | B27: 50 | C27: 0.088495575 | D27: 65 | E27: 0.097014925 | F27: 80 | G27: 0.12403101 | H27: 0.1 | I27: 0.0012406948 | J27: 65 | K27: 0.10831528 | L27: 70 | M27: 0.112 | O27: =AA27/$AM$172 -> 63.75 | Q27: =AC27/$AM$172 -> 68.75 | S27: =AE27/$AM$172 -> 78.75 | U27: =AG27/$AM$172 -> 1.05 | W27: =AI27/$AM$172 -> 68.75 | Y27: =AK27/$AM$172 -> 58.75 | AA27: =(B71+B60+B49+B38) -> 255 | AC27: =(D71+D60+D49+D38) -> 275 | AE27: =(F71+F60+F49+F38) -> 315 | AG27: =(H71+H60+H49+H38) -> 4.2 | AI27: =(J71+J60+J49+J38) -> 275 | AK27: =(L71+L60+L49+L38) -> 235
A29: 1-08 | B29: TNX | C29: 565 | D29: DJI | E29: 670 | F29: SPX | G29: 645 | H29: VIX | I29: 80.6 | J29: QQQ | K29: 600.1 | L29: AAPL | M29: 625 | O29: TNX | Q29: DJI | S29: SPX | U29: VIX | W29: QQQ | Y29: AAPL | AA29: TNX | AC29: DJI | AE29: SPX | AG29: VIX | AI29: QQQ | AK29: AAPL | AM29: =AM40 -> 4
A30: =A41 -> PyCaret | B30: 90 | C30: 0.15929204 | D30: 60 | E30: 0.089552239 | F30: 75 | G30: 0.11627907 | H30: 0.1 | I30: 0.0012406948 | J30: 90 | K30: 0.149975 | L30: 75 | M30: 0.12 | O30: =AA30/$AM$172 -> 65 | Q30: =AC30/$AM$172 -> 61.25 | S30: =AE30/$AM$172 -> 60 | U30: =AG30/$AM$172 -> 31.275 | W30: =AI30/$AM$172 -> 76.25 | Y30: =AK30/$AM$172 -> 48.75 | AA30: =(B74+B63+B52+B41) -> 260 | AC30: =(D74+D63+D52+D41) -> 245 | AE30: =(F74+F63+F52+F41) -> 240 | AG30: =(H74+H63+H52+H41) -> 125.1 | AI30: =(J74+J63+J52+J41) -> 305 | AK30: =(L74+L63+L52+L41) -> 195
A31: =A42 -> ARIMAX | B31: 70 | C31: 0.12389381 | D31: 80 | E31: 0.11940299 | F31: 70 | G31: 0.10852713 | H31: 0.1 | I31: 0.0012406948 | J31: 65 | K31: 0.10831528 | L31: 90 | M31: 0.144 | O31: =AA31/$AM$172 -> 63.75 | Q31: =AC31/$AM$172 -> 67.5 | S31: =AE31/$AM$172 -> 78.75 | U31: =AG31/$AM$172 -> 21.775 | W31: =AI31/$AM$172 -> 75 | Y31: =AK31/$AM$172 -> 60 | AA31: =(B75+B64+B53+B42) -> 255 | AC31: =(D75+D64+D53+D42) -> 270 | AE31: =(F75+F64+F53+F42) -> 315 | AG31: =(H75+H64+H53+H42) -> 87.1 | AI31: =(J75+J64+J53+J42) -> 300 | AK31: =(L75+L64+L53+L42) -> 240
A32: =A43 -> PCE | B32: 80 | C32: 0.14159292 | D32: 65 | E32: 0.097014925 | F32: 65 | G32: 0.10077519 | H32: 60 | I32: 0.74441687 | J32: 60 | K32: 0.099983336 | L32: 70 | M32: 0.112 | O32: =AA32/$AM$172 -> 37.5 | Q32: =AC32/$AM$172 -> 31.25 | S32: =AE32/$AM$172 -> 38.75 | U32: =AG32/$AM$172 -> 30 | W32: =AI32/$AM$172 -> 35 | Y32: =AK32/$AM$172 -> 32.5 | AA32: =(B76+B65+B54+B43) -> 150 | AC32: =(D76+D65+D54+D43) -> 125 | AE32: =(F76+F65+F54+F43) -> 155 | AG32: =(H76+H65+H54+H43) -> 120 | AI32: =(J76+J65+J54+J43) -> 140 | AK32: =(L76+L65+L54+L43) -> 130
A33: =A44 -> LSTM | B33: 70 | C33: 0.12389381 | D33: 95 | E33: 0.14179104 | F33: 75 | G33: 0.11627907 | H33: 10 | I33: 0.12406948 | J33: 95 | K33: 0.15830695 | L33: 30 | M33: 0.048 | O33: =AA33/$AM$172 -> 63.75 | Q33: =AC33/$AM$172 -> 81.25 | S33: =AE33/$AM$172 -> 73.75 | U33: =AG33/$AM$172 -> 21.775 | W33: =AI33/$AM$172 -> 68.75 | Y33: =AK33/$AM$172 -> 40 | AA33: =(B77+B66+B55+B44) -> 255 | AC33: =(D77+D66+D55+D44) -> 325 | AE33: =(F77+F66+F55+F44) -> 295 | AG33: =(H77+H66+H55+H44) -> 87.1 | AI33: =(J77+J66+J55+J44) -> 275 | AK33: =(L77+L66+L55+L44) -> 160
A34: =A45 -> GARCH | B34: 65 | C34: 0.11504425 | D34: 75 | E34: 0.1119403 | F34: 75 | G34: 0.11627907 | H34: 10 | I34: 0.12406948 | J34: 95 | K34: 0.15830695 | L34: 30 | M34: 0.048 | O34: =AA34/$AM$172 -> 71.25 | Q34: =AC34/$AM$172 -> 68.75 | S34: =AE34/$AM$172 -> 76.25 | U34: =AG34/$AM$172 -> 28.75 | W34: =AI34/$AM$172 -> 72.5 | Y34: =AK34/$AM$172 -> 43.75 | AA34: =(B78+B67+B56+B45) -> 285 | AC34: =(D78+D67+D56+D45) -> 275 | AE34: =(F78+F67+F56+F45) -> 305 | AG34: =(H78+H67+H56+H45) -> 115 | AI34: =(J78+J67+J56+J45) -> 290 | AK34: =(L78+L67+L56+L45) -> 175
A35: =A46 -> VAR | B35: 0 | C35: 0 | D35: 75 | E35: 0.1119403 | F35: 65 | G35: 0.10077519 | H35: 0.1 | I35: 0.0012406948 | J35: 65 | K35: 0.10831528 | L35: 70 | M35: 0.112 | O35: =AA35/$AM$172 -> 15 | Q35: =AC35/$AM$172 -> 72.5 | S35: =AE35/$AM$172 -> 80 | U35: =AG35/$AM$172 -> 20.525 | W35: =AI35/$AM$172 -> 68.75 | Y35: =AK35/$AM$172 -> 55 | AA35: =(B79+B68+B57+B46) -> 60 | AC35: =(D79+D68+D57+D46) -> 290 | AE35: =(F79+F68+F57+F46) -> 320 | AG35: =(H79+H68+H57+H46) -> 82.1 | AI35: =(J79+J68+J57+J46) -> 275 | AK35: =(L79+L68+L57+L46) -> 220
A36: =A47 -> RW | B36: 70 | C36: 0.12389381 | D36: 75 | E36: 0.1119403 | F36: 70 | G36: 0.10852713 | H36: 0.1 | I36: 0.0012406948 | J36: 65 | K36: 0.10831528 | L36: 95 | M36: 0.152 | O36: =AA36/$AM$172 -> 58.75 | Q36: =AC36/$AM$172 -> 71.25 | S36: =AE36/$AM$172 -> 81.25 | U36: =AG36/$AM$172 -> 25.525 | W36: =AI36/$AM$172 -> 67.5 | Y36: =AK36/$AM$172 -> 70 | AA36: =(B80+B69+B58+B47) -> 235 | AC36: =(D80+D69+D58+D47) -> 285 | AE36: =(F80+F69+F58+F47) -> 325 | AG36: =(H80+H69+H58+H47) -> 102.1 | AI36: =(J80+J69+J58+J47) -> 270 | AK36: =(L80+L69+L58+L47) -> 280
A37: =A48 -> ETS | B37: 70 | C37: 0.12389381 | D37: 80 | E37: 0.11940299 | F37: 70 | G37: 0.10852713 | H37: 0.1 | I37: 0.0012406948 | J37: 0.1 | K37: 0.00016663889 | L37: 95 | M37: 0.152 | O37: =AA37/$AM$172 -> 73.75 | Q37: =AC37/$AM$172 -> 72.5 | S37: =AE37/$AM$172 -> 81.25 | U37: =AG37/$AM$172 -> 18.025 | W37: =AI37/$AM$172 -> 55.025 | Y37: =AK37/$AM$172 -> 70 | AA37: =(B81+B70+B59+B48) -> 295 | AC37: =(D81+D70+D59+D48) -> 290 | AE37: =(F81+F70+F59+F48) -> 325 | AG37: =(H81+H70+H59+H48) -> 72.1 | AI37: =(J81+J70+J59+J48) -> 220.1 | AK37: =(L81+L70+L59+L48) -> 280
A38: =A49 -> DynaMix | B38: 50 | C38: 0.088495575 | D38: 65 | E38: 0.097014925 | F38: 80 | G38: 0.12403101 | H38: 0.1 | I38: 0.0012406948 | J38: 65 | K38: 0.10831528 | L38: 70 | M38: 0.112 | O38: =AA38/$AM$172 -> 67.5 | Q38: =AC38/$AM$172 -> 67.5 | S38: =AE38/$AM$172 -> 82.5 | U38: =AG38/$AM$172 -> 13.525 | W38: =AI38/$AM$172 -> 71.25 | Y38: =AK38/$AM$172 -> 53.75 | AA38: =(B82+B71+B60+B49) -> 270 | AC38: =(D82+D71+D60+D49) -> 270 | AE38: =(F82+F71+F60+F49) -> 330 | AG38: =(H82+H71+H60+H49) -> 54.1 | AI38: =(J82+J71+J60+J49) -> 285 | AK38: =(L82+L71+L60+L49) -> 215
A40: 1-07 | B40: TNX | C40: 565 | D40: DJI | E40: 670 | F40: SPX | G40: 645 | H40: VIX | I40: 80.6 | J40: QQQ | K40: 600.1 | L40: AAPL | M40: 625 | O40: TNX | Q40: DJI | S40: SPX | U40: VIX | W40: QQQ | Y40: AAPL | AA40: TNX | AC40: DJI | AE40: SPX | AG40: VIX | AI40: QQQ | AK40: AAPL | AM40: =AM51 -> 4
A41: =A52 -> PyCaret | B41: 90 | C41: 0.15929204 | D41: 60 | E41: 0.089552239 | F41: 75 | G41: 0.11627907 | H41: 0.1 | I41: 0.0012406948 | J41: 90 | K41: 0.149975 | L41: 75 | M41: 0.12 | O41: =AA41/$AM$172 -> 60 | Q41: =AC41/$AM$172 -> 62.5 | S41: =AE41/$AM$172 -> 61.25 | U41: =AG41/$AM$172 -> 50 | W41: =AI41/$AM$172 -> 72.5 | Y41: =AK41/$AM$172 -> 53.75 | AA41: =(B85+B74+B63+B52) -> 240 | AC41: =(D85+D74+D63+D52) -> 250 | AE41: =(F85+F74+F63+F52) -> 245 | AG41: =(H85+H74+H63+H52) -> 200 | AI41: =(J85+J74+J63+J52) -> 290 | AK41: =(L85+L74+L63+L52) -> 215
A42: =A53 -> ARIMAX | B42: 70 | C42: 0.12389381 | D42: 80 | E42: 0.11940299 | F42: 70 | G42: 0.10852713 | H42: 0.1 | I42: 0.0012406948 | J42: 65 | K42: 0.10831528 | L42: 90 | M42: 0.144 | O42: =AA42/$AM$172 -> 65 | Q42: =AC42/$AM$172 -> 65 | S42: =AE42/$AM$172 -> 77.5 | U42: =AG42/$AM$172 -> 29.25 | W42: =AI42/$AM$172 -> 75 | Y42: =AK42/$AM$172 -> 55 | AA42: =(B86+B75+B64+B53) -> 260 | AC42: =(D86+D75+D64+D53) -> 260 | AE42: =(F86+F75+F64+F53) -> 310 | AG42: =(H86+H75+H64+H53) -> 117 | AI42: =(J86+J75+J64+J53) -> 300 | AK42: =(L86+L75+L64+L53) -> 220
A43: =A54 -> PCE | B43: 80 | C43: 0.14159292 | D43: 65 | E43: 0.097014925 | F43: 65 | G43: 0.10077519 | H43: 60 | I43: 0.74441687 | J43: 60 | K43: 0.099983336 | L43: 70 | M43: 0.112 | O43: =AA43/$AM$172 -> 36.25 | Q43: =AC43/$AM$172 -> 40 | S43: =AE43/$AM$172 -> 46.25 | U43: =AG43/$AM$172 -> 31.25 | W43: =AI43/$AM$172 -> 38.75 | Y43: =AK43/$AM$172 -> 38.75 | AA43: =(B87+B76+B65+B54) -> 145 | AC43: =(D87+D76+D65+D54) -> 160 | AE43: =(F87+F76+F65+F54) -> 185 | AG43: =(H87+H76+H65+H54) -> 125 | AI43: =(J87+J76+J65+J54) -> 155 | AK43: =(L87+L76+L65+L54) -> 155
A44: =A55 -> LSTM | B44: 70 | C44: 0.12389381 | D44: 95 | E44: 0.14179104 | F44: 75 | G44: 0.11627907 | H44: 10 | I44: 0.12406948 | J44: 95 | K44: 0.15830695 | L44: 30 | M44: 0.048 | O44: =AA44/$AM$172 -> 66.25 | Q44: =AC44/$AM$172 -> 73.75 | S44: =AE44/$AM$172 -> 77.5 | U44: =AG44/$AM$172 -> 26.775 | W44: =AI44/$AM$172 -> 60 | Y44: =AK44/$AM$172 -> 47.5 | AA44: =(B88+B77+B66+B55) -> 265 | AC44: =(D88+D77+D66+D55) -> 295 | AE44: =(F88+F77+F66+F55) -> 310 | AG44: =(H88+H77+H66+H55) -> 107.1 | AI44: =(J88+J77+J66+J55) -> 240 | AK44: =(L88+L77+L66+L55) -> 190
A45: =A56 -> GARCH | B45: 65 | C45: 0.11504425 | D45: 75 | E45: 0.1119403 | F45: 75 | G45: 0.11627907 | H45: 10 | I45: 0.12406948 | J45: 95 | K45: 0.15830695 | L45: 30 | M45: 0.048 | O45: =AA45/$AM$172 -> 77.5 | Q45: =AC45/$AM$172 -> 70 | S45: =AE45/$AM$172 -> 77.5 | U45: =AG45/$AM$172 -> 33.75 | W45: =AI45/$AM$172 -> 65 | Y45: =AK45/$AM$172 -> 60 | AA45: =(B89+B78+B67+B56) -> 310 | AC45: =(D89+D78+D67+D56) -> 280 | AE45: =(F89+F78+F67+F56) -> 310 | AG45: =(H89+H78+H67+H56) -> 135 | AI45: =(J89+J78+J67+J56) -> 260 | AK45: =(L89+L78+L67+L56) -> 240
A46: =A57 -> VAR | B46: 0 | C46: 0 | D46: 75 | E46: 0.1119403 | F46: 65 | G46: 0.10077519 | H46: 0.1 | I46: 0.0012406948 | J46: 65 | K46: 0.10831528 | L46: 70 | M46: 0.112 | O46: =AA46/$AM$172 -> 15 | Q46: =AC46/$AM$172 -> 73.75 | S46: =AE46/$AM$172 -> 83.75 | U46: =AG46/$AM$172 -> 30.5 | W46: =AI46/$AM$172 -> 68.75 | Y46: =AK46/$AM$172 -> 57.5 | AA46: =(B90+B79+B68+B57) -> 60 | AC46: =(D90+D79+D68+D57) -> 295 | AE46: =(F90+F79+F68+F57) -> 335 | AG46: =(H90+H79+H68+H57) -> 122 | AI46: =(J90+J79+J68+J57) -> 275 | AK46: =(L90+L79+L68+L57) -> 230
A47: =A58 -> RW | B47: 70 | C47: 0.12389381 | D47: 75 | E47: 0.1119403 | F47: 70 | G47: 0.10852713 | H47: 0.1 | I47: 0.0012406948 | J47: 65 | K47: 0.10831528 | L47: 95 | M47: 0.152 | O47: =AA47/$AM$172 -> 63.75 | Q47: =AC47/$AM$172 -> 72.5 | S47: =AE47/$AM$172 -> 82.5 | U47: =AG47/$AM$172 -> 33 | W47: =AI47/$AM$172 -> 67.5 | Y47: =AK47/$AM$172 -> 62.5 | AA47: =(B91+B80+B69+B58) -> 255 | AC47: =(D91+D80+D69+D58) -> 290 | AE47: =(F91+F80+F69+F58) -> 330 | AG47: =(H91+H80+H69+H58) -> 132 | AI47: =(J91+J80+J69+J58) -> 270 | AK47: =(L91+L80+L69+L58) -> 250
A48: =A59 -> ETS | B48: 70 | C48: 0.12389381 | D48: 80 | E48: 0.11940299 | F48: 70 | G48: 0.10852713 | H48: 0.1 | I48: 0.0012406948 | J48: 0.1 | K48: 0.00016663889 | L48: 95 | M48: 0.152 | O48: =AA48/$AM$172 -> 78.75 | Q48: =AC48/$AM$172 -> 72.5 | S48: =AE48/$AM$172 -> 82.5 | U48: =AG48/$AM$172 -> 23 | W48: =AI48/$AM$172 -> 71.25 | Y48: =AK48/$AM$172 -> 62.5 | AA48: =(B92+B81+B70+B59) -> 315 | AC48: =(D92+D81+D70+D59) -> 290 | AE48: =(F92+F81+F70+F59) -> 330 | AG48: =(H92+H81+H70+H59) -> 92 | AI48: =(J92+J81+J70+J59) -> 285 | AK48: =(L92+L81+L70+L59) -> 250
A49: =A60 -> DynaMix | B49: 50 | C49: 0.088495575 | D49: 65 | E49: 0.097014925 | F49: 80 | G49: 0.12403101 | H49: 0.1 | I49: 0.0012406948 | J49: 65 | K49: 0.10831528 | L49: 70 | M49: 0.112 | O49: =AA49/$AM$172 -> 75 | Q49: =AC49/$AM$172 -> 73.75 | S49: =AE49/$AM$172 -> 80 | U49: =AG49/$AM$172 -> 21 | W49: =AI49/$AM$172 -> 67.5 | Y49: =AK49/$AM$172 -> 52.5 | AA49: =(B93+B82+B71+B60) -> 300 | AC49: =(D93+D82+D71+D60) -> 295 | AE49: =(F93+F82+F71+F60) -> 320 | AG49: =(H93+H82+H71+H60) -> 84 | AI49: =(J93+J82+J71+J60) -> 270 | AK49: =(L93+L82+L71+L60) -> 210
A51: 1-06 | B51: TNX | C51: 615 | D51: DJI | E51: 705 | F51: SPX | G51: 675 | H51: VIX | I51: 55.1 | J51: QQQ | K51: 665 | L51: AAPL | M51: 560 | O51: TNX | Q51: DJI | S51: SPX | U51: VIX | W51: QQQ | Y51: AAPL | AA51: TNX | AC51: DJI | AE51: SPX | AG51: VIX | AI51: QQQ | AK51: AAPL | AM51: =AM62 -> 4
A52: =A63 -> PyCaret | B52: 90 | C52: 0.14634146 | D52: 75 | E52: 0.10638298 | F52: 50 | G52: 0.074074074 | H52: 40 | I52: 0.72595281 | J52: 90 | K52: 0.13533835 | L52: 60 | M52: 0.10714286 | O52: =AA52/$AM$172 -> 60 | Q52: =AC52/$AM$172 -> 58.75 | S52: =AE52/$AM$172 -> 67.5 | U52: =AG52/$AM$172 -> 40.025 | W52: =AI52/$AM$172 -> 72.5 | Y52: =AK52/$AM$172 -> 57.5 | AA52: =(B96+B85+B74+B63) -> 240 | AC52: =(D96+D85+D74+D63) -> 235 | AE52: =(F96+F85+F74+F63) -> 270 | AG52: =(H96+H85+H74+H63) -> 160.1 | AI52: =(J96+J85+J74+J63) -> 290 | AK52: =(L96+L85+L74+L63) -> 230
A53: =A64 -> ARIMAX | B53: 65 | C53: 0.10569106 | D53: 90 | E53: 0.12765957 | F53: 95 | G53: 0.14074074 | H53: 2 | I53: 0.036297641 | J53: 95 | K53: 0.14285714 | L53: 70 | M53: 0.125 | O53: =AA53/$AM$172 -> 66.25 | Q53: =AC53/$AM$172 -> 62.5 | S53: =AE53/$AM$172 -> 71.25 | U53: =AG53/$AM$172 -> 28.775 | W53: =AI53/$AM$172 -> 67.5 | Y53: =AK53/$AM$172 -> 60 | AA53: =(B97+B86+B75+B64) -> 265 | AC53: =(D97+D86+D75+D64) -> 250 | AE53: =(F97+F86+F75+F64) -> 285 | AG53: =(H97+H86+H75+H64) -> 115.1 | AI53: =(J97+J86+J75+J64) -> 270 | AK53: =(L97+L86+L75+L64) -> 240
A54: =A65 -> PCE | B54: 0 | C54: 0 | D54: 0 | E54: 0 | F54: 0 | G54: 0 | H54: 0 | I54: 0 | J54: 0 | K54: 0 | L54: 0 | M54: 0 | O54: =AA54/$AM$172 -> 56.25 | Q54: =AC54/$AM$172 -> 56.25 | S54: =AE54/$AM$172 -> 62.5 | U54: =AG54/$AM$172 -> 46.25 | W54: =AI54/$AM$172 -> 53.75 | Y54: =AK54/$AM$172 -> 56.25 | AA54: =(B98+B87+B76+B65) -> 225 | AC54: =(D98+D87+D76+D65) -> 225 | AE54: =(F98+F87+F76+F65) -> 250 | AG54: =(H98+H87+H76+H65) -> 185 | AI54: =(J98+J87+J76+J65) -> 215 | AK54: =(L98+L87+L76+L65) -> 225
A55: =A66 -> LSTM | B55: 80 | C55: 0.1300813 | D55: 90 | E55: 0.12765957 | F55: 65 | G55: 0.096296296 | H55: 0.1 | I55: 0.001814882 | J55: 60 | K55: 0.090225564 | L55: 50 | M55: 0.089285714 | O55: =AA55/$AM$172 -> 63.75 | Q55: =AC55/$AM$172 -> 75 | S55: =AE55/$AM$172 -> 80 | U55: =AG55/$AM$172 -> 29.25 | W55: =AI55/$AM$172 -> 68.75 | Y55: =AK55/$AM$172 -> 42.5 | AA55: =(B99+B88+B77+B66) -> 255 | AC55: =(D99+D88+D77+D66) -> 300 | AE55: =(F99+F88+F77+F66) -> 320 | AG55: =(H99+H88+H77+H66) -> 117 | AI55: =(J99+J88+J77+J66) -> 275 | AK55: =(L99+L88+L77+L66) -> 170
