Workbook

Sheet 26-1-08
A1: model | B1: O 5.2 | C1: Grok 4.1 | D1: Gemini Pro 3 | E1: Claude | F1: GLM-4.7 | G1: Kimi 2.5 | H1: Minimax 2.1 | I1: LeChat | J1: Qwen | L1: 26-Q1-08 | N1: Accuracy | O1: TNX | P1: =SUM(O2:O10) -> 889.86536 | Q1: DJI | R1: =SUM(Q2:Q10) -> 893.18423 | S1: SPX | T1: =SUM(S2:S10) -> 897.60837 | U1: VIX | V1: =SUM(U2:U10) -> 882.50393 | W1: QQQ | X1: =SUM(W2:W10) -> 897.56574 | Y1: AAPL | Z1: =SUM(Y2:Y9) -> 770.6705 | AB1: AVR-4 | AC1: AVR-6 | AH1: max-Q | AL1: REPORT | AO1: Round | AP1: 2 | AQ1: =K10 -> +3-day | AR1: User1 | AS1: User2 | AT1: User3
A2: TNX | B2: 4.03 | C2: 4.05 | D2: 4.05 | E2: 4.055 | F2: 4.033 | G2: 4.043 | H2: 4.01 | I2: 4.05 | J2: 4.03 | N2: =B1 -> O 5.2 | O2: =100-ABS((($K11-B2)/($K11)))*100 -> 98.653611 | P2: =O2/$P$1 -> 0.11086353 | Q2: =100-ABS((($K12-B3)/($K12)))*100 -> 99.419719 | R2: =Q2/$R$1 -> 0.11130931 | S2: =100-ABS((($K13-B4)/($K13)))*100 -> 99.775961 | T2: =S2/$T$1 -> 0.11115757 | U2: =100-ABS((($K14-B5)/($K14)))*100 -> 97.537978 | V2: =U2/$V$1 -> 0.11052413 | W2: =100-ABS((($K15-B6)/($K15)))*100 -> 99.868596 | X2: =W2/$X$1 -> 0.11126605 | Y2: =100-ABS((($K16-B7)/($K16)))*100 -> 96.541689 | Z2: =Y2/$Z$1 -> 0.12526973 | AB2: =(Q2+S2+U2+W2)/4 -> 99.150564 | AC2: =(O2+Q2+S2+U2+W2+Y2)/6 -> 98.632926 | AD2: =IF($AB2=MAX(AB2:AB10),"TOP","") | AE2: =IF($AC2=MAX(AC2:AC10),"TOP","") | AG2: TNX | AH2: GLM, L | AI2: =MAX(O2:P10) -> 99.265606 | AK2: =AG2 -> TNX | AL2: 4.25 | AM2: =100-ABS(($K11-AL2)/($K11))*100 -> 95.960832 | AP2: Ticker | AQ2: Exact | AR2: ∆ | AS2: =AR2 -> ∆ | AT2: =AS2 -> ∆ | AU2: Penalty function
A3: DJI | B3: 49338 | C3: 49320 | D3: 49290 | E3: 49300 | F3: 48705.34 | G3: 49408 | H3: 49320 | I3: 49250 | J3: 49320 | L3: 2026/03/03 | N3: =C1 -> Grok 4.1 | O3: =100-ABS((($K11-C2)/($K11)))*100 -> 99.143207 | P3: =O3/$P$1 -> 0.11141372 | Q3: =100-ABS((($K12-C3)/($K12)))*100 -> 99.383448 | R3: =Q3/$R$1 -> 0.1112687 | S3: =100-ABS((($K13-C4)/($K13)))*100 -> 99.877271 | T3: =S3/$T$1 -> 0.11127043 | U3: =100-ABS((($K14-C5)/($K14)))*100 -> 99.947617 | V3: =U3/$V$1 -> 0.11325459 | W3: =100-ABS((($K15-C6)/($K15)))*100 -> 99.804537 | X3: =W3/$X$1 -> 0.11119468 | Y3: =100-ABS((($K16-C7)/($K16)))*100 -> 96.250661 | Z3: =Y3/$Z$1 -> 0.12489211 | AB3: =(Q3+S3+U3+W3)/4 -> 99.753218 | AC3: =(O3+Q3+S3+U3+W3+Y3)/6 -> 99.06779 | AD3: =IF($AB3=MAX(AB2:AB10),"TOP","") -> TOP | AE3: =IF($AC3=MAX(AC2:AC10),"TOP","") | AG3: DJI | AH3: GLM | AI3: =MAX(Q2:R10) -> 99.560774 | AK3: =AG3 -> DJI | AL3: 48833 | AM3: =100-ABS(($K12-AL3)/($K12))*100 -> 98.402107 | AP3: =AG2 -> TNX | AQ3: =K11 -> 4.085 | AR3: =ABS(C29-AQ3) -> 0.075 | AS3: =ABS(E29-K11) -> 0.035 | AT3: =ABS(AQ3-G29) -> 0.005 | AU3: N/A
A4: SPX | B4: 6925 | C4: 6918 | D4: 6915 | E4: 6920 | F4: 6891.15 | G4: 6925 | H4: 6922 | I4: 6835 | J4: 6914 | N4: =D1 -> Gemini Pro 3 | O4: =100-ABS((($K11-D2)/($K11)))*100 -> 99.143207 | P4: =O4/$P$1 -> 0.11141372 | Q4: =100-ABS((($K12-D3)/($K12)))*100 -> 99.322996 | R4: =Q4/$R$1 -> 0.11120102 | S4: =100-ABS((($K13-D4)/($K13)))*100 -> 99.920689 | T4: =S4/$T$1 -> 0.1113188 | U4: =100-ABS((($K14-D5)/($K14)))*100 -> 99.947617 | V4: =U4/$V$1 -> 0.11325459 | W4: =100-ABS((($K15-D6)/($K15)))*100 -> 99.763473 | X4: =W4/$X$1 -> 0.11114893 | Y4: =100-ABS((($K16-D7)/($K16)))*100 -> 96.401844 | Z4: =Y4/$Z$1 -> 0.12508828 | AB4: =(Q4+S4+U4+W4)/4 -> 99.738694 | AC4: =(O4+Q4+S4+U4+W4+Y4)/6 -> 99.083304 | AD4: =IF($AB4=MAX(AB2:AB10),"TOP","") | AE4: =IF($AC4=MAX(AC2:AC10),"TOP","") -> TOP | AG4: SPX | AH4: C | AI4: =MAX(S2:T10) -> 99.935162 | AK4: =AG4 -> SPX | AL4: 6810 | AM4: =100-ABS(($K13-AL4)/($K13))*100 -> 98.559668 | AP4: =AG3 -> DJI | AQ4: =K12 -> 49625.97 | AR4: =ABS(C12-AQ4) -> 10.97 | AS4: =ABS(E12-AQ4) -> 42.97 | AT4: =ABS(AQ4-G12) -> 3.97 | AU4: F1
A5: VIX | B5: 19.56 | C5: 19.1 | D5: 19.1 | E5: 19.2 | F5: 20.25 | G5: 19.76 | H5: 19.2 | I5: 19 | J5: 18.38 | L5: LLM | N5: =E1 -> Claude | O5: =100-ABS((($K11-E2)/($K11)))*100 -> 99.265606 | P5: =O5/$P$1 -> 0.11155126 | Q5: =100-ABS((($K12-E3)/($K12)))*100 -> 99.343146 | R5: =Q5/$R$1 -> 0.11122358 | S5: =100-ABS((($K13-E4)/($K13)))*100 -> 99.848325 | T5: =S5/$T$1 -> 0.11123818 | U5: =100-ABS((($K14-E5)/($K14)))*100 -> 99.423782 | V5: =U5/$V$1 -> 0.11266101 | W5: =100-ABS((($K15-E6)/($K15)))*100 -> 99.640282 | X5: =W5/$X$1 -> 0.11101168 | Y5: =100-ABS((($K16-E7)/($K16)))*100 -> 96.061683 | Z5: =Y5/$Z$1 -> 0.12464689 | AB5: =(Q5+S5+U5+W5)/4 -> 99.563884 | AC5: =(O5+Q5+S5+U5+W5+Y5)/6 -> 98.930471 | AD5: =IF($AB5=MAX(AB2:AB10),"TOP","") | AE5: =IF($AC5=MAX(AC2:AC10),"TOP","") | AG5: VIX | AH5: M | AI5: =MAX(U2:V10) -> 99.947617 | AK5: =AG5 -> VIX | AL5: 19.1 | AM5: =100-ABS(($K14-AL5)/($K14))*100 -> 99.947617 | AP5: =AG4 -> SPX | AQ5: =K13 -> 6909.52 | AR5: =ABS(C13-AQ5) -> 2.52 | AS5: =ABS(E13-AQ5) -> 3.48 | AT5: =ABS(AQ5-G13) -> 59.52 | AU5: F2
A6: QQQ | B6: 609.61 | C6: 610 | D6: 610.25 | E6: 611 | F6: 606.37 | G6: 611 | H6: 612 | I6: 610 | J6: 609 | N6: =F1 -> GLM-4.7 | O6: =100-ABS((($K11-F2)/($K11)))*100 -> 98.72705 | P6: =O6/$P$1 -> 0.11094605 | Q6: =100-ABS((($K12-F3)/($K12)))*100 -> 98.144862 | R6: =Q6/$R$1 -> 0.10988199 | S6: =100-ABS((($K13-F4)/($K13)))*100 -> 99.734135 | T6: =S6/$T$1 -> 0.11111097 | U6: =100-ABS((($K14-F5)/($K14)))*100 -> 93.92352 | V6: =U6/$V$1 -> 0.10642844 | W6: =100-ABS((($K15-F6)/($K15)))*100 -> 99.599218 | X6: =W6/$X$1 -> 0.11096593 | Y6: =100-ABS((($K16-F7)/($K16)))*100 -> 96.851614 | Z6: =Y6/$Z$1 -> 0.12567188 | AB6: =(Q6+S6+U6+W6)/4 -> 97.850434 | AC6: =(O6+Q6+S6+U6+W6+Y6)/6 -> 97.830067 | AD6: =IF($AB6=MAX(AB2:AB10),"TOP","") | AE6: =IF($AC6=MAX(AC2:AC10),"TOP","") | AG6: QQQ | AH6: o | AI6: =MAX(W2:X10) -> 99.968792 | AK6: =AG6 -> QQQ | AL6: 604.8 | AM6: =100-ABS(($K15-AL6)/($K15))*100 -> 99.341338 | AP6: =AG5 -> VIX | AQ6: =K14 -> 19.09 | AR6: =ABS(C14-AQ6) -> 0.79 | AS6: =ABS(E14-AQ6) -> 0.44 | AT6: =ABS(AQ6-G14) -> 0.1 | AU6: F3
A7: AAPL | B7: 273.73 | C7: 274.5 | D7: 274.1 | E7: 275 | F7: 272.91 | G7: 275 | H7: 274 | I7: 275 | J7: 275 | L7: F & G | N7: =G1 -> Kimi 2.5 | O7: =100-ABS((($K11-G2)/($K11)))*100 -> 98.971848 | P7: =O7/$P$1 -> 0.11122115 | Q7: =100-ABS((($K12-G3)/($K12)))*100 -> 99.560774 | R7: =Q7/$R$1 -> 0.11146723 | S7: =100-ABS((($K13-G4)/($K13)))*100 -> 99.775961 | T7: =S7/$T$1 -> 0.11115757 | U7: =100-ABS((($K14-G5)/($K14)))*100 -> 96.490309 | V7: =U7/$V$1 -> 0.10933697 | W7: =100-ABS((($K15-G6)/($K15)))*100 -> 99.640282 | X7: =W7/$X$1 -> 0.11101168 | Y7: =100-ABS((($K16-G7)/($K16)))*100 -> 96.061683 | Z7: =Y7/$Z$1 -> 0.12464689 | AB7: =(Q7+S7+U7+W7)/4 -> 98.866832 | AC7: =(O7+Q7+S7+U7+W7+Y7)/6 -> 98.41681 | AD7: =IF($AB7=MAX(AB2:AB10),"TOP","") | AE7: =IF($AC7=MAX(AC2:AC10),"TOP","") | AG7: AAPL | AH7: Q | AI7: =MAX(Y2:Z10) -> 96.851614 | AK7: =AG7 -> AAPL | AL7: 245.25 | AM7: =100-ABS(($K16-AL7)/($K16))*100 -> 92.694081 | AP7: =AG6 -> QQQ | AQ7: =K15 -> 608.81 | AR7: =ABS(C15-AQ7) -> 4.49 | AS7: =ABS(E15-AQ7) -> 6.59 | AT7: =ABS(AQ7-G15) -> 5.31 | AU7: F4
L8: 43 | N8: =H1 -> Minimax 2.1 | O8: =100-ABS((($K11-H2)/($K11)))*100 -> 98.164015 | P8: =O8/$P$1 -> 0.11031333 | Q8: =100-ABS((($K12-H3)/($K12)))*100 -> 99.383448 | R8: =Q8/$R$1 -> 0.1112687 | S8: =100-ABS((($K13-H4)/($K13)))*100 -> 99.81938 | T8: =S8/$T$1 -> 0.11120594 | U8: =100-ABS((($K14-H5)/($K14)))*100 -> 99.423782 | V8: =U8/$V$1 -> 0.11266101 | W8: =100-ABS((($K15-H6)/($K15)))*100 -> 99.476027 | X8: =W8/$X$1 -> 0.11082868 | Y8: =100-ABS((($K16-H7)/($K16)))*100 -> 96.43964 | Z8: =Y8/$Z$1 -> 0.12513732 | AB8: =(Q8+S8+U8+W8)/4 -> 99.525659 | AC8: =(O8+Q8+S8+U8+W8+Y8)/6 -> 98.784382 | AD8: =IF($AB8=MAX(AB2:AB10),"TOP","") | AE8: =IF($AC8=MAX(AC2:AC10),"TOP","") | AP8: =AG7 -> AAPL | AQ8: =K16 -> 264.58 | AR8: =ABS(C34-AQ8) -> 8.62 | AS8: =ABS(E34-K16) -> 9.72 | AT8: =ABS(AQ8-G34) -> 0.28 | AU8: N/A
L9: =IF(L8<25,AC31,IF(L8<45,AC32,IF(L8<55,AC33,IF(L8<75,AC34,AC35)))) -> Fear | N9: =I1 -> LeChat | O9: =100-ABS((($K11-I2)/($K11)))*100 -> 99.143207 | P9: =O9/$P$1 -> 0.11141372 | Q9: =100-ABS((($K12-I3)/($K12)))*100 -> 99.242393 | R9: =Q9/$R$1 -> 0.11111078 | S9: =100-ABS((($K13-I4)/($K13)))*100 -> 98.921488 | T9: =S9/$T$1 -> 0.11020562 | U9: =100-ABS((($K14-I5)/($K14)))*100 -> 99.528549 | V9: =U9/$V$1 -> 0.11277972 | W9: =100-ABS((($K15-I6)/($K15)))*100 -> 99.804537 | X9: =W9/$X$1 -> 0.11119468 | Y9: =100-ABS((($K16-I7)/($K16)))*100 -> 96.061683 | Z9: =Y9/$Z$1 -> 0.12464689 | AB9: =(Q10+S10+U10+W10)/4 -> 98.892044 | AC9: =(O10+Q10+S10+U10+W10+Y10)/6 -> 98.380578 | AD9: =IF($AB10=MAX(AB2:AB10),"TOP","") | AE9: =IF($AC9=MAX(AC2:AC10),"TOP","") | AG9: max-Q AVR-4 | AI9: =AVERAGE(AI3:AI6) -> 99.853086 | AK9: max-Q AVR-4 | AM9: =AVERAGE(AM3:AM6) -> 99.062682 | AQ9: 0 | AR9: 2.16 | AS9: 2.24 | AT9: 1.79 | AU9: Round Penalty
B10: Close YF | C10: RD | E10: 85520 | G10: MICH | I10: LLM | J10: ML | K10: +3-day | N10: =J1 -> Qwen | O10: =100-ABS((($K11-J2)/($K11)))*100 -> 98.653611 | P10: =O10/$P$1 -> 0.11086353 | Q10: =100-ABS((($K12-J3)/($K12)))*100 -> 99.383448 | R10: =Q10/$R$1 -> 0.1112687 | S10: =100-ABS((($K13-J4)/($K13)))*100 -> 99.935162 | T10: =S10/$T$1 -> 0.11133493 | U10: =100-ABS((($K14-J5)/($K14)))*100 -> 96.280775 | V10: =U10/$V$1 -> 0.10909954 | W10: =100-ABS((($K15-J6)/($K15)))*100 -> 99.968792 | X10: =W10/$X$1 -> 0.11137768 | Y10: =100-ABS((($K16-J7)/($K16)))*100 -> 96.061683 | Z10: =Y10/$Z$1 -> 0.12464689 | AB10: =(Q9+S9+U9+W9)/4 -> 99.374242 | AC10: =(O9+Q9+S9+U9+W9+Y9)/6 -> 98.783643 | AD10: =IF($AB11=MAX(AB2:AB10),"TOP","") | AE10: =IF($AC10=MAX(AC2:AC10),"TOP","") | AG10: max AVR-6 | AI10: =AVERAGE(AI2:AI7) -> 99.254927 | AK10: max AVR-6 | AM10: =AVERAGE(AM2:AM7) -> 97.484274 | AQ10: 0 | AR10: 5.28 | AS10: 5.33 | AT10: 5.1 | AU10: Total Penalty
A11: TNX | B11: 4.033 | C11: 4.01 | D11: =IF(ABS(K11-I11)<ABS(C11-K11),$I$10,$C$10) -> LLM | E11: 4.05 | F11: =IF(ABS(K11-I11)<ABS(K11-E11),$I$10,$E$10) -> 85520 | G11: 4.08 | H11: =IF(ABS(I11-K11)<ABS(K11-G11),$I$10,$G$10) -> MICH | I11: =(B2*P24)+(C2*P25)+(D2*P26)+(E2*P27)+(F2*P28)+(G2*P29)+(H2*P30)+(I2*P31)+(J2*P31) -> 4.0388972 | J11: 4.0421697 | K11: 4.085
A12: DJI | B12: 49174.5 | C12: 49615 | D12: =IF(ABS(K12-I12)<ABS(C12-K12),$I$10,$C$10) -> RD | E12: 49583 | F12: =IF(ABS(K12-I12)<ABS(K12-E12),$I$10,$E$10) -> 85520 | G12: 49622 | H12: =IF(ABS(I12-K12)<ABS(K12-G12),$I$10,$G$10) -> MICH | I12: =(B3*R24)+(C3*R25)+(D3*R26)+(E3*R27)+(F3*R28)+(G3*R29)+(H3*R30)+(I3*R31)+(J3*R31) -> 49251.484 | J12: 49221.088 | K12: 49625.97 | N12: Update | O12: TNX | P12: =SUM(O13:O21) -> 650 | Q12: DJI | R12: =SUM(Q13:Q21) -> 710 | S12: SPX | T12: =SUM(S13:S21) -> 825 | U12: VIX | V12: =SUM(U13:U21) -> 630 | W12: QQQ | X12: =SUM(W13:W21) -> 825 | Y12: AAPL | Z12: =SUM(Y13:Y21) -> 450 | AB12: Value | AC12: Assign | AG12: =B19 -> Close YF | AH12: =(I20-B20)/B20 -> 0.012893628 | AI12: =IF(K11-B20>0,"↑","↓") -> ↑ | AJ12: =(C20-B20)/B20 -> -0.0057029507 | AK12: =IF(C20-B20>0,"↑","↓") -> ↓ | AL12: =(E20-B20)/B20 -> 0.0042152244 | AM12: =IF(E20-B20>0,"↑","↓") -> ↑ | AN12: =(G20-B20)/B20 -> 0.011653856 | AO12: =IF(G20-B20>0,"↑","↓") -> ↑
A13: SPX | B13: 6890.07 | C13: 6907 | D13: =IF(ABS(K13-I13)<ABS(C13-K13),$I$10,$C$10) -> LLM | E13: 6913 | F13: =IF(ABS(K13-I13)<ABS(K13-E13),$I$10,$E$10) -> LLM | G13: 6850 | H13: =IF(ABS(I13-K13)<ABS(K13-G13),$I$10,$G$10) -> LLM | I13: =(B4*T24)+(C4*T25)+(D4*T26)+(E4*T27)+(F4*T28)+(G4*T29)+(H4*T30)+(I4*T31)+(J4*T31) -> 6907.2033 | J13: 6912.7657 | K13: 6909.52 | N13: =N2 -> O 5.2 | O13: =IF(O2=0,0, LOOKUP(O2-0.000000000001,$AB$13:$AB$29,$AC$13:$AC$29)) -> 70 | P13: =O13/$P$12 -> 0.10769231 | Q13: =IF(Q2=0,0, LOOKUP(Q2-0.000000000001,$AB$13:$AB$29,$AC$13:$AC$29)) -> 80 | R13: =Q13/$R$12 -> 0.11267606 | S13: =IF(S2=0,0, LOOKUP(S2-0.000000000001,$AB$13:$AB$29,$AC$13:$AC$29)) -> 95 | T13: =S13/$T$12 -> 0.11515152 | U13: =IF(U2=0,0, LOOKUP(U2-0.000000000001,$AB$13:$AB$29,$AC$13:$AC$29)) -> 60 | V13: =U13/$V$12 -> 0.095238095 | W13: =IF(W2=0,0, LOOKUP(W2-0.000000000001,$AB$13:$AB$29,$AC$13:$AC$29)) -> 95 | X13: =W13/$X$12 -> 0.11515152 | Y13: =IF(Y2=0,0, LOOKUP(Y2-0.000000000001,$AB$13:$AB$29,$AC$13:$AC$29)) -> 50 | Z13: =Y13/$Z$12 -> 0.11111111 | AB13: 1 | AC13: 0.1 | AH13: =(I21-B21)/B21 -> 0.0091809779 | AI13: =IF(I21-B21>0,"↑","↓") -> ↑ | AJ13: =(C21-B21)/B21 -> 0.0089578948 | AK13: =IF(C21-B21>0,"↑","↓") -> ↑ | AL13: =(E21-B21)/B21 -> 0.0083071511 | AM13: =IF(E21-B21>0,"↑","↓") -> ↑ | AN13: =(G21-B21)/B21 -> 0.009100245 | AO13: =IF(G21-B21>0,"↑","↓") -> ↑ | AP13: DJI | AQ13: =K10 -> +3-day | AR13: User1 | AS13: User2 | AT13: User3 | AU13: F1 | AV13: 893 | AW13: TEST | AX13: BEST = | AY13: 893
A14: VIX | B14: 19.55 | C14: 18.3 | D14: =IF(ABS(K14-I14)<ABS(C14-K14),$I$10,$C$10) -> LLM | E14: 18.65 | F14: =IF(ABS(K14-I14)<ABS(K14-E14),$I$10,$E$10) -> LLM | G14: 19.19 | H14: =IF(ABS(I14-K14)<ABS(K14-G14),$I$10,$G$10) -> MICH | I14: =(B5*V24)+(C5*V25)+(D5*V26)+(E5*V27)+(F5*V28)+(G5*V29)+(H5*V30)+(I5*V31)+(J5*V31) -> 19.318179 | J14: 18.934458 | K14: 19.09 | N14: =N3 -> Grok 4.1 | O14: =IF(O3=0,0, LOOKUP(O3-0.000000000001,$AB$13:$AB$29,$AC$13:$AC$29)) -> 75 | P14: =O14/$P$12 -> 0.11538462 | Q14: =IF(Q3=0,0, LOOKUP(Q3-0.000000000001,$AB$13:$AB$29,$AC$13:$AC$29)) -> 80 | R14: =Q14/$R$12 -> 0.11267606 | S14: =IF(S3=0,0, LOOKUP(S3-0.000000000001,$AB$13:$AB$29,$AC$13:$AC$29)) -> 95 | T14: =S14/$T$12 -> 0.11515152 | U14: =IF(U3=0,0, LOOKUP(U3-0.000000000001,$AB$13:$AB$29,$AC$13:$AC$29)) -> 95 | V14: =U14/$V$12 -> 0.15079365 | W14: =IF(W3=0,0, LOOKUP(W3-0.000000000001,$AB$13:$AB$29,$AC$13:$AC$29)) -> 95 | X14: =W14/$X$12 -> 0.11515152 | Y14: =IF(Y3=0,0, LOOKUP(Y3-0.000000000001,$AB$13:$AB$29,$AC$13:$AC$29)) -> 50 | Z14: =Y14/$Z$12 -> 0.11111111 | AB14: 80 | AC14: 1 | AH14: =(I22-B22)/B22 -> 0.0028229031 | AI14: =IF(I22-B22>0,"↑","↓") -> ↑ | AJ14: =(C22-B22)/B22 -> 0.0024571594 | AK14: =IF(C22-B22>0,"↑","↓") -> ↑ | AL14: =(E22-B22)/B22 -> 0.0033279778 | AM14: =IF(E22-B22>0,"↑","↓") -> ↑ | AN14: =(G22-B22)/B22 -> -0.0058156158 | AO14: =IF(G22-B22>0,"↑","↓") -> ↓ | AQ14: 0 | AR14: =AR15/AU15 -> 0.012284434 | AS14: =AS15/AU15 -> 0.048118701 | AT14: =AT15/AU15 -> 0.0044456887 | AU14: 5 | AV14: 1 | AW14: Scale | AX14: RANGE = | AY14: =AV13/AQ4 -> 0.01799461
A15: QQQ | B15: 607.87 | C15: 613.3 | D15: =IF(ABS(K15-I15)<ABS(C15-K15),$I$10,$C$10) -> LLM | E15: 615.4 | F15: =IF(ABS(K15-I15)<ABS(K15-E15),$I$10,$E$10) -> LLM | G15: 603.5 | H15: =IF(ABS(I15-K15)<ABS(K15-G15),$I$10,$G$10) -> LLM | I15: =(B6*X24)+(C6*X25)+(D6*X26)+(E6*X27)+(F6*X28)+(G6*X29)+(H6*X30)+(I6*X31)+(J6*X31) -> 609.91082 | J15: 609.60971 | K15: 608.81 | N15: =N4 -> Gemini Pro 3 | O15: =IF(O4=0,0, LOOKUP(O4-0.000000000001,$AB$13:$AB$29,$AC$13:$AC$29)) -> 75 | P15: =O15/$P$12 -> 0.11538462 | Q15: =IF(Q4=0,0, LOOKUP(Q4-0.000000000001,$AB$13:$AB$29,$AC$13:$AC$29)) -> 80 | R15: =Q15/$R$12 -> 0.11267606 | S15: =IF(S4=0,0, LOOKUP(S4-0.000000000001,$AB$13:$AB$29,$AC$13:$AC$29)) -> 95 | T15: =S15/$T$12 -> 0.11515152 | U15: =IF(U4=0,0, LOOKUP(U4-0.000000000001,$AB$13:$AB$29,$AC$13:$AC$29)) -> 95 | V15: =U15/$V$12 -> 0.15079365 | W15: =IF(W4=0,0, LOOKUP(W4-0.000000000001,$AB$13:$AB$29,$AC$13:$AC$29)) -> 95 | X15: =W15/$X$12 -> 0.11515152 | Y15: =IF(Y4=0,0, LOOKUP(Y4-0.000000000001,$AB$13:$AB$29,$AC$13:$AC$29)) -> 50 | Z15: =Y15/$Z$12 -> 0.11111111 | AB15: 82.5 | AC15: 2 | AH15: =(I23-B23)/B23 -> -0.023529412 | AI15: =IF(I23-B23>0,"↑","↓") -> ↓ | AJ15: =(C23-B23)/B23 -> -0.063938619 | AK15: =IF(C23-B23>0,"↑","↓") -> ↓ | AL15: =(E23-B23)/B23 -> -0.046035806 | AM15: =IF(E23-B23>0,"↑","↓") -> ↓ | AN15: =(G23-B23)/B23 -> -0.018414322 | AO15: =IF(G23-B23>0,"↑","↓") -> ↓ | AQ15: 0 | AR15: =AR4 -> 10.97 | AS15: =AS4 -> 42.97 | AT15: =AT4 -> 3.97 | AU15: =AV14*AV13 -> 893
A16: AAPL | B16: 272.14 | C16: 273.2 | D16: =IF(ABS(K16-I16)<ABS(C16-K16),$I$10,$C$10) -> RD | E16: 274.3 | F16: =IF(ABS(K16-I16)<ABS(K16-E16),$I$10,$E$10) -> 85520 | G16: 264.3 | H16: =IF(ABS(I16-K16)<ABS(K16-G16),$I$10,$G$10) -> MICH | I16: =(B7*Z24)+(C7*Z25)+(D7*Z26)+(E7*Z27)+(F7*Z28)+(G7*Z29)+(H7*Z30)+(I7*Z31)+(J7*Z31) -> 274.37624 | J16: 271.24407 | K16: 264.58 | N16: =N5 -> Claude | O16: =IF(O5=0,0, LOOKUP(O5-0.000000000001,$AB$13:$AB$29,$AC$13:$AC$29)) -> 80 | P16: =O16/$P$12 -> 0.12307692 | Q16: =IF(Q5=0,0, LOOKUP(Q5-0.000000000001,$AB$13:$AB$29,$AC$13:$AC$29)) -> 80 | R16: =Q16/$R$12 -> 0.11267606 | S16: =IF(S5=0,0, LOOKUP(S5-0.000000000001,$AB$13:$AB$29,$AC$13:$AC$29)) -> 95 | T16: =S16/$T$12 -> 0.11515152 | U16: =IF(U5=0,0, LOOKUP(U5-0.000000000001,$AB$13:$AB$29,$AC$13:$AC$29)) -> 80 | V16: =U16/$V$12 -> 0.12698413 | W16: =IF(W5=0,0, LOOKUP(W5-0.000000000001,$AB$13:$AB$29,$AC$13:$AC$29)) -> 90 | X16: =W16/$X$12 -> 0.10909091 | Y16: =IF(Y5=0,0, LOOKUP(Y5-0.000000000001,$AB$13:$AB$29,$AC$13:$AC$29)) -> 50 | Z16: =Y16/$Z$12 -> 0.11111111 | AB16: 85 | AC16: 5 | AH16: =(I24-B24)/B24 -> 0.0015463833 | AI16: =IF(I24-B24>0,"↑","↓") -> ↑ | AJ16: =(C24-B24)/B24 -> 0.008932831 | AK16: =IF(C24-B24>0,"↑","↓") -> ↑ | AL16: =(E24-B24)/B24 -> 0.012387517 | AM16: =IF(E24-B24>0,"↑","↓") -> ↑ | AN16: =(G24-B24)/B24 -> -0.0071890371 | AO16: =IF(G24-B24>0,"↑","↓") -> ↓
N17: =N6 -> GLM-4.7 | O17: =IF(O6=0,0, LOOKUP(O6-0.000000000001,$AB$13:$AB$29,$AC$13:$AC$29)) -> 70 | P17: =O17/$P$12 -> 0.10769231 | Q17: =IF(Q6=0,0, LOOKUP(Q6-0.000000000001,$AB$13:$AB$29,$AC$13:$AC$29)) -> 65 | R17: =Q17/$R$12 -> 0.091549296 | S17: =IF(S6=0,0, LOOKUP(S6-0.000000000001,$AB$13:$AB$29,$AC$13:$AC$29)) -> 90 | T17: =S17/$T$12 -> 0.10909091 | U17: =IF(U6=0,0, LOOKUP(U6-0.000000000001,$AB$13:$AB$29,$AC$13:$AC$29)) -> 30 | V17: =U17/$V$12 -> 0.047619048 | W17: =IF(W6=0,0, LOOKUP(W6-0.000000000001,$AB$13:$AB$29,$AC$13:$AC$29)) -> 90 | X17: =W17/$X$12 -> 0.10909091 | Y17: =IF(Y6=0,0, LOOKUP(Y6-0.000000000001,$AB$13:$AB$29,$AC$13:$AC$29)) -> 50 | Z17: =Y17/$Z$12 -> 0.11111111 | AB17: 87.5 | AC17: 10 | AH17: =(I25-B25)/B25 -> -0.027779819 | AI17: =IF(I25-B25>0,"↑","↓") -> ↓ | AJ17: =(C25-B25)/B25 -> 0.003895054 | AK17: =IF(C25-B25>0,"↑","↓") -> ↑ | AL17: =(E25-B25)/B25 -> 0.0079370912 | AM17: =IF(E25-B25>0,"↑","↓") -> ↑ | AN17: =(G25-B25)/B25 -> -0.028808701 | AO17: =IF(G25-B25>0,"↑","↓") -> ↓ | AP17: SPX | AQ17: =AQ13 -> +3-day | AR17: =AR13 -> User1 | AS17: =AS13 -> User2 | AT17: =AT13 -> User3 | AU17: F2 | AV17: 225.6 | AW17: =AW13 -> TEST | AX17: =AX13 -> BEST = | AY17: 225.6
N18: =N7 -> Kimi 2.5 | O18: =IF(O7=0,0, LOOKUP(O7-0.000000000001,$AB$13:$AB$29,$AC$13:$AC$29)) -> 70 | P18: =O18/$P$12 -> 0.10769231 | Q18: =IF(Q7=0,0, LOOKUP(Q7-0.000000000001,$AB$13:$AB$29,$AC$13:$AC$29)) -> 90 | R18: =Q18/$R$12 -> 0.12676056 | S18: =IF(S7=0,0, LOOKUP(S7-0.000000000001,$AB$13:$AB$29,$AC$13:$AC$29)) -> 95 | T18: =S18/$T$12 -> 0.11515152 | U18: =IF(U7=0,0, LOOKUP(U7-0.000000000001,$AB$13:$AB$29,$AC$13:$AC$29)) -> 50 | V18: =U18/$V$12 -> 0.079365079 | W18: =IF(W7=0,0, LOOKUP(W7-0.000000000001,$AB$13:$AB$29,$AC$13:$AC$29)) -> 90 | X18: =W18/$X$12 -> 0.10909091 | Y18: =IF(Y7=0,0, LOOKUP(Y7-0.000000000001,$AB$13:$AB$29,$AC$13:$AC$29)) -> 50 | Z18: =Y18/$Z$12 -> 0.11111111 | AB18: 90 | AC18: 20 | AH18: =K10 -> +3-day | AJ18: =C10 -> RD | AL18: =E10 -> 85520 | AN18: =G10 -> MICH | AQ18: 0 | AR18: =AR19/AU19 -> 0.011170213 | AS18: =AS19/AU19 -> 0.015425532 | AT18: =AT19/AU19 -> 0.26382979 | AU18: 5 | AV18: =AV14 -> 1 | AW18: =AW14 -> Scale | AX18: =AX14 -> RANGE = | AY18: =AV17/AQ5 -> 0.032650604
A19: model | B19: =B10 -> Close YF | C19: RD | E19: 85520 | G19: =G10 -> MICH | I19: +3-day | N19: =N8 -> Minimax 2.1 | O19: =IF(O8=0,0, LOOKUP(O8-0.000000000001,$AB$13:$AB$29,$AC$13:$AC$29)) -> 65 | P19: =O19/$P$12 -> 0.1 | Q19: =IF(Q8=0,0, LOOKUP(Q8-0.000000000001,$AB$13:$AB$29,$AC$13:$AC$29)) -> 80 | R19: =Q19/$R$12 -> 0.11267606 | S19: =IF(S8=0,0, LOOKUP(S8-0.000000000001,$AB$13:$AB$29,$AC$13:$AC$29)) -> 95 | T19: =S19/$T$12 -> 0.11515152 | U19: =IF(U8=0,0, LOOKUP(U8-0.000000000001,$AB$13:$AB$29,$AC$13:$AC$29)) -> 80 | V19: =U19/$V$12 -> 0.12698413 | W19: =IF(W8=0,0, LOOKUP(W8-0.000000000001,$AB$13:$AB$29,$AC$13:$AC$29)) -> 80 | X19: =W19/$X$12 -> 0.096969697 | Y19: =IF(Y8=0,0, LOOKUP(Y8-0.000000000001,$AB$13:$AB$29,$AC$13:$AC$29)) -> 50 | Z19: =Y19/$Z$12 -> 0.11111111 | AB19: 92.5 | AC19: 30 | AG19: =B28 -> Oraclum | AH19: =(I29-B29)/B29 -> 0.010138477 | AI19: =IF(I29-B29>0,"↑","↓") -> ↑ | AJ19: =(C29-B29)/B29 -> -0.0084075173 | AK19: =IF(C29-B29>0,"↑","↓") -> ↓ | AL19: =(E29-B29)/B29 -> 0.0014836795 | AM19: =IF(E29-B29>0,"↑","↓") -> ↑ | AN19: =(G29-B29)/B29 -> 0.0089020772 | AO19: =IF(G29-B29>0,"↑","↓") -> ↑ | AQ19: 0 | AR19: =AR5 -> 2.52 | AS19: =AS5 -> 3.48 | AT19: =AT5 -> 59.52 | AU19: =AV18*AV17 -> 225.6
A20: TNX | B20: =B11 -> 4.033 | C20: =C11 -> 4.01 | D20: =CONCATENATE(TEXT(AJ12,"0.00%")," ",AK12) -> -0.57% ↓ | E20: =E11 -> 4.05 | F20: =CONCATENATE(TEXT(AL12,"0.00%")," ",AM12) -> 0.42% ↑ | G20: =G11 -> 4.08 | H20: =CONCATENATE(TEXT(AN12,"0.00%")," ",AO12) -> 1.17% ↑ | I20: =K11 -> 4.085 | J20: =CONCATENATE(TEXT(AH12,"0.00%")," ",AI12) -> 1.29% ↑ | N20: =N9 -> LeChat | O20: =IF(O9=0,0, LOOKUP(O9-0.000000000001,$AB$13:$AB$29,$AC$13:$AC$29)) -> 75 | P20: =O20/$P$12 -> 0.11538462 | Q20: =IF(Q9=0,0, LOOKUP(Q9-0.000000000001,$AB$13:$AB$29,$AC$13:$AC$29)) -> 75 | R20: =Q20/$R$12 -> 0.1056338 | S20: =IF(S9=0,0, LOOKUP(S9-0.000000000001,$AB$13:$AB$29,$AC$13:$AC$29)) -> 70 | T20: =S20/$T$12 -> 0.084848485 | U20: =IF(U9=0,0, LOOKUP(U9-0.000000000001,$AB$13:$AB$29,$AC$13:$AC$29)) -> 90 | V20: =U20/$V$12 -> 0.14285714 | W20: =IF(W9=0,0, LOOKUP(W9-0.000000000001,$AB$13:$AB$29,$AC$13:$AC$29)) -> 95 | X20: =W20/$X$12 -> 0.11515152 | Y20: =IF(Y9=0,0, LOOKUP(Y9-0.000000000001,$AB$13:$AB$29,$AC$13:$AC$29)) -> 50 | Z20: =Y20/$Z$12 -> 0.11111111 | AB20: 95 | AC20: 40 | AH20: =(I30-B30)/B30 -> 0.016532958 | AI20: =IF(I30-B30>0,"↑","↓") -> ↑ | AJ20: =(C30-B30)/B30 -> 0.01630825 | AK20: =IF(C30-B30>0,"↑","↓") -> ↑ | AL20: =(E30-B30)/B30 -> 0.015652765 | AM20: =IF(E30-B30>0,"↑","↓") -> ↑ | AN20: =(G30-B30)/B30 -> 0.016451637 | AO20: =IF(G30-B30>0,"↑","↓") -> ↑
A21: DJI | B21: =B12 -> 49174.5 | C21: =C12 -> 49615 | D21: =CONCATENATE(TEXT(AJ13,"0.00%")," ",AK13) -> 0.90% ↑ | E21: =E12 -> 49583 | F21: =CONCATENATE(TEXT(AL13,"0.00%")," ",AM13) -> 0.83% ↑ | G21: =G12 -> 49622 | H21: =CONCATENATE(TEXT(AN13,"0.00%")," ",AO13) -> 0.91% ↑ | I21: =K12 -> 49625.97 | J21: =CONCATENATE(TEXT(AH13,"0.00%")," ",AI13) -> 0.92% ↑ | N21: =N10 -> Qwen | O21: =IF(O10=0,0, LOOKUP(O10-0.000000000001,$AB$13:$AB$29,$AC$13:$AC$29)) -> 70 | P21: =O21/$P$12 -> 0.10769231 | Q21: =IF(Q10=0,0, LOOKUP(Q10-0.000000000001,$AB$13:$AB$29,$AC$13:$AC$29)) -> 80 | R21: =Q21/$R$12 -> 0.11267606 | S21: =IF(S10=0,0, LOOKUP(S10-0.000000000001,$AB$13:$AB$29,$AC$13:$AC$29)) -> 95 | T21: =S21/$T$12 -> 0.11515152 | U21: =IF(U10=0,0, LOOKUP(U10-0.000000000001,$AB$13:$AB$29,$AC$13:$AC$29)) -> 50 | V21: =U21/$V$12 -> 0.079365079 | W21: =IF(W10=0,0, LOOKUP(W10-0.000000000001,$AB$13:$AB$29,$AC$13:$AC$29)) -> 95 | X21: =W21/$X$12 -> 0.11515152 | Y21: =IF(Y10=0,0, LOOKUP(Y10-0.000000000001,$AB$13:$AB$29,$AC$13:$AC$29)) -> 50 | Z21: =Y21/$Z$12 -> 0.11111111 | AB21: 96 | AC21: 50 | AH21: =(I31-B31)/B31 -> 0.010497621 | AI21: =IF(I31-B31>0,"↑","↓") -> ↑ | AJ21: =(C31-B31)/B31 -> 0.010129078 | AK21: =IF(C31-B31>0,"↑","↓") -> ↑ | AL21: =(E31-B31)/B31 -> 0.011006561 | AM21: =IF(E31-B31>0,"↑","↓") -> ↑ | AN21: =(G31-B31)/B31 -> 0.0017929901 | AO21: =IF(G31-B31>0,"↑","↓") -> ↑ | AP21: VIX | AQ21: =AQ17 -> +3-day | AR21: =AR17 -> User1 | AS21: =AS17 -> User2 | AT21: =AT17 -> User3 | AU21: F3 | AV21: 3.3 | AW21: =AW17 -> TEST | AX21: =AX17 -> BEST = | AY21: 3.3
A22: SPX | B22: =B13 -> 6890.07 | C22: =C13 -> 6907 | D22: =CONCATENATE(TEXT(AJ14,"0.00%")," ",AK14) -> 0.25% ↑ | E22: =E13 -> 6913 | F22: =CONCATENATE(TEXT(AL14,"0.00%")," ",AM14) -> 0.33% ↑ | G22: =G13 -> 6850 | H22: =CONCATENATE(TEXT(AN14,"0.00%")," ",AO14) -> -0.58% ↓ | I22: =K13 -> 6909.52 | J22: =CONCATENATE(TEXT(AH14,"0.00%")," ",AI14) -> 0.28% ↑ | AB22: 97 | AC22: 60 | AH22: =(I32-B32)/B32 -> -0.023529412 | AI22: =IF(I32-B32>0,"↑","↓") -> ↓ | AJ22: =(C32-B32)/B32 -> -0.063938619 | AK22: =IF(C32-B32>0,"↑","↓") -> ↓ | AL22: =(E32-B32)/B32 -> -0.046035806 | AM22: =IF(E32-B32>0,"↑","↓") -> ↓ | AN22: =(G32-B32)/B32 -> -0.018414322 | AO22: =IF(G32-B32>0,"↑","↓") -> ↓ | AQ22: 0 | AR22: =AR23/AU23 -> 0.23939394 | AS22: =AS23/AU23 -> 0.13333333 | AT22: =AT23/AU23 -> 0.03030303 | AU22: 5 | AV22: =AV18 -> 1 | AW22: =AW18 -> Scale | AX22: =AX18 -> RANGE = | AY22: =AV21/AQ6 -> 0.17286537
A23: VIX | B23: =B14 -> 19.55 | C23: =C14 -> 18.3 | D23: =CONCATENATE(TEXT(AJ15,"0.00%")," ",AK15) -> -6.39% ↓ | E23: =E14 -> 18.65 | F23: =CONCATENATE(TEXT(AL15,"0.00%")," ",AM15) -> -4.60% ↓ | G23: =G14 -> 19.19 | H23: =CONCATENATE(TEXT(AN15,"0.00%")," ",AO15) -> -1.84% ↓ | I23: =K14 -> 19.09 | J23: =CONCATENATE(TEXT(AH15,"0.00%")," ",AI15) -> -2.35% ↓ | N23: History | O23: TNX | P23: =SUM(O24:O32) -> 681.25 | Q23: DJI | R23: =SUM(Q24:Q32) -> 657.5 | S23: SPX | T23: =SUM(S24:S32) -> 682.5 | U23: VIX | V23: =SUM(U24:U32) -> 329.775 | W23: QQQ | X23: =SUM(W24:W32) -> 595 | Y23: AAPL | Z23: =SUM(Y24:Y32) -> 528.75 | AB23: 98 | AC23: 65 | AH23: =(I33-B33)/B33 -> 0.0015463833 | AI23: =IF(I33-B33>0,"↑","↓") -> ↑ | AJ23: =(C33-B33)/B33 -> 0.008932831 | AK23: =IF(C33-B33>0,"↑","↓") -> ↑ | AL23: =(E33-B33)/B33 -> 0.012387517 | AM23: =IF(E33-B33>0,"↑","↓") -> ↑ | AN23: =(G33-B33)/B33 -> -0.0071890371 | AO23: =IF(G33-B33>0,"↑","↓") -> ↓ | AQ23: 0 | AR23: =AR6 -> 0.79 | AS23: =AS6 -> 0.44 | AT23: =AT6 -> 0.1 | AU23: =AV22*AV21 -> 3.3
A24: QQQ | B24: =B15 -> 607.87 | C24: =C15 -> 613.3 | D24: =CONCATENATE(TEXT(AJ16,"0.00%")," ",AK16) -> 0.89% ↑ | E24: =E15 -> 615.4 | F24: =CONCATENATE(TEXT(AL16,"0.00%")," ",AM16) -> 1.24% ↑ | G24: =G15 -> 603.5 | H24: =CONCATENATE(TEXT(AN16,"0.00%")," ",AO16) -> -0.72% ↓ | I24: =K15 -> 608.81 | J24: =CONCATENATE(TEXT(AH16,"0.00%")," ",AI16) -> 0.15% ↑ | N24: =N13 -> O 5.2 | O24: 78.75 | P24: =O24/$P$23 -> 0.11559633 | Q24: 76.25 | R24: =Q24/$R$23 -> 0.11596958 | S24: 77.5 | T24: =S24/$T$23 -> 0.11355311 | U24: 41.25 | V24: =U24/$V$23 -> 0.12508529 | W24: 67.5 | X24: =W24/$X$23 -> 0.11344538 | Y24: 53.75 | Z24: =Y24/$Z$23 -> 0.10165485 | AB24: 98.5 | AC24: 70 | AH24: =(I34-B34)/B34 -> -0.027958411 | AI24: =IF(I34-B34>0,"↑","↓") -> ↓ | AJ24: =(C34-B34)/B34 -> 0.0037106433 | AK24: =IF(C34-B34>0,"↑","↓") -> ↑ | AL24: =(E34-B34)/B34 -> 0.007751938 | AM24: =IF(E34-B34>0,"↑","↓") -> ↑ | AN24: =(G34-B34)/B34 -> -0.028987105 | AO24: =IF(G34-B34>0,"↑","↓") -> ↓
A25: AAPL | B25: =B16 -> 272.14 | C25: =C16 -> 273.2 | D25: =CONCATENATE(TEXT(AJ17,"0.00%")," ",AK17) -> 0.39% ↑ | E25: =E16 -> 274.3 | F25: =CONCATENATE(TEXT(AL17,"0.00%")," ",AM17) -> 0.79% ↑ | G25: =G16 -> 264.3 | H25: =CONCATENATE(TEXT(AN17,"0.00%")," ",AO17) -> -2.88% ↓ | I25: =K16 -> 264.58 | J25: =CONCATENATE(TEXT(AH17,"0.00%")," ",AI17) -> -2.78% ↓ | N25: =N14 -> Grok 4.1 | O25: 72.5 | P25: =O25/$P$23 -> 0.10642202 | Q25: 72.5 | R25: =Q25/$R$23 -> 0.11026616 | S25: 77.5 | T25: =S25/$T$23 -> 0.11355311 | U25: 35.5 | V25: =U25/$V$23 -> 0.10764915 | W25: 65 | X25: =W25/$X$23 -> 0.1092437 | Y25: 55 | Z25: =Y25/$Z$23 -> 0.10401891 | AB25: 99 | AC25: 75 | AP25: QQQ | AQ25: =AQ21 -> +3-day | AR25: =AR21 -> User1 | AS25: =AS21 -> User2 | AT25: =AT21 -> User3 | AU25: F4 | AV25: 16 | AW25: =AW21 -> TEST | AX25: =AX21 -> BEST = | AY25: 16
N26: =N15 -> Gemini Pro 3 | O26: 75 | P26: =O26/$P$23 -> 0.11009174 | Q26: 72.5 | R26: =Q26/$R$23 -> 0.11026616 | S26: 77.5 | T26: =S26/$T$23 -> 0.11355311 | U26: 32.525 | V26: =U26/$V$23 -> 0.098627852 | W26: 65 | X26: =W26/$X$23 -> 0.1092437 | Y26: 61.25 | Z26: =Y26/$Z$23 -> 0.11583924 | AB26: 99.25 | AC26: 80 | AH26: RD | AI26: 85220 | AJ26: MICH | AK26: =J10 -> ML | AL26: =I10 -> LLM | AQ26: 0 | AR26: =AR27/AU27 -> 0.280625 | AS26: =AS27/AU27 -> 0.411875 | AT26: =AT27/AU27 -> 0.331875 | AU26: 5 | AV26: =AV22 -> 1 | AW26: =AW22 -> Scale | AX26: =AX22 -> RANGE = | AY26: =AV25/AQ7 -> 0.026280777
N27: =N16 -> Claude | O27: 72.5 | P27: =O27/$P$23 -> 0.10642202 | Q27: 72.5 | R27: =Q27/$R$23 -> 0.11026616 | S27: 75 | T27: =S27/$T$23 -> 0.10989011 | U27: 48.75 | V27: =U27/$V$23 -> 0.14782806 | W27: 67.5 | X27: =W27/$X$23 -> 0.11344538 | Y27: 55 | Z27: =Y27/$Z$23 -> 0.10401891 | AB27: 99.5 | AC27: 90 | AG27: TNX | AH27: =100-ABS(($K11-C11)/($K11))*100 -> 98.164015 | AI27: =100-ABS(($K11-E11)/($K11))*100 -> 99.143207 | AJ27: =100-ABS(($K11-G11)/($K11))*100 -> 99.877601 | AK27: =100-ABS((($K11-J11)/($K11)))*100 -> 98.951522 | AL27: =100-ABS((($K11-I11)/($K11)))*100 -> 98.871414 | AQ27: 0 | AR27: =AR7 -> 4.49 | AS27: =AS7 -> 6.59 | AT27: =AT7 -> 5.31 | AU27: =AV26*AV25 -> 16
A28: model | B28: Oraclum | C28: RD | E28: 85520 | G28: =G19 -> MICH | I28: +3-day | N28: =N17 -> GLM-4.7 | O28: 77.5 | P28: =O28/$P$23 -> 0.11376147 | Q28: 71.25 | R28: =Q28/$R$23 -> 0.10836502 | S28: 75 | T28: =S28/$T$23 -> 0.10989011 | U28: 35.5 | V28: =U28/$V$23 -> 0.10764915 | W28: 66.25 | X28: =W28/$X$23 -> 0.11134454 | Y28: 57.5 | Z28: =Y28/$Z$23 -> 0.10874704 | AB28: 99.75 | AC28: 95 | AG28: DJI | AH28: =100-ABS(($K12-C12)/($K12))*100 -> 99.977895 | AI28: =100-ABS(($K12-E12)/($K12))*100 -> 99.913412 | AJ28: =100-ABS(($K12-G12)/($K12))*100 -> 99.992 | AK28: =100-ABS((($K12-J12)/($K12)))*100 -> 99.184133 | AL28: =100-ABS((($K12-I12)/($K12)))*100 -> 99.245382
A29: TNX | B29: 4.044 | C29: =C20 -> 4.01 | D29: =CONCATENATE(TEXT(AJ19,"0.00%")," ",AK19) -> -0.84% ↓ | E29: =E20 -> 4.05 | F29: =CONCATENATE(TEXT(AL19,"0.00%")," ",AM19) -> 0.15% ↑ | G29: =G20 -> 4.08 | H29: =CONCATENATE(TEXT(AN19,"0.00%")," ",AO19) -> 0.89% ↑ | I29: =I20 -> 4.085 | J29: =CONCATENATE(TEXT(AH19,"0.00%")," ",AI19) -> 1.01% ↑ | N29: =N18 -> Kimi 2.5 | O29: 76.25 | P29: =O29/$P$23 -> 0.11192661 | Q29: 70 | R29: =Q29/$R$23 -> 0.10646388 | S29: 76.25 | T29: =S29/$T$23 -> 0.11172161 | U29: 38.75 | V29: =U29/$V$23 -> 0.11750436 | W29: 66.25 | X29: =W29/$X$23 -> 0.11134454 | Y29: 60 | Z29: =Y29/$Z$23 -> 0.11347518 | AB29: 99.99 | AC29: 100 | AG29: SPX | AH29: =100-ABS(($K13-C13)/($K13))*100 -> 99.963529 | AI29: =100-ABS(($K13-E13)/($K13))*100 -> 99.949635 | AJ29: =100-ABS(($K13-G13)/($K13))*100 -> 99.13858 | AK29: =100-ABS((($K13-J13)/($K13)))*100 -> 99.953025 | AL29: =100-ABS((($K13-I13)/($K13)))*100 -> 99.966471 | AR29: User1 | AS29: User2 | AT29: User3
A30: DJI | B30: 48818.85 | C30: =C21 -> 49615 | D30: =CONCATENATE(TEXT(AJ20,"0.00%")," ",AK20) -> 1.63% ↑ | E30: =E21 -> 49583 | F30: =CONCATENATE(TEXT(AL20,"0.00%")," ",AM20) -> 1.57% ↑ | G30: =G21 -> 49622 | H30: =CONCATENATE(TEXT(AN20,"0.00%")," ",AO20) -> 1.65% ↑ | I30: =I21 -> 49625.97 | J30: =CONCATENATE(TEXT(AH20,"0.00%")," ",AI20) -> 1.65% ↑ | N30: =N19 -> Minimax 2.1 | O30: 73.75 | P30: =O30/$P$23 -> 0.10825688 | Q30: 75 | R30: =Q30/$R$23 -> 0.11406844 | S30: 71.25 | T30: =S30/$T$23 -> 0.1043956 | U30: 42.5 | V30: =U30/$V$23 -> 0.12887575 | W30: 65 | X30: =W30/$X$23 -> 0.1092437 | Y30: 58.75 | Z30: =Y30/$Z$23 -> 0.11111111 | AG30: VIX | AH30: =100-ABS(($K14-C14)/($K14))*100 -> 95.861708 | AI30: =100-ABS(($K14-E14)/($K14))*100 -> 97.695128 | AJ30: =100-ABS(($K14-G14)/($K14))*100 -> 99.476166 | AK30: =100-ABS((($K14-J14)/($K14)))*100 -> 99.185218 | AL30: =100-ABS((($K14-I14)/($K14)))*100 -> 98.804719 | AR30: =SUM(AR14,AR18,AR22,AR26) -> 0.54347359 | AS30: =SUM(AS14,AS18,AS22,AS26) -> 0.60875257 | AT30: =SUM(AT14,AT18,AT22,AT26) -> 0.63045351 | AU30: CALC
A31: SPX | B31: 6837.74 | C31: =C22 -> 6907 | D31: =CONCATENATE(TEXT(AJ21,"0.00%")," ",AK21) -> 1.01% ↑ | E31: =E22 -> 6913 | F31: =CONCATENATE(TEXT(AL21,"0.00%")," ",AM21) -> 1.10% ↑ | G31: =G22 -> 6850 | H31: =CONCATENATE(TEXT(AN21,"0.00%")," ",AO21) -> 0.18% ↑ | I31: =I22 -> 6909.52 | J31: =CONCATENATE(TEXT(AH21,"0.00%")," ",AI21) -> 1.05% ↑ | N31: =N20 -> LeChat | O31: 77.5 | P31: =O31/$P$23 -> 0.11376147 | Q31: 73.75 | R31: =Q31/$R$23 -> 0.1121673 | S31: 76.25 | T31: =S31/$T$23 -> 0.11172161 | U31: 27.5 | V31: =U31/$V$23 -> 0.08339019 | W31: 66.25 | X31: =W31/$X$23 -> 0.11134454 | Y31: 63.75 | Z31: =Y31/$Z$23 -> 0.12056738 | AC31: Extreme Fear | AG31: QQQ | AH31: =100-ABS(($K15-C15)/($K15))*100 -> 99.262496 | AI31: =100-ABS(($K15-E15)/($K15))*100 -> 98.91756 | AJ31: =100-ABS(($K15-G15)/($K15))*100 -> 99.127807 | AK31: =100-ABS((($K15-J15)/($K15)))*100 -> 99.868643 | AL31: =100-ABS((($K15-I15)/($K15)))*100 -> 99.819185 | AR31: =AR9 -> 2.16 | AS31: =AS9 -> 2.24 | AT31: =AT9 -> 1.79 | AU31: Oraclum
A32: VIX | B32: 19.55 | C32: =C23 -> 18.3 | D32: =CONCATENATE(TEXT(AJ22,"0.00%")," ",AK22) -> -6.39% ↓ | E32: =E23 -> 18.65 | F32: =CONCATENATE(TEXT(AL22,"0.00%")," ",AM22) -> -4.60% ↓ | G32: =G23 -> 19.19 | H32: =CONCATENATE(TEXT(AN22,"0.00%")," ",AO22) -> -1.84% ↓ | I32: =I23 -> 19.09 | J32: =CONCATENATE(TEXT(AH22,"0.00%")," ",AI22) -> -2.35% ↓ | N32: =N21 -> Qwen | O32: 77.5 | P32: =O32/$P$23 -> 0.11376147 | Q32: 73.75 | R32: =Q32/$R$23 -> 0.1121673 | S32: 76.25 | T32: =S32/$T$23 -> 0.11172161 | U32: 27.5 | V32: =U32/$V$23 -> 0.08339019 | W32: 66.25 | X32: =W32/$X$23 -> 0.11134454 | Y32: 63.75 | Z32: =Y32/$Z$23 -> 0.12056738 | AC32: Fear | AG32: AAPL | AH32: =100-ABS(($K16-C16)/($K16))*100 -> 96.742006 | AI32: =100-ABS(($K16-E16)/($K16))*100 -> 96.326253 | AJ32: =100-ABS(($K16-G16)/($K16))*100 -> 99.894172 | AK32: =100-ABS((($K16-J16)/($K16)))*100 -> 97.481263 | AL32: =100-ABS((($K16-I16)/($K16)))*100 -> 96.297437
A33: QQQ | B33: 607.87 | C33: =C24 -> 613.3 | D33: =CONCATENATE(TEXT(AJ23,"0.00%")," ",AK23) -> 0.89% ↑ | E33: =E24 -> 615.4 | F33: =CONCATENATE(TEXT(AL23,"0.00%")," ",AM23) -> 1.24% ↑ | G33: =G24 -> 603.5 | H33: =CONCATENATE(TEXT(AN23,"0.00%")," ",AO23) -> -0.72% ↓ | I33: =I24 -> 608.81 | J33: =CONCATENATE(TEXT(AH23,"0.00%")," ",AI23) -> 0.15% ↑ | AC33: Neutral
A34: AAPL | B34: 272.19 | C34: =C25 -> 273.2 | D34: =CONCATENATE(TEXT(AJ24,"0.00%")," ",AK24) -> 0.37% ↑ | E34: =E25 -> 274.3 | F34: =CONCATENATE(TEXT(AL24,"0.00%")," ",AM24) -> 0.78% ↑ | G34: =G25 -> 264.3 | H34: =CONCATENATE(TEXT(AN24,"0.00%")," ",AO24) -> -2.90% ↓ | I34: =I25 -> 264.58 | J34: =CONCATENATE(TEXT(AH24,"0.00%")," ",AI24) -> -2.80% ↓ | AC34: Greed | AG34: =AB1 -> AVR-4 | AH34: {=SUM(AH28:AH31/4)} -> 98.766407 | AI34: {=SUM(AI28:AI31/4)} -> 99.118934 | AJ34: {=SUM(AJ28:AJ31/4)} -> 99.433638 | AK34: {=SUM(AK28:AK31/4)} -> 99.547755 | AL34: {=SUM(AL28:AL31/4)} -> 99.458939
AC35: Extreme Greed | AG35: =AC1 -> AVR-6 | AH35: {=SUM(AH27:AH32/6)} -> 98.328608 | AI35: {=SUM(AI27:AI32/6)} -> 98.657533 | AJ35: {=SUM(AJ27:AJ32/6)} -> 99.584388 | AK35: {=SUM(AK27:AK32/6)} -> 99.103967 | AL35: {=SUM(AL27:AL32/6)} -> 98.834101
AH38: RD CALC | AL38: 85520 CALC
AG39: =A2 -> TNX | AH39: =C11 -> 4.01 | AI39: =100-ABS(($K11-AH39)/($K11))*100 -> 98.164015 | AK39: =AG39 -> TNX | AL39: =E11 -> 4.05 | AM39: =100-ABS(($K11-AL39)/($K11))*100 -> 99.143207
AG40: =A3 -> DJI | AH40: =C12 -> 49615 | AI40: =100-ABS(($K12-AH40)/($K12))*100 -> 99.977895 | AK40: =AG40 -> DJI | AL40: =E12 -> 49583 | AM40: =100-ABS(($K12-AL40)/($K12))*100 -> 99.913412
AG41: =A4 -> SPX | AH41: =C13 -> 6907 | AI41: =100-ABS(($K13-AH41)/($K13))*100 -> 99.963529 | AK41: =AG41 -> SPX | AL41: =E13 -> 6913 | AM41: =100-ABS(($K13-AL41)/($K13))*100 -> 99.949635
AG42: =A5 -> VIX | AH42: =C14 -> 18.3 | AI42: =100-ABS(($K14-AH42)/($K14))*100 -> 95.861708 | AK42: =AG42 -> VIX | AL42: =E14 -> 18.65 | AM42: =100-ABS(($K14-AL42)/($K14))*100 -> 97.695128
...

Sheet 26-1-07
A1: model | B1: O 5.2 | C1: Grok 4.1 | D1: Gemini Pro 3 | E1: Claude | F1: GLM-4.7 | G1: Kimi 2.5 | H1: Minimax 2.1 | I1: LeChat | J1: Qwen | L1: 26-Q1-07 | N1: Accuracy | O1: TNX | P1: =SUM(O2:O10) -> 895.34483 | Q1: DJI | R1: =SUM(Q2:Q10) -> 895.00523 | S1: SPX | T1: =SUM(S2:S10) -> 897.60837 | U1: VIX | V1: =SUM(U2:U10) -> 882.50393 | W1: QQQ | X1: =SUM(W2:W10) -> 898.48033 | Y1: AAPL | Z1: =SUM(Y2:Y9) -> 326.52381 | AB1: AVR-4 | AC1: AVR-6 | AH1: max-Q | AL1: REPORT | AO1: Round | AP1: 2 | AQ1: =K10 -> +3-day | AR1: User1 | AS1: User2 | AT1: User3
A2: TNX | B2: 4.03 | C2: 4.05 | D2: 4.05 | E2: 4.055 | F2: 4.033 | G2: 4.043 | H2: 4.01 | I2: 4.05 | J2: 4.03 | N2: =B1 -> O 5.2 | O2: =100-ABS((($K11-B2)/($K11)))*100 -> 99.261084 | P2: =O2/$P$1 -> 0.11086353 | Q2: =100-ABS((($K12-B3)/($K12)))*100 -> 99.622413 | R2: =Q2/$R$1 -> 0.11130931 | S2: =100-ABS((($K13-B4)/($K13)))*100 -> 99.775961 | T2: =S2/$T$1 -> 0.11115757 | U2: =100-ABS((($K14-B5)/($K14)))*100 -> 97.537978 | V2: =U2/$V$1 -> 0.11052413 | W2: =100-ABS((($K15-B6)/($K15)))*100 -> 99.936066 | X2: =W2/$X$1 -> 0.11122788 | Y2: =100-ABS((($K16-B7)/($K16)))*100 -> 40.733631 | Z2: =Y2/$Z$1 -> 0.12474934 | AB2: =(Q2+S2+U2+W2)/4 -> 99.218104 | AC2: =(O2+Q2+S2+U2+W2+Y2)/6 -> 89.477855 | AD2: =IF($AB2=MAX(AB2:AB10),"TOP","") | AE2: =IF($AC2=MAX(AC2:AC10),"TOP","") | AG2: TNX | AH2: GLM, L | AI2: =MAX(O2:P10) -> 99.876847 | AK2: =AG2 -> TNX | AL2: 4.25 | AM2: =100-ABS(($K11-AL2)/($K11))*100 -> 95.320197 | AP2: Ticker | AQ2: Exact | AR2: ∆ | AS2: =AR2 -> ∆ | AT2: =AS2 -> ∆ | AU2: Penalty function
A3: DJI | B3: 49338 | C3: 49320 | D3: 49290 | E3: 49300 | F3: 48705.34 | G3: 49408 | H3: 49320 | I3: 49250 | J3: 49320 | L3: 2026/02/24 | N3: =C1 -> Grok 4.1 | O3: =100-ABS((($K11-C2)/($K11)))*100 -> 99.753695 | P3: =O3/$P$1 -> 0.11141372 | Q3: =100-ABS((($K12-C3)/($K12)))*100 -> 99.586068 | R3: =Q3/$R$1 -> 0.1112687 | S3: =100-ABS((($K13-C4)/($K13)))*100 -> 99.877271 | T3: =S3/$T$1 -> 0.11127043 | U3: =100-ABS((($K14-C5)/($K14)))*100 -> 99.947617 | V3: =U3/$V$1 -> 0.11325459 | W3: =100-ABS((($K15-C6)/($K15)))*100 -> 100 | X3: =W3/$X$1 -> 0.11129904 | Y3: =100-ABS((($K16-C7)/($K16)))*100 -> 40.848214 | Z3: =Y3/$Z$1 -> 0.12510026 | AB3: =(Q3+S3+U3+W3)/4 -> 99.852739 | AC3: =(O3+Q3+S3+U3+W3+Y3)/6 -> 90.002144 | AD3: =IF($AB3=MAX(AB2:AB10),"TOP","") -> TOP | AE3: =IF($AC3=MAX(AC2:AC10),"TOP","") -> TOP | AG3: DJI | AH3: GLM | AI3: =MAX(Q2:R10) -> 99.763756 | AK3: =AG3 -> DJI | AL3: 48833 | AM3: =100-ABS(($K12-AL3)/($K12))*100 -> 98.602726 | AP3: =AG2 -> TNX | AQ3: =K11 -> 4.06 | AR3: =ABS(C29-AQ3) -> 0.04 | AS3: =ABS(E29-K11) -> 0.01 | AT3: =ABS(AQ3-G29) -> 0 | AU3: N/A
A4: SPX | B4: 6925 | C4: 6918 | D4: 6915 | E4: 6920 | F4: 6891.15 | G4: 6925 | H4: 6922 | I4: 6835 | J4: 6914 | N4: =D1 -> Gemini Pro 3 | O4: =100-ABS((($K11-D2)/($K11)))*100 -> 99.753695 | P4: =O4/$P$1 -> 0.11141372 | Q4: =100-ABS((($K12-D3)/($K12)))*100 -> 99.525492 | R4: =Q4/$R$1 -> 0.11120102 | S4: =100-ABS((($K13-D4)/($K13)))*100 -> 99.920689 | T4: =S4/$T$1 -> 0.1113188 | U4: =100-ABS((($K14-D5)/($K14)))*100 -> 99.947617 | V4: =U4/$V$1 -> 0.11325459 | W4: =100-ABS((($K15-D6)/($K15)))*100 -> 99.959016 | X4: =W4/$X$1 -> 0.11125343 | Y4: =100-ABS((($K16-D7)/($K16)))*100 -> 40.78869 | Z4: =Y4/$Z$1 -> 0.12491797 | AB4: =(Q4+S4+U4+W4)/4 -> 99.838204 | AC4: =(O4+Q4+S4+U4+W4+Y4)/6 -> 89.982533 | AD4: =IF($AB4=MAX(AB2:AB10),"TOP","") | AE4: =IF($AC4=MAX(AC2:AC10),"TOP","") | AG4: SPX | AH4: C | AI4: =MAX(S2:T10) -> 99.935162 | AK4: =AG4 -> SPX | AL4: 6810 | AM4: =100-ABS(($K13-AL4)/($K13))*100 -> 98.559668 | AP4: =AG3 -> DJI | AQ4: =K12 -> 49525 | AR4: =ABS(C12-AQ4) -> 10 | AS4: =ABS(E12-AQ4) -> 42 | AT4: =ABS(AQ4-G12) -> 215 | AU4: F1
A5: VIX | B5: 19.56 | C5: 19.1 | D5: 19.1 | E5: 19.2 | F5: 20.25 | G5: 19.76 | H5: 19.2 | I5: 19 | J5: 18.38 | L5: LLM | N5: =E1 -> Claude | O5: =100-ABS((($K11-E2)/($K11)))*100 -> 99.876847 | P5: =O5/$P$1 -> 0.11155126 | Q5: =100-ABS((($K12-E3)/($K12)))*100 -> 99.545684 | R5: =Q5/$R$1 -> 0.11122358 | S5: =100-ABS((($K13-E4)/($K13)))*100 -> 99.848325 | T5: =S5/$T$1 -> 0.11123818 | U5: =100-ABS((($K14-E5)/($K14)))*100 -> 99.423782 | V5: =U5/$V$1 -> 0.11266101 | W5: =100-ABS((($K15-E6)/($K15)))*100 -> 99.836066 | X5: =W5/$X$1 -> 0.11111658 | Y5: =100-ABS((($K16-E7)/($K16)))*100 -> 40.922619 | Z5: =Y5/$Z$1 -> 0.12532813 | AB5: =(Q5+S5+U5+W5)/4 -> 99.663464 | AC5: =(O5+Q5+S5+U5+W5+Y5)/6 -> 89.908887 | AD5: =IF($AB5=MAX(AB2:AB10),"TOP","") | AE5: =IF($AC5=MAX(AC2:AC10),"TOP","") | AG5: VIX | AH5: M | AI5: =MAX(U2:V10) -> 99.947617 | AK5: =AG5 -> VIX | AL5: 19.1 | AM5: =100-ABS(($K14-AL5)/($K14))*100 -> 99.947617 | AP5: =AG4 -> SPX | AQ5: =K13 -> 6909.52 | AR5: =ABS(C13-AQ5) -> 2.52 | AS5: =ABS(E13-AQ5) -> 3.48 | AT5: =ABS(AQ5-G13) -> 9.48 | AU5: F2
A6: QQQ | B6: 609.61 | C6: 610 | D6: 610.25 | E6: 611 | F6: 606.37 | G6: 611 | H6: 612 | I6: 610 | J6: 609 | N6: =F1 -> GLM-4.7 | O6: =100-ABS((($K11-F2)/($K11)))*100 -> 99.334975 | P6: =O6/$P$1 -> 0.11094605 | Q6: =100-ABS((($K12-F3)/($K12)))*100 -> 98.344957 | R6: =Q6/$R$1 -> 0.10988199 | S6: =100-ABS((($K13-F4)/($K13)))*100 -> 99.734135 | T6: =S6/$T$1 -> 0.11111097 | U6: =100-ABS((($K14-F5)/($K14)))*100 -> 93.92352 | V6: =U6/$V$1 -> 0.10642844 | W6: =100-ABS((($K15-F6)/($K15)))*100 -> 99.404918 | X6: =W6/$X$1 -> 0.11063672 | Y6: =100-ABS((($K16-F7)/($K16)))*100 -> 40.611607 | Z6: =Y6/$Z$1 -> 0.12437564 | AB6: =(Q6+S6+U6+W6)/4 -> 97.851883 | AC6: =(O6+Q6+S6+U6+W6+Y6)/6 -> 88.559019 | AD6: =IF($AB6=MAX(AB2:AB10),"TOP","") | AE6: =IF($AC6=MAX(AC2:AC10),"TOP","") | AG6: QQQ | AH6: o | AI6: =MAX(W2:X10) -> 100 | AK6: =AG6 -> QQQ | AL6: 604.8 | AM6: =100-ABS(($K15-AL6)/($K15))*100 -> 99.147541 | AP6: =AG5 -> VIX | AQ6: =K14 -> 19.09 | AR6: =ABS(C14-AQ6) -> 0.69 | AS6: =ABS(E14-AQ6) -> 0.34 | AT6: =ABS(AQ6-G14) -> 0.12 | AU6: F3
A7: AAPL | B7: 273.73 | C7: 274.5 | D7: 274.1 | E7: 275 | F7: 272.91 | G7: 275 | H7: 274 | I7: 275 | J7: 275 | L7: F & G | N7: =G1 -> Kimi 2.5 | O7: =100-ABS((($K11-G2)/($K11)))*100 -> 99.581281 | P7: =O7/$P$1 -> 0.11122115 | Q7: =100-ABS((($K12-G3)/($K12)))*100 -> 99.763756 | R7: =Q7/$R$1 -> 0.11146723 | S7: =100-ABS((($K13-G4)/($K13)))*100 -> 99.775961 | T7: =S7/$T$1 -> 0.11115757 | U7: =100-ABS((($K14-G5)/($K14)))*100 -> 96.490309 | V7: =U7/$V$1 -> 0.10933697 | W7: =100-ABS((($K15-G6)/($K15)))*100 -> 99.836066 | X7: =W7/$X$1 -> 0.11111658 | Y7: =100-ABS((($K16-G7)/($K16)))*100 -> 40.922619 | Z7: =Y7/$Z$1 -> 0.12532813 | AB7: =(Q7+S7+U7+W7)/4 -> 98.966523 | AC7: =(O7+Q7+S7+U7+W7+Y7)/6 -> 89.394999 | AD7: =IF($AB7=MAX(AB2:AB10),"TOP","") | AE7: =IF($AC7=MAX(AC2:AC10),"TOP","") | AG7: AAPL | AH7: Q | AI7: =MAX(Y2:Z10) -> 40.922619 | AK7: =AG7 -> AAPL | AL7: 245.25 | AM7: =100-ABS(($K16-AL7)/($K16))*100 -> 36.495536 | AP7: =AG6 -> QQQ | AQ7: =K15 -> 610 | AR7: =ABS(C15-AQ7) -> 3.3 | AS7: =ABS(E15-AQ7) -> 5.4 | AT7: =ABS(AQ7-G15) -> 0.1 | AU7: F4
L8: 43 | N8: =H1 -> Minimax 2.1 | O8: =100-ABS((($K11-H2)/($K11)))*100 -> 98.768473 | P8: =O8/$P$1 -> 0.11031333 | Q8: =100-ABS((($K12-H3)/($K12)))*100 -> 99.586068 | R8: =Q8/$R$1 -> 0.1112687 | S8: =100-ABS((($K13-H4)/($K13)))*100 -> 99.81938 | T8: =S8/$T$1 -> 0.11120594 | U8: =100-ABS((($K14-H5)/($K14)))*100 -> 99.423782 | V8: =U8/$V$1 -> 0.11266101 | W8: =100-ABS((($K15-H6)/($K15)))*100 -> 99.672131 | X8: =W8/$X$1 -> 0.11093413 | Y8: =100-ABS((($K16-H7)/($K16)))*100 -> 40.77381 | Z8: =Y8/$Z$1 -> 0.12487239 | AB8: =(Q8+S8+U8+W8)/4 -> 99.62534 | AC8: =(O8+Q8+S8+U8+W8+Y8)/6 -> 89.67394 | AD8: =IF($AB8=MAX(AB2:AB10),"TOP","") | AE8: =IF($AC8=MAX(AC2:AC10),"TOP","") | AP8: =AG7 -> AAPL | AQ8: =K16 -> 672 | AR8: =ABS(C34-AQ8) -> 398.8 | AS8: =ABS(E34-K16) -> 397.7 | AT8: =ABS(AQ8-G34) -> 399.1 | AU8: N/A
L9: =IF(L8<25,AC31,IF(L8<45,AC32,IF(L8<55,AC33,IF(L8<75,AC34,AC35)))) -> Fear | N9: =I1 -> LeChat | O9: =100-ABS((($K11-I2)/($K11)))*100 -> 99.753695 | P9: =O9/$P$1 -> 0.11141372 | Q9: =100-ABS((($K12-I3)/($K12)))*100 -> 99.444725 | R9: =Q9/$R$1 -> 0.11111078 | S9: =100-ABS((($K13-I4)/($K13)))*100 -> 98.921488 | T9: =S9/$T$1 -> 0.11020562 | U9: =100-ABS((($K14-I5)/($K14)))*100 -> 99.528549 | V9: =U9/$V$1 -> 0.11277972 | W9: =100-ABS((($K15-I6)/($K15)))*100 -> 100 | X9: =W9/$X$1 -> 0.11129904 | Y9: =100-ABS((($K16-I7)/($K16)))*100 -> 40.922619 | Z9: =Y9/$Z$1 -> 0.12532813 | AB9: =(Q10+S10+U10+W10)/4 -> 98.909518 | AC9: =(O10+Q10+S10+U10+W10+Y10)/6 -> 89.303629 | AD9: =IF($AB10=MAX(AB2:AB10),"TOP","") | AE9: =IF($AC9=MAX(AC2:AC10),"TOP","") | AG9: max-Q AVR-4 | AI9: =AVERAGE(AI3:AI6) -> 99.911634 | AK9: max-Q AVR-4 | AM9: =AVERAGE(AM3:AM6) -> 99.064388 | AQ9: 0 | AR9: 2.16 | AS9: 2.24 | AT9: 1.79 | AU9: Round Penalty
B10: Close YF | C10: RD | E10: 85520 | G10: MICH | I10: LLM | J10: ML | K10: +3-day | N10: =J1 -> Qwen | O10: =100-ABS((($K11-J2)/($K11)))*100 -> 99.261084 | P10: =O10/$P$1 -> 0.11086353 | Q10: =100-ABS((($K12-J3)/($K12)))*100 -> 99.586068 | R10: =Q10/$R$1 -> 0.1112687 | S10: =100-ABS((($K13-J4)/($K13)))*100 -> 99.935162 | T10: =S10/$T$1 -> 0.11133493 | U10: =100-ABS((($K14-J5)/($K14)))*100 -> 96.280775 | V10: =U10/$V$1 -> 0.10909954 | W10: =100-ABS((($K15-J6)/($K15)))*100 -> 99.836066 | X10: =W10/$X$1 -> 0.11111658 | Y10: =100-ABS((($K16-J7)/($K16)))*100 -> 40.922619 | Z10: =Y10/$Z$1 -> 0.12532813 | AB10: =(Q9+S9+U9+W9)/4 -> 99.47369 | AC10: =(O9+Q9+S9+U9+W9+Y9)/6 -> 89.761846 | AD10: =IF($AB11=MAX(AB2:AB10),"TOP","") | AE10: =IF($AC10=MAX(AC2:AC10),"TOP","") | AG10: max AVR-6 | AI10: =AVERAGE(AI2:AI7) -> 90.074333 | AK10: max AVR-6 | AM10: =AVERAGE(AM2:AM7) -> 88.012214 | AQ10: 0 | AR10: 5.28 | AS10: 5.33 | AT10: 5.1 | AU10: Total Penalty
A11: TNX | B11: 4.033 | C11: 4.02 | D11: =IF(ABS(K11-I11)<ABS(C11-K11),$I$10,$C$10) -> LLM | E11: 4.05 | F11: =IF(ABS(K11-I11)<ABS(K11-E11),$I$10,$E$10) -> 85520 | G11: 4.06 | H11: =IF(ABS(I11-K11)<ABS(K11-G11),$I$10,$G$10) -> MICH | I11: =(B2*P24)+(C2*P25)+(D2*P26)+(E2*P27)+(F2*P28)+(G2*P29)+(H2*P30)+(I2*P31)+(J2*P31) -> 4.0388972 | J11: 4.0421697 | K11: 4.06
A12: DJI | B12: 49174.5 | C12: 49515 | D12: =IF(ABS(K12-I12)<ABS(C12-K12),$I$10,$C$10) -> RD | E12: 49483 | F12: =IF(ABS(K12-I12)<ABS(K12-E12),$I$10,$E$10) -> 85520 | G12: 49310 | H12: =IF(ABS(I12-K12)<ABS(K12-G12),$I$10,$G$10) -> MICH | I12: =(B3*R24)+(C3*R25)+(D3*R26)+(E3*R27)+(F3*R28)+(G3*R29)+(H3*R30)+(I3*R31)+(J3*R31) -> 49251.484 | J12: 49221.088 | K12: 49525 | N12: Update | O12: TNX | P12: =SUM(O13:O21) -> 780 | Q12: DJI | R12: =SUM(Q13:Q21) -> 780 | S12: SPX | T12: =SUM(S13:S21) -> 825 | U12: VIX | V12: =SUM(U13:U21) -> 630 | W12: QQQ | X12: =SUM(W13:W21) -> 845 | Y12: AAPL | Z12: =SUM(Y13:Y21) -> 0.9 | AB12: Value | AC12: Assign | AG12: =B19 -> Close YF | AH12: =(I20-B20)/B20 -> 0.0066947682 | AI12: =IF(K11-B20>0,"↑","↓") -> ↑ | AJ12: =(C20-B20)/B20 -> -0.0032234069 | AK12: =IF(C20-B20>0,"↑","↓") -> ↓ | AL12: =(E20-B20)/B20 -> 0.0042152244 | AM12: =IF(E20-B20>0,"↑","↓") -> ↑ | AN12: =(G20-B20)/B20 -> 0.0066947682 | AO12: =IF(G20-B20>0,"↑","↓") -> ↑
A13: SPX | B13: 6890.07 | C13: 6907 | D13: =IF(ABS(K13-I13)<ABS(C13-K13),$I$10,$C$10) -> LLM | E13: 6913 | F13: =IF(ABS(K13-I13)<ABS(K13-E13),$I$10,$E$10) -> LLM | G13: 6919 | H13: =IF(ABS(I13-K13)<ABS(K13-G13),$I$10,$G$10) -> LLM | I13: =(B4*T24)+(C4*T25)+(D4*T26)+(E4*T27)+(F4*T28)+(G4*T29)+(H4*T30)+(I4*T31)+(J4*T31) -> 6907.2033 | J13: 6912.7657 | K13: 6909.52 | N13: =N2 -> O 5.2 | O13: =IF(O2=0,0, LOOKUP(O2-0.000000000001,$AB$13:$AB$29,$AC$13:$AC$29)) -> 80 | P13: =O13/$P$12 -> 0.1025641 | Q13: =IF(Q2=0,0, LOOKUP(Q2-0.000000000001,$AB$13:$AB$29,$AC$13:$AC$29)) -> 90 | R13: =Q13/$R$12 -> 0.11538462 | S13: =IF(S2=0,0, LOOKUP(S2-0.000000000001,$AB$13:$AB$29,$AC$13:$AC$29)) -> 95 | T13: =S13/$T$12 -> 0.11515152 | U13: =IF(U2=0,0, LOOKUP(U2-0.000000000001,$AB$13:$AB$29,$AC$13:$AC$29)) -> 60 | V13: =U13/$V$12 -> 0.095238095 | W13: =IF(W2=0,0, LOOKUP(W2-0.000000000001,$AB$13:$AB$29,$AC$13:$AC$29)) -> 95 | X13: =W13/$X$12 -> 0.11242604 | Y13: =IF(Y2=0,0, LOOKUP(Y2-0.000000000001,$AB$13:$AB$29,$AC$13:$AC$29)) -> 0.1 | Z13: =Y13/$Z$12 -> 0.11111111 | AB13: 1 | AC13: 0.1 | AH13: =(I21-B21)/B21 -> 0.007127678 | AI13: =IF(I21-B21>0,"↑","↓") -> ↑ | AJ13: =(C21-B21)/B21 -> 0.0069243205 | AK13: =IF(C21-B21>0,"↑","↓") -> ↑ | AL13: =(E21-B21)/B21 -> 0.0062735768 | AM13: =IF(E21-B21>0,"↑","↓") -> ↑ | AN13: =(G21-B21)/B21 -> 0.0027554932 | AO13: =IF(G21-B21>0,"↑","↓") -> ↑ | AP13: DJI | AQ13: =K10 -> +3-day | AR13: User1 | AS13: User2 | AT13: User3 | AU13: F1 | AV13: 893 | AW13: TEST | AX13: BEST = | AY13: 893
A14: VIX | B14: 19.55 | C14: 18.4 | D14: =IF(ABS(K14-I14)<ABS(C14-K14),$I$10,$C$10) -> LLM | E14: 18.75 | F14: =IF(ABS(K14-I14)<ABS(K14-E14),$I$10,$E$10) -> LLM | G14: 19.21 | H14: =IF(ABS(I14-K14)<ABS(K14-G14),$I$10,$G$10) -> MICH | I14: =(B5*V24)+(C5*V25)+(D5*V26)+(E5*V27)+(F5*V28)+(G5*V29)+(H5*V30)+(I5*V31)+(J5*V31) -> 19.318179 | J14: 18.934458 | K14: 19.09 | N14: =N3 -> Grok 4.1 | O14: =IF(O3=0,0, LOOKUP(O3-0.000000000001,$AB$13:$AB$29,$AC$13:$AC$29)) -> 95 | P14: =O14/$P$12 -> 0.12179487 | Q14: =IF(Q3=0,0, LOOKUP(Q3-0.000000000001,$AB$13:$AB$29,$AC$13:$AC$29)) -> 90 | R14: =Q14/$R$12 -> 0.11538462 | S14: =IF(S3=0,0, LOOKUP(S3-0.000000000001,$AB$13:$AB$29,$AC$13:$AC$29)) -> 95 | T14: =S14/$T$12 -> 0.11515152 | U14: =IF(U3=0,0, LOOKUP(U3-0.000000000001,$AB$13:$AB$29,$AC$13:$AC$29)) -> 95 | V14: =U14/$V$12 -> 0.15079365 | W14: =IF(W3=0,0, LOOKUP(W3-0.000000000001,$AB$13:$AB$29,$AC$13:$AC$29)) -> 100 | X14: =W14/$X$12 -> 0.1183432 | Y14: =IF(Y3=0,0, LOOKUP(Y3-0.000000000001,$AB$13:$AB$29,$AC$13:$AC$29)) -> 0.1 | Z14: =Y14/$Z$12 -> 0.11111111 | AB14: 80 | AC14: 1 | AH14: =(I22-B22)/B22 -> 0.0028229031 | AI14: =IF(I22-B22>0,"↑","↓") -> ↑ | AJ14: =(C22-B22)/B22 -> 0.0024571594 | AK14: =IF(C22-B22>0,"↑","↓") -> ↑ | AL14: =(E22-B22)/B22 -> 0.0033279778 | AM14: =IF(E22-B22>0,"↑","↓") -> ↑ | AN14: =(G22-B22)/B22 -> 0.0041987962 | AO14: =IF(G22-B22>0,"↑","↓") -> ↑ | AQ14: 0 | AR14: =AR15/AU15 -> 0.011198208 | AS14: =AS15/AU15 -> 0.047032475 | AT14: =AT15/AU15 -> 0.24076148 | AU14: 5 | AV14: 1 | AW14: Scale | AX14: RANGE = | AY14: =AV13/AQ4 -> 0.018031297
A15: QQQ | B15: 607.87 | C15: 613.3 | D15: =IF(ABS(K15-I15)<ABS(C15-K15),$I$10,$C$10) -> LLM | E15: 615.4 | F15: =IF(ABS(K15-I15)<ABS(K15-E15),$I$10,$E$10) -> LLM | G15: 609.9 | H15: =IF(ABS(I15-K15)<ABS(K15-G15),$I$10,$G$10) -> LLM | I15: =(B6*X24)+(C6*X25)+(D6*X26)+(E6*X27)+(F6*X28)+(G6*X29)+(H6*X30)+(I6*X31)+(J6*X31) -> 609.91082 | J15: 609.60971 | K15: 610 | N15: =N4 -> Gemini Pro 3 | O15: =IF(O4=0,0, LOOKUP(O4-0.000000000001,$AB$13:$AB$29,$AC$13:$AC$29)) -> 95 | P15: =O15/$P$12 -> 0.12179487 | Q15: =IF(Q4=0,0, LOOKUP(Q4-0.000000000001,$AB$13:$AB$29,$AC$13:$AC$29)) -> 90 | R15: =Q15/$R$12 -> 0.11538462 | S15: =IF(S4=0,0, LOOKUP(S4-0.000000000001,$AB$13:$AB$29,$AC$13:$AC$29)) -> 95 | T15: =S15/$T$12 -> 0.11515152 | U15: =IF(U4=0,0, LOOKUP(U4-0.000000000001,$AB$13:$AB$29,$AC$13:$AC$29)) -> 95 | V15: =U15/$V$12 -> 0.15079365 | W15: =IF(W4=0,0, LOOKUP(W4-0.000000000001,$AB$13:$AB$29,$AC$13:$AC$29)) -> 95 | X15: =W15/$X$12 -> 0.11242604 | Y15: =IF(Y4=0,0, LOOKUP(Y4-0.000000000001,$AB$13:$AB$29,$AC$13:$AC$29)) -> 0.1 | Z15: =Y15/$Z$12 -> 0.11111111 | AB15: 82.5 | AC15: 2 | AH15: =(I23-B23)/B23 -> -0.023529412 | AI15: =IF(I23-B23>0,"↑","↓") -> ↓ | AJ15: =(C23-B23)/B23 -> -0.058823529 | AK15: =IF(C23-B23>0,"↑","↓") -> ↓ | AL15: =(E23-B23)/B23 -> -0.040920716 | AM15: =IF(E23-B23>0,"↑","↓") -> ↓ | AN15: =(G23-B23)/B23 -> -0.017391304 | AO15: =IF(G23-B23>0,"↑","↓") -> ↓ | AQ15: 0 | AR15: =AR4 -> 10 | AS15: =AS4 -> 42 | AT15: =AT4 -> 215 | AU15: =AV14*AV13 -> 893
A16: AAPL | B16: 272.14 | C16: 273.2 | D16: =IF(ABS(K16-I16)<ABS(C16-K16),$I$10,$C$10) -> LLM | E16: 274.3 | F16: =IF(ABS(K16-I16)<ABS(K16-E16),$I$10,$E$10) -> LLM | G16: 272.9 | H16: =IF(ABS(I16-K16)<ABS(K16-G16),$I$10,$G$10) -> LLM | I16: =(B7*Z24)+(C7*Z25)+(D7*Z26)+(E7*Z27)+(F7*Z28)+(G7*Z29)+(H7*Z30)+(I7*Z31)+(J7*Z31) -> 274.37624 | J16: 271.24407 | K16: 672 | N16: =N5 -> Claude | O16: =IF(O5=0,0, LOOKUP(O5-0.000000000001,$AB$13:$AB$29,$AC$13:$AC$29)) -> 95 | P16: =O16/$P$12 -> 0.12179487 | Q16: =IF(Q5=0,0, LOOKUP(Q5-0.000000000001,$AB$13:$AB$29,$AC$13:$AC$29)) -> 90 | R16: =Q16/$R$12 -> 0.11538462 | S16: =IF(S5=0,0, LOOKUP(S5-0.000000000001,$AB$13:$AB$29,$AC$13:$AC$29)) -> 95 | T16: =S16/$T$12 -> 0.11515152 | U16: =IF(U5=0,0, LOOKUP(U5-0.000000000001,$AB$13:$AB$29,$AC$13:$AC$29)) -> 80 | V16: =U16/$V$12 -> 0.12698413 | W16: =IF(W5=0,0, LOOKUP(W5-0.000000000001,$AB$13:$AB$29,$AC$13:$AC$29)) -> 95 | X16: =W16/$X$12 -> 0.11242604 | Y16: =IF(Y5=0,0, LOOKUP(Y5-0.000000000001,$AB$13:$AB$29,$AC$13:$AC$29)) -> 0.1 | Z16: =Y16/$Z$12 -> 0.11111111 | AB16: 85 | AC16: 5 | AH16: =(I24-B24)/B24 -> 0.0035040387 | AI16: =IF(I24-B24>0,"↑","↓") -> ↑ | AJ16: =(C24-B24)/B24 -> 0.008932831 | AK16: =IF(C24-B24>0,"↑","↓") -> ↑ | AL16: =(E24-B24)/B24 -> 0.012387517 | AM16: =IF(E24-B24>0,"↑","↓") -> ↑ | AN16: =(G24-B24)/B24 -> 0.0033395298 | AO16: =IF(G24-B24>0,"↑","↓") -> ↑
N17: =N6 -> GLM-4.7 | O17: =IF(O6=0,0, LOOKUP(O6-0.000000000001,$AB$13:$AB$29,$AC$13:$AC$29)) -> 80 | P17: =O17/$P$12 -> 0.1025641 | Q17: =IF(Q6=0,0, LOOKUP(Q6-0.000000000001,$AB$13:$AB$29,$AC$13:$AC$29)) -> 65 | R17: =Q17/$R$12 -> 0.083333333 | S17: =IF(S6=0,0, LOOKUP(S6-0.000000000001,$AB$13:$AB$29,$AC$13:$AC$29)) -> 90 | T17: =S17/$T$12 -> 0.10909091 | U17: =IF(U6=0,0, LOOKUP(U6-0.000000000001,$AB$13:$AB$29,$AC$13:$AC$29)) -> 30 | V17: =U17/$V$12 -> 0.047619048 | W17: =IF(W6=0,0, LOOKUP(W6-0.000000000001,$AB$13:$AB$29,$AC$13:$AC$29)) -> 80 | X17: =W17/$X$12 -> 0.094674556 | Y17: =IF(Y6=0,0, LOOKUP(Y6-0.000000000001,$AB$13:$AB$29,$AC$13:$AC$29)) -> 0.1 | Z17: =Y17/$Z$12 -> 0.11111111 | AB17: 87.5 | AC17: 10 | AH17: =(I25-B25)/B25 -> 1.4693173 | AI17: =IF(I25-B25>0,"↑","↓") -> ↑ | AJ17: =(C25-B25)/B25 -> 0.003895054 | AK17: =IF(C25-B25>0,"↑","↓") -> ↑ | AL17: =(E25-B25)/B25 -> 0.0079370912 | AM17: =IF(E25-B25>0,"↑","↓") -> ↑ | AN17: =(G25-B25)/B25 -> 0.0027926802 | AO17: =IF(G25-B25>0,"↑","↓") -> ↑ | AP17: SPX | AQ17: =AQ13 -> +3-day | AR17: =AR13 -> User1 | AS17: =AS13 -> User2 | AT17: =AT13 -> User3 | AU17: F2 | AV17: 225.6 | AW17: =AW13 -> TEST | AX17: =AX13 -> BEST = | AY17: 225.6
N18: =N7 -> Kimi 2.5 | O18: =IF(O7=0,0, LOOKUP(O7-0.000000000001,$AB$13:$AB$29,$AC$13:$AC$29)) -> 90 | P18: =O18/$P$12 -> 0.11538462 | Q18: =IF(Q7=0,0, LOOKUP(Q7-0.000000000001,$AB$13:$AB$29,$AC$13:$AC$29)) -> 95 | R18: =Q18/$R$12 -> 0.12179487 | S18: =IF(S7=0,0, LOOKUP(S7-0.000000000001,$AB$13:$AB$29,$AC$13:$AC$29)) -> 95 | T18: =S18/$T$12 -> 0.11515152 | U18: =IF(U7=0,0, LOOKUP(U7-0.000000000001,$AB$13:$AB$29,$AC$13:$AC$29)) -> 50 | V18: =U18/$V$12 -> 0.079365079 | W18: =IF(W7=0,0, LOOKUP(W7-0.000000000001,$AB$13:$AB$29,$AC$13:$AC$29)) -> 95 | X18: =W18/$X$12 -> 0.11242604 | Y18: =IF(Y7=0,0, LOOKUP(Y7-0.000000000001,$AB$13:$AB$29,$AC$13:$AC$29)) -> 0.1 | Z18: =Y18/$Z$12 -> 0.11111111 | AB18: 90 | AC18: 20 | AH18: =K10 -> +3-day | AJ18: =C10 -> RD | AL18: =E10 -> 85520 | AN18: =G10 -> MICH | AQ18: 0 | AR18: =AR19/AU19 -> 0.011170213 | AS18: =AS19/AU19 -> 0.015425532 | AT18: =AT19/AU19 -> 0.042021277 | AU18: 5 | AV18: =AV14 -> 1 | AW18: =AW14 -> Scale | AX18: =AX14 -> RANGE = | AY18: =AV17/AQ5 -> 0.032650604
A19: model | B19: =B10 -> Close YF | C19: RD | E19: 85520 | G19: =G10 -> MICH | I19: +3-day | N19: =N8 -> Minimax 2.1 | O19: =IF(O8=0,0, LOOKUP(O8-0.000000000001,$AB$13:$AB$29,$AC$13:$AC$29)) -> 70 | P19: =O19/$P$12 -> 0.08974359 | Q19: =IF(Q8=0,0, LOOKUP(Q8-0.000000000001,$AB$13:$AB$29,$AC$13:$AC$29)) -> 90 | R19: =Q19/$R$12 -> 0.11538462 | S19: =IF(S8=0,0, LOOKUP(S8-0.000000000001,$AB$13:$AB$29,$AC$13:$AC$29)) -> 95 | T19: =S19/$T$12 -> 0.11515152 | U19: =IF(U8=0,0, LOOKUP(U8-0.000000000001,$AB$13:$AB$29,$AC$13:$AC$29)) -> 80 | V19: =U19/$V$12 -> 0.12698413 | W19: =IF(W8=0,0, LOOKUP(W8-0.000000000001,$AB$13:$AB$29,$AC$13:$AC$29)) -> 90 | X19: =W19/$X$12 -> 0.10650888 | Y19: =IF(Y8=0,0, LOOKUP(Y8-0.000000000001,$AB$13:$AB$29,$AC$13:$AC$29)) -> 0.1 | Z19: =Y19/$Z$12 -> 0.11111111 | AB19: 92.5 | AC19: 30 | AG19: =B28 -> Oraclum | AH19: =(I29-B29)/B29 -> 0.0014800197 | AI19: =IF(I29-B29>0,"↑","↓") -> ↑ | AJ19: =(C29-B29)/B29 -> -0.0083867785 | AK19: =IF(C29-B29>0,"↑","↓") -> ↓ | AL19: =(E29-B29)/B29 -> -0.00098667982 | AM19: =IF(E29-B29>0,"↑","↓") -> ↓ | AN19: =(G29-B29)/B29 -> 0.0014800197 | AO19: =IF(G29-B29>0,"↑","↓") -> ↑ | AQ19: 0 | AR19: =AR5 -> 2.52 | AS19: =AS5 -> 3.48 | AT19: =AT5 -> 9.48 | AU19: =AV18*AV17 -> 225.6
A20: TNX | B20: =B11 -> 4.033 | C20: =C11 -> 4.02 | D20: =CONCATENATE(TEXT(AJ12,"0.00%")," ",AK12) -> -0.32% ↓ | E20: =E11 -> 4.05 | F20: =CONCATENATE(TEXT(AL12,"0.00%")," ",AM12) -> 0.42% ↑ | G20: =G11 -> 4.06 | H20: =CONCATENATE(TEXT(AN12,"0.00%")," ",AO12) -> 0.67% ↑ | I20: =K11 -> 4.06 | J20: =CONCATENATE(TEXT(AH12,"0.00%")," ",AI12) -> 0.67% ↑ | N20: =N9 -> LeChat | O20: =IF(O9=0,0, LOOKUP(O9-0.000000000001,$AB$13:$AB$29,$AC$13:$AC$29)) -> 95 | P20: =O20/$P$12 -> 0.12179487 | Q20: =IF(Q9=0,0, LOOKUP(Q9-0.000000000001,$AB$13:$AB$29,$AC$13:$AC$29)) -> 80 | R20: =Q20/$R$12 -> 0.1025641 | S20: =IF(S9=0,0, LOOKUP(S9-0.000000000001,$AB$13:$AB$29,$AC$13:$AC$29)) -> 70 | T20: =S20/$T$12 -> 0.084848485 | U20: =IF(U9=0,0, LOOKUP(U9-0.000000000001,$AB$13:$AB$29,$AC$13:$AC$29)) -> 90 | V20: =U20/$V$12 -> 0.14285714 | W20: =IF(W9=0,0, LOOKUP(W9-0.000000000001,$AB$13:$AB$29,$AC$13:$AC$29)) -> 100 | X20: =W20/$X$12 -> 0.1183432 | Y20: =IF(Y9=0,0, LOOKUP(Y9-0.000000000001,$AB$13:$AB$29,$AC$13:$AC$29)) -> 0.1 | Z20: =Y20/$Z$12 -> 0.11111111 | AB20: 95 | AC20: 40 | AH20: =(I30-B30)/B30 -> 0.0069300781 | AI20: =IF(I30-B30>0,"↑","↓") -> ↑ | AJ20: =(C30-B30)/B30 -> 0.0067267606 | AK20: =IF(C30-B30>0,"↑","↓") -> ↑ | AL20: =(E30-B30)/B30 -> 0.0060761444 | AM20: =IF(E30-B30>0,"↑","↓") -> ↑ | AN20: =(G30-B30)/B30 -> 0.0025587511 | AO20: =IF(G30-B30>0,"↑","↓") -> ↑
A21: DJI | B21: =B12 -> 49174.5 | C21: =C12 -> 49515 | D21: =CONCATENATE(TEXT(AJ13,"0.00%")," ",AK13) -> 0.69% ↑ | E21: =E12 -> 49483 | F21: =CONCATENATE(TEXT(AL13,"0.00%")," ",AM13) -> 0.63% ↑ | G21: =G12 -> 49310 | H21: =CONCATENATE(TEXT(AN13,"0.00%")," ",AO13) -> 0.28% ↑ | I21: =K12 -> 49525 | J21: =CONCATENATE(TEXT(AH13,"0.00%")," ",AI13) -> 0.71% ↑ | N21: =N10 -> Qwen | O21: =IF(O10=0,0, LOOKUP(O10-0.000000000001,$AB$13:$AB$29,$AC$13:$AC$29)) -> 80 | P21: =O21/$P$12 -> 0.1025641 | Q21: =IF(Q10=0,0, LOOKUP(Q10-0.000000000001,$AB$13:$AB$29,$AC$13:$AC$29)) -> 90 | R21: =Q21/$R$12 -> 0.11538462 | S21: =IF(S10=0,0, LOOKUP(S10-0.000000000001,$AB$13:$AB$29,$AC$13:$AC$29)) -> 95 | T21: =S21/$T$12 -> 0.11515152 | U21: =IF(U10=0,0, LOOKUP(U10-0.000000000001,$AB$13:$AB$29,$AC$13:$AC$29)) -> 50 | V21: =U21/$V$12 -> 0.079365079 | W21: =IF(W10=0,0, LOOKUP(W10-0.000000000001,$AB$13:$AB$29,$AC$13:$AC$29)) -> 95 | X21: =W21/$X$12 -> 0.11242604 | Y21: =IF(Y10=0,0, LOOKUP(Y10-0.000000000001,$AB$13:$AB$29,$AC$13:$AC$29)) -> 0.1 | Z21: =Y21/$Z$12 -> 0.11111111 | AB21: 96 | AC21: 50 | AH21: =(I31-B31)/B31 -> 0.0028243586 | AI21: =IF(I31-B31>0,"↑","↓") -> ↑ | AJ21: =(C31-B31)/B31 -> 0.0024586143 | AK21: =IF(C31-B31>0,"↑","↓") -> ↑ | AL21: =(E31-B31)/B31 -> 0.003329434 | AM21: =IF(E31-B31>0,"↑","↓") -> ↑ | AN21: =(G31-B31)/B31 -> 0.0042002537 | AO21: =IF(G31-B31>0,"↑","↓") -> ↑ | AP21: VIX | AQ21: =AQ17 -> +3-day | AR21: =AR17 -> User1 | AS21: =AS17 -> User2 | AT21: =AT17 -> User3 | AU21: F3 | AV21: 3.3 | AW21: =AW17 -> TEST | AX21: =AX17 -> BEST = | AY21: 3.3
A22: SPX | B22: =B13 -> 6890.07 | C22: =C13 -> 6907 | D22: =CONCATENATE(TEXT(AJ14,"0.00%")," ",AK14) -> 0.25% ↑ | E22: =E13 -> 6913 | F22: =CONCATENATE(TEXT(AL14,"0.00%")," ",AM14) -> 0.33% ↑ | G22: =G13 -> 6919 | H22: =CONCATENATE(TEXT(AN14,"0.00%")," ",AO14) -> 0.42% ↑ | I22: =K13 -> 6909.52 | J22: =CONCATENATE(TEXT(AH14,"0.00%")," ",AI14) -> 0.28% ↑ | AB22: 97 | AC22: 60 | AH22: =(I32-B32)/B32 -> -0.023529412 | AI22: =IF(I32-B32>0,"↑","↓") -> ↓ | AJ22: =(C32-B32)/B32 -> -0.058823529 | AK22: =IF(C32-B32>0,"↑","↓") -> ↓ | AL22: =(E32-B32)/B32 -> -0.040920716 | AM22: =IF(E32-B32>0,"↑","↓") -> ↓ | AN22: =(G32-B32)/B32 -> -0.017391304 | AO22: =IF(G32-B32>0,"↑","↓") -> ↓ | AQ22: 0 | AR22: =AR23/AU23 -> 0.20909091 | AS22: =AS23/AU23 -> 0.1030303 | AT22: =AT23/AU23 -> 0.036363636 | AU22: 5 | AV22: =AV18 -> 1 | AW22: =AW18 -> Scale | AX22: =AX18 -> RANGE = | AY22: =AV21/AQ6 -> 0.17286537
